Workbook
Name 표시연도: 'FCST RESULT'!$P$4

Sheet 표지

Sheet FCST RESULT
B3: NSA SALES FORECAST
P4: 2026
B6: 1. 매출수량 (백만 A)
B21: 구분 | C21: FY2026 | D21: FY2027 | E21: FY2028 | F21: FY2029 | G21: FY2030
B22: Model Base | C22: =근거_매출!J10/1000000 | D22: =근거_매출!K10/1000000 | E22: =근거_매출!L10/1000000 | F22: =근거_매출!M10/1000000 | G22: =근거_매출!N10/1000000
B23: MKT Base | C23: =IF(근거_매출!$J$12="",NA(),근거_매출!J12/1000000) | D23: =IF(근거_매출!$J$12="",NA(),근거_매출!K12/1000000) | E23: =IF(근거_매출!$J$12="",NA(),근거_매출!L12/1000000) | F23: =IF(근거_매출!$J$12="",NA(),근거_매출!M12/1000000) | G23: =IF(근거_매출!$J$12="",NA(),근거_매출!N12/1000000)
B24: Best (MS +10%p) | C24: =근거_매출!J14/1000000 | D24: =근거_매출!K14/1000000 | E24: =근거_매출!L14/1000000 | F24: =근거_매출!M14/1000000 | G24: =근거_매출!N14/1000000
B25: Worst (MS -10%p) | C25: =근거_매출!J16/1000000 | D25: =근거_매출!K16/1000000 | E25: =근거_매출!L16/1000000 | F25: =근거_매출!M16/1000000 | G25: =근거_매출!N16/1000000
B26: Best (MS +5%p) | C26: =근거_매출!J18/1000000 | D26: =근거_매출!K18/1000000 | E26: =근거_매출!L18/1000000 | F26: =근거_매출!M18/1000000 | G26: =근거_매출!N18/1000000
B27: Worst (MS -5%p) | C27: =근거_매출!J20/1000000 | D27: =근거_매출!K20/1000000 | E27: =근거_매출!L20/1000000 | F27: =근거_매출!M20/1000000 | G27: =근거_매출!N20/1000000
B29: 2. 매출액 (백만원)
B44: 구분 | C44: FY2026 | D44: FY2027 | E44: FY2028 | F44: FY2029 | G44: FY2030
B45: Model Base | C45: =근거_매출!J32 | D45: =근거_매출!K32 | E45: =근거_매출!L32 | F45: =근거_매출!M32 | G45: =근거_매출!N32
B46: MKT Base | C46: =IF(근거_매출!$J$12="",NA(),근거_매출!J34) | D46: =IF(근거_매출!$J$12="",NA(),근거_매출!K34) | E46: =IF(근거_매출!$J$12="",NA(),근거_매출!L34) | F46: =IF(근거_매출!$J$12="",NA(),근거_매출!M34) | G46: =IF(근거_매출!$J$12="",NA(),근거_매출!N34)
B47: Best (MS +10%p) | C47: =근거_매출!J35 | D47: =근거_매출!K35 | E47: =근거_매출!L35 | F47: =근거_매출!M35 | G47: =근거_매출!N35
B48: Worst (MS -10%p) | C48: =근거_매출!J36 | D48: =근거_매출!K36 | E48: =근거_매출!L36 | F48: =근거_매출!M36 | G48: =근거_매출!N36
B49: Best (MS +5%p) | C49: =근거_매출!J37 | D49: =근거_매출!K37 | E49: =근거_매출!L37 | F49: =근거_매출!M37 | G49: =근거_매출!N37
B50: Worst (MS -5%p) | C50: =근거_매출!J38 | D50: =근거_매출!K38 | E50: =근거_매출!L38 | F50: =근거_매출!M38 | G50: =근거_매출!N38

Sheet 변동요인분석
A2: NSA FCST 변동 요인 분석과 시뮬레이션
A4: ① 변동 요인 분석
A5: - 핵심 변동 요인 : NSA MS (Ramosetron 시장 내 점유율) (매출 변동성 ±18.9%로, 타 요인 대비 압도적인 영향력을 행사함)
A6: - 기타 변동 요인: 환자당 Ramo 사용량(±5.6%), 전환비율(±3.4%), NSA MS 상급종합 하한(±3.0%) 등 (구조 파라미터 성격, 분기 실측 갱신 시 자동 재추정)
A7: - 예외 요인: 약가 인하 고시(현재 없음) 및 MKT 제출 수치와의 차이는 본 시뮬레이션 외 별도 리스크로 분류 · 입찰(저가 제네릭) 단발 이벤트는 분기 모니터링으로 감시
A25: ② 시뮬레이션 : NSA MS 변동의 재무적 가치
A26: - Best (MS 확대): NSA MS +10%p 시 → FY2030 매출 437억 (상단) · +5%p 시 402억
A27: - Worst (MS 잠식): NSA MS -10%p 시 → FY2030 매출 298억 (하단) · -5%p 시 332억
A28: (※ 기준선 Base: 367억 · 세일즈 포캐스트 밴드는 FY2027부터 적용)
A47: · 근거: 근거_민감도 참조

Sheet FCST FLOW
A2: NSA Sales FCST FLOW
J3: 각 행의 [▶ 근거] 를 클릭하면 해당 백데이터 시트로 이동 (기준수치·예측수치는 백데이터 참조)
A5: 단계 | B5: 항목 | C5: 기준 수치 | D5: 모델 방법 | E5: FY2026E | F5: FY2027 | G5: FY2028 | H5: FY2029 | I5: FY2030 | J5: 근거
A6: ① 환자 현황 | B6: 전신마취 환자수 | C6: =CALC!C20 | D6: · 추계인구(통계청 중위) × 연령별 전신마취 비율 (30~50대 선형회귀 연장, 그 외 최근 5개년 평균) | E6: =INDEX(CALC!$C$5:$C$25,MATCH(표시연도,CALC!$B$5:$B$25,0)) | F6: =INDEX(CALC!$C$5:$C$25,MATCH(2027,CALC!$B$5:$B$25,0)) | G6: =INDEX(CALC!$C$5:$C$25,MATCH(2028,CALC!$B$5:$B$25,0)) | H6: =INDEX(CALC!$C$5:$C$25,MATCH(2029,CALC!$B$5:$B$25,0)) | I6: =INDEX(CALC!$C$5:$C$25,MATCH(2030,CALC!$B$5:$B$25,0)) | J6: ▶ 근거
B7: 종별 환자비율 (상급종합병원) | C7: ='근거_종별전신마취환자수'!Q10 | D7: · HIRA 분기 실측(~2026Q1) 기반 회복모형 — 상급종합 상한 41%·종합 하한 40%·병원 하한 10%·의원 S-curve, 4종별 정규화 | E7: ='근거_종별전신마취환자수'!R10 | F7: ='근거_종별전신마취환자수'!S10 | G7: ='근거_종별전신마취환자수'!T10 | H7: ='근거_종별전신마취환자수'!U10 | I7: ='근거_종별전신마취환자수'!V10 | J7: ▶ 근거
A8: ② 시장 구조 | B8: 환자당 Ramosetron 사용량 (상급종합, A/명) | C8: ='근거_Ramosetron 시장 수량'!Q22 | D8: · 연간 선형회귀(상한 5A) / 종합 상한 4A / 병원·의원 최근값 flat — 4개 분기 동일 적용 | E8: ='근거_Ramosetron 시장 수량'!R22 | F8: ='근거_Ramosetron 시장 수량'!S22 | G8: ='근거_Ramosetron 시장 수량'!T22 | H8: ='근거_Ramosetron 시장 수량'!U22 | I8: ='근거_Ramosetron 시장 수량'!V22 | J8: ▶ 근거
B9: Ramosetron 시장 수량 (A) | C9: =CALC!E20 | D9: · Σ 종별 전신마취환자수 × 종별 환자당 사용량 (CY 분기 → FY 재구성) | E9: =INDEX(CALC!$E$5:$E$25,MATCH(표시연도,CALC!$B$5:$B$25,0)) | F9: =INDEX(CALC!$E$5:$E$25,MATCH(2027,CALC!$B$5:$B$25,0)) | G9: =INDEX(CALC!$E$5:$E$25,MATCH(2028,CALC!$B$5:$B$25,0)) | H9: =INDEX(CALC!$E$5:$E$25,MATCH(2029,CALC!$B$5:$B$25,0)) | I9: =INDEX(CALC!$E$5:$E$25,MATCH(2030,CALC!$B$5:$B$25,0)) | J9: ▶ 근거
A10: ③ 경쟁 현황 | B10: NSA MS (상급종합병원) | C10: ='근거_NSA수량(IQVIA기준)'!I16 | D10: · 전체기간 선형(레벨보정, 하한 55%) — 백테스트 MAPE 2.9% | E10: ='근거_NSA수량(IQVIA기준)'!J16 | F10: ='근거_NSA수량(IQVIA기준)'!K16 | G10: ='근거_NSA수량(IQVIA기준)'!L16 | H10: ='근거_NSA수량(IQVIA기준)'!M16 | I10: ='근거_NSA수량(IQVIA기준)'!N16 | J10: ▶ 근거
B11: NSA MS (종합병원) | C11: ='근거_NSA수량(IQVIA기준)'!I17 | D11: · S-curve(로짓변환+저점앵커, 상한 56%) — 백테스트 MAPE 3.8% | E11: ='근거_NSA수량(IQVIA기준)'!J17 | F11: ='근거_NSA수량(IQVIA기준)'!K17 | G11: ='근거_NSA수량(IQVIA기준)'!L17 | H11: ='근거_NSA수량(IQVIA기준)'!M17 | I11: ='근거_NSA수량(IQVIA기준)'!N17 | J11: ▶ 근거
B12: NSA MS (병원·의원) | C12: ='근거_NSA수량(IQVIA기준)'!I18 | D12: · 병원 롤링 4분기 평균 / 의원 EWMA(α=0.3) flat — MAPE 8.9~10.3% (표시값은 병원) | E12: ='근거_NSA수량(IQVIA기준)'!J18 | F12: ='근거_NSA수량(IQVIA기준)'!K18 | G12: ='근거_NSA수량(IQVIA기준)'!L18 | H12: ='근거_NSA수량(IQVIA기준)'!M18 | I12: ='근거_NSA수량(IQVIA기준)'!N18 | J12: ▶ 근거
B13: NSA MS (전체) | C13: =CALC!I20 | D13: · Σ 종별 NSA 수량 ÷ Ramosetron 시장 수량 | E13: =INDEX(CALC!$I$5:$I$25,MATCH(표시연도,CALC!$B$5:$B$25,0)) | F13: =INDEX(CALC!$I$5:$I$25,MATCH(2027,CALC!$B$5:$B$25,0)) | G13: =INDEX(CALC!$I$5:$I$25,MATCH(2028,CALC!$B$5:$B$25,0)) | H13: =INDEX(CALC!$I$5:$I$25,MATCH(2029,CALC!$B$5:$B$25,0)) | I13: =INDEX(CALC!$I$5:$I$25,MATCH(2030,CALC!$B$5:$B$25,0)) | J13: ▶ 근거
A14: ④ 시장매출 | B14: DSKR 매출수량 (A) | C14: =INDEX(근거_매출!$B$10:$N$10,표시연도-1-2017) | D14: · NSA 수량(IQVIA, A) ÷ 전환비율(FY24~25 평균 1.044) → SAP 판매 수량 환산 | E14: =INDEX(근거_매출!$B$10:$N$10,표시연도-2017) | F14: =INDEX(근거_매출!$B$10:$N$10,2027-2017) | G14: =INDEX(근거_매출!$B$10:$N$10,2028-2017) | H14: =INDEX(근거_매출!$B$10:$N$10,2029-2017) | I14: =INDEX(근거_매출!$B$10:$N$10,2030-2017) | J14: ▶ 근거
B15: 연도별 단가 (원/A) | C15: =근거_매출!B27 | D15: · FY2026 목표단가 69,056원/5A ÷ 5 = 13,811원/A × 약가 배율 (인하 고시 없음 → 100% 유지, 근거_매출 28행에서 조정) | E15: =INDEX(근거_매출!$B$29:$N$29,표시연도-2017) | F15: =INDEX(근거_매출!$B$29:$N$29,2027-2017) | G15: =INDEX(근거_매출!$B$29:$N$29,2028-2017) | H15: =INDEX(근거_매출!$B$29:$N$29,2029-2017) | I15: =INDEX(근거_매출!$B$29:$N$29,2030-2017) | J15: ▶ 근거
A17: ▶ 결과 | B17: Ramosetron 시장 (수량, A) | C17: =CALC!E20 | D17: Σ 종별 전신마취환자수 × 종별 환자당 사용량 | E17: =INDEX(CALC!$E$5:$E$25,MATCH(표시연도,CALC!$B$5:$B$25,0)) | F17: =INDEX(CALC!$E$5:$E$25,MATCH(2027,CALC!$B$5:$B$25,0)) | G17: =INDEX(CALC!$E$5:$E$25,MATCH(2028,CALC!$B$5:$B$25,0)) | H17: =INDEX(CALC!$E$5:$E$25,MATCH(2029,CALC!$B$5:$B$25,0)) | I17: =INDEX(CALC!$E$5:$E$25,MATCH(2030,CALC!$B$5:$B$25,0)) | J17: ▶ 근거
B18: NSA 수량 (IQVIA, A) | C18: =CALC!H20 | D18: Σ 종별 Ramosetron 수량 × 종별 NSA MS | E18: =INDEX(CALC!$H$5:$H$25,MATCH(표시연도,CALC!$B$5:$B$25,0)) | F18: =INDEX(CALC!$H$5:$H$25,MATCH(2027,CALC!$B$5:$B$25,0)) | G18: =INDEX(CALC!$H$5:$H$25,MATCH(2028,CALC!$B$5:$B$25,0)) | H18: =INDEX(CALC!$H$5:$H$25,MATCH(2029,CALC!$B$5:$B$25,0)) | I18: =INDEX(CALC!$H$5:$H$25,MATCH(2030,CALC!$B$5:$B$25,0)) | J18: ▶ 근거
B19: NSA SAP매출 (백만원) | C19: =INDEX(근거_매출!$B$32:$N$32,표시연도-1-2017) | D19: DSKR 매출수량 × 연도별 단가 | E19: =INDEX(근거_매출!$B$32:$N$32,표시연도-2017) | F19: =INDEX(근거_매출!$B$32:$N$32,2027-2017) | G19: =INDEX(근거_매출!$B$32:$N$32,2028-2017) | H19: =INDEX(근거_매출!$B$32:$N$32,2029-2017) | I19: =INDEX(근거_매출!$B$32:$N$32,2030-2017) | J19: ▶ 근거
H20: ="※ 시나리오 밴드(FY2030): "&TEXT(근거_매출!N36,"#,##0")&" ~ "&TEXT(근거_매출!N35,"#,##0")&" (MS ±10%p) · "&TEXT(근거_매출!N38,"#,##0")&" ~ "&TEXT(근거_매출!N37,"#,##0")&" (±5%p) →" | I20: =HYPERLINK("#'FCST RESULT'!A1","상세: FCST RESULT ▶")
B22: ※ 기준 수치 - 출처 및 기준연도
B23: ① 환자 현황 (연령별 전신마취환자수): NHIS 진료행위 통계 L1211·L1212, CY2025 · 행위별 청구분 기준(포괄수가 DRG 제외 → 실제보다 약 15% 적음, 모델 내 배분 기준으로만 사용)
B24: ② 시장 구조: 종별 환자비율 HIRA 분기 실측(~2026Q1) / Ramosetron 시장 수량 IQVIA, CY2025 / 흡입마취제 종별 비율 NHIS N01AB, CY2025
B25: ③ 경쟁 현황 (종별 NSA MS): IQVIA NASEA 수량 × SS-Chart 종별 비율 ÷ 종별 Ramosetron 수량, 2026Q1
B26: ④ 시장매출(수량·단가): SAP 실측 FY2025 / 단가: FY2026 목표단가 (NASEA Inj. 0.3mg/5A)
B29: ■ 부록 — 백테스트 (종별 NSA MS 예측방식 walk-forward, 2020Q1~2026Q1)
B30: 종별 NSA MS | C30: 예측 방식 | D30: 백테스트 MAPE | E30: 판정
B31: 상급종합병원 MS | C31: 전체기간선형(레벨보정) | D31: 2.92% | E31: 채택
B32: 종합병원 MS | C32: S-curve(로짓+저점앵커) | D32: 3.83% | E32: 채택
B33: 병원 MS | C33: 롤링 4분기 평균 | D33: 8.89% | E33: 채택 (표본 소)
B34: 의원 MS | C34: EWMA(α=0.3) | D34: 10.30% | E34: 채택 (표본 소)
B35: · 방법: 2020Q1~2026Q1 분기 실측 walk-forward 백테스트(근거_NSA수량 [참고] 30~36행에서 이관). 각 종별 MS 예측 방식을 후보 중 MAPE 최소 방식으로 채택.
B36: · 결론: 상급종합·종합병원(NSA 수량의 95%)은 MAPE 3~4%로 안정, 병원·의원은 표본이 작아 오차 9~10% — 분기 모니터링 대상

Sheet 근거_전신마취환자수
A2: 전신마취 환자수 산출 : NHIS 데이터 기반 예측
B4: ◀ 실측 (NHIS, 2010~2025) | R4: 예측 (2025~2030) ▶
A5: 구분 / 연도 ▶ | B5: 2010 | C5: 2011 | D5: 2012 | E5: 2013 | F5: 2014 | G5: 2015 | H5: 2016 | I5: 2017 | J5: 2018 | K5: 2019 | L5: 2020 | M5: 2021 | N5: 2022 | O5: 2023 | P5: 2024 | Q5: 2025 | R5: 2026 | S5: 2027 | T5: 2028 | U5: 2029 | V5: 2030
A6: ■ A. 인구 (명) [통계청 장래인구추계, 중위]
A7: 0-9세 | B7: 4769730 | C7: 4651969 | D7: 4607872 | E7: 4589149 | F7: 4547518 | G7: 4541197 | H7: 4537256 | I7: 4460206 | J7: 4327663 | K7: 4206519 | L7: 4054901 | M7: 3850627 | N7: 3636125 | O7: 3415474 | P7: 3211594 | Q7: 2986799 | R7: 2774527 | S7: 2617033 | T7: 2507428 | U7: 2434549 | V7: 2396575
A8: 10-19세 | B8: 6638502 | C8: 6588027 | D8: 6404935 | E8: 6176138 | F8: 5955904 | G8: 5710954 | H8: 5459511 | I8: 5246532 | J8: 5087396 | K8: 4927537 | L8: 4769187 | M8: 4643600 | N8: 4599712 | O8: 4590838 | P8: 4546494 | Q8: 4538674 | R8: 4530952 | S8: 4460471 | T8: 4324683 | U8: 4195539 | V8: 4046514
A9: 20-29세 | B9: 6973154 | C9: 6840475 | D9: 6733813 | E9: 6686161 | F9: 6716535 | G9: 6781422 | H9: 6839660 | I9: 6897818 | J9: 6991259 | K9: 7026828 | L9: 7037893 | M9: 6953529 | N9: 6734021 | O9: 6548381 | P9: 6372432 | Q9: 6136764 | R9: 5887622 | S9: 5678166 | T9: 5510243 | U9: 5341561 | V9: 5157518
A10: 30-39세 | B10: 8264820 | C10: 8208754 | D10: 8146381 | E10: 8035971 | F10: 7899840 | G10: 7763702 | H10: 7652940 | I10: 7545842 | J10: 7456227 | K10: 7358231 | L10: 7174782 | M10: 6989477 | N10: 6872945 | O10: 6874383 | P10: 6913023 | Q10: 6975568 | R10: 7037580 | S10: 7096790 | T10: 7152255 | U10: 7158328 | V10: 7156565
A11: 40-49세 | B11: 8578079 | C11: 8600111 | D11: 8657375 | E11: 8653288 | F11: 8774714 | G11: 8752417 | H11: 8671799 | I11: 8585346 | J11: 8504579 | K11: 8335481 | L11: 8257903 | M11: 8158318 | N11: 8097011 | O11: 7993159 | P11: 7852297 | Q11: 7717016 | R11: 7624180 | S11: 7530657 | T11: 7417118 | U11: 7309393 | V11: 7147423
A12: 50-59세 | B12: 6751678 | C12: 7229163 | D12: 7504944 | E12: 7821975 | F12: 8033801 | G12: 8173256 | H12: 8305212 | I12: 8389739 | J12: 8462781 | K12: 8593283 | L12: 8575336 | M12: 8539374 | N12: 8603509 | O12: 8596363 | P12: 8705899 | Q12: 8660370 | R12: 8586606 | S12: 8508537 | T12: 8417195 | U12: 8247351 | V12: 8195954
A13: 60-69세 | B13: 4090354 | C13: 4149296 | D13: 4252495 | E13: 4358060 | F13: 4546950 | G13: 4856462 | H13: 5204346 | I13: 5456887 | J13: 5745656 | K13: 6076571 | L13: 6476602 | M13: 6959660 | N13: 7211963 | O13: 7532388 | P13: 7720341 | Q13: 7844071 | R13: 7980101 | S13: 8068291 | T13: 8139161 | U13: 8263910 | V13: 8262115
A14: 70-79세 | B14: 2565169 | C14: 2688344 | D14: 2841451 | E14: 2982923 | F14: 3062150 | G14: 3130047 | H14: 3129288 | I14: 3251115 | J14: 3374539 | K14: 3475741 | L14: 3598811 | M14: 3657969 | N14: 3761305 | O14: 3871775 | P14: 4046445 | Q14: 4347619 | R14: 4665354 | S14: 4907263 | T14: 5183887 | U14: 5496486 | V14: 5869554
A15: 80세 이상 | B15: 922626 | C15: 980499 | D15: 1050587 | E15: 1125228 | F15: 1209247 | G15: 1305490 | H15: 1417791 | I15: 1528426 | J15: 1634958 | K15: 1764631 | L15: 1890824 | M15: 2016985 | N15: 2155978 | O15: 2289858 | P15: 2382540 | Q15: 2477683 | R15: 2522199 | S15: 2667343 | T15: 2807907 | U15: 2936935 | V15: 3073495
A17: 전체 인구 | B17: =SUM(B7:B15) | C17: =SUM(C7:C15) | D17: =SUM(D7:D15) | E17: =SUM(E7:E15) | F17: =SUM(F7:F15) | G17: =SUM(G7:G15) | H17: =SUM(H7:H15) | I17: =SUM(I7:I15) | ... V17: =SUM(V7:V15)
A19: ■ B. 전신마취 환자 연령별 비율 (%) [2010~2024 : 환자수(C) ÷ 인구(A) | 2026~2030 : 연령대별 추세에 따른 차별화된(선형회귀·평균)1 추정 방식 적용]
A20: 0-9세 | B20: =B33/B7 | C20: =C33/C7 | D20: =D33/D7 | E20: =E33/E7 | F20: =F33/F7 | G20: =G33/G7 | H20: =H33/H7 | I20: =I33/I7 | ... Q20: =Q33/Q7 | R20: =$L54 | S20: =$L54 | T20: =$L54 | U20: =$L54 | V20: =$L54
A21: 10-19세 | B21: =B34/B8 | C21: =C34/C8 | D21: =D34/D8 | E21: =E34/E8 | F21: =F34/F8 | G21: =G34/G8 | H21: =H34/H8 | I21: =I34/I8 | ... Q21: =Q34/Q8 | R21: =$L55 | S21: =$L55 | T21: =$L55 | U21: =$L55 | V21: =$L55
A22: 20-29세 | B22: =B35/B9 | C22: =C35/C9 | D22: =D35/D9 | E22: =E35/E9 | F22: =F35/F9 | G22: =G35/G9 | H22: =H35/H9 | I22: =I35/I9 | ... Q22: =Q35/Q9 | R22: =$L56 | S22: =$L56 | T22: =$L56 | U22: =$L56 | V22: =$L56
A23: 30-39세 | B23: =B36/B10 | C23: =C36/C10 | D23: =D36/D10 | E23: =E36/E10 | F23: =F36/F10 | G23: =G36/G10 | H23: =H36/H10 | I23: =I36/I10 | ... Q23: =Q36/Q10 | R23: =$C$57*R$5+$D$57 | S23: =$C$57*S$5+$D$57 | T23: =$C$57*T$5+$D$57 | U23: =$C$57*U$5+$D$57 | V23: =$C$57*V$5+$D$57
A24: 40-49세 | B24: =B37/B11 | C24: =C37/C11 | D24: =D37/D11 | E24: =E37/E11 | F24: =F37/F11 | G24: =G37/G11 | H24: =H37/H11 | I24: =I37/I11 | ... Q24: =Q37/Q11 | R24: =$C$58*R$5+$D$58 | S24: =$C$58*S$5+$D$58 | T24: =$C$58*T$5+$D$58 | U24: =$C$58*U$5+$D$58 | V24: =$C$58*V$5+$D$58
A25: 50-59세 | B25: =B38/B12 | C25: =C38/C12 | D25: =D38/D12 | E25: =E38/E12 | F25: =F38/F12 | G25: =G38/G12 | H25: =H38/H12 | I25: =I38/I12 | ... Q25: =Q38/Q12 | R25: =$C$59*R$5+$D$59 | S25: =$C$59*S$5+$D$59 | T25: =$C$59*T$5+$D$59 | U25: =$C$59*U$5+$D$59 | V25: =$C$59*V$5+$D$59
A26: 60-69세 | B26: =B39/B13 | C26: =C39/C13 | D26: =D39/D13 | E26: =E39/E13 | F26: =F39/F13 | G26: =G39/G13 | H26: =H39/H13 | I26: =I39/I13 | ... Q26: =Q39/Q13 | R26: =$L60 | S26: =$L60 | T26: =$L60 | U26: =$L60 | V26: =$L60
A27: 70-79세 | B27: =B40/B14 | C27: =C40/C14 | D27: =D40/D14 | E27: =E40/E14 | F27: =F40/F14 | G27: =G40/G14 | H27: =H40/H14 | I27: =I40/I14 | ... Q27: =Q40/Q14 | R27: =$L61 | S27: =$L61 | T27: =$L61 | U27: =$L61 | V27: =$L61
A28: 80세 이상 | B28: =B41/B15 | C28: =C41/C15 | D28: =D41/D15 | E28: =E41/E15 | F28: =F41/F15 | G28: =G41/G15 | H28: =H41/H15 | I28: =I41/I15 | ... Q28: =Q41/Q15 | R28: =$L62 | S28: =$L62 | T28: =$L62 | U28: =$L62 | V28: =$L62
A30: 전체 비율 | B30: =B42/B17 | C30: =C42/C17 | D30: =D42/D17 | E30: =E42/E17 | F30: =F42/F17 | G30: =G42/G17 | H30: =H42/H17 | I30: =I42/I17 | ... V30: =V42/V17
A32: ■ C. 전신마취 환자수 (명) [2010~2025 : NHIS L1211+1212 실측 | 2026~2030 : 인구(A) ×유병률(B)]
A33: 0-9세 | B33: 91549 | C33: 94141 | D33: 91485 | E33: 81220 | F33: 69973 | G33: 68365 | H33: 69178 | I33: 66073 | J33: 63030 | K33: 65230 | L33: 60427 | M33: 60799 | N33: 52238 | O33: 56676 | P33: 51839 | Q33: 50130 | R33: =R7*R20 | S33: =S7*S20 | T33: =T7*T20 | U33: =U7*U20 | V33: =V7*V20
A34: 10-19세 | B34: 85028 | C34: 85974 | D34: 83270 | E34: 68438 | F34: 59440 | G34: 57229 | H34: 54783 | I34: 52126 | J34: 50607 | K34: 52324 | L34: 46041 | M34: 48668 | N34: 47831 | O34: 54607 | P34: 50925 | Q34: 48269 | R34: =R8*R21 | S34: =S8*S21 | T34: =T8*T21 | U34: =U8*U21 | V34: =V8*V21
A35: 20-29세 | B35: 106295 | C35: 104595 | D35: 96499 | E35: 79774 | F35: 71919 | G35: 70926 | H35: 72683 | I35: 72896 | J35: 73407 | K35: 76718 | L35: 80056 | M35: 83325 | N35: 73269 | O35: 79137 | P35: 68668 | Q35: 63263 | R35: =R9*R22 | S35: =S9*S22 | T35: =T9*T22 | U35: =U9*U22 | V35: =V9*V22
A36: 30-39세 | B36: 160278 | C36: 164919 | D36: 155026 | E36: 128602 | F36: 111068 | G36: 105403 | H36: 108007 | I36: 109215 | J36: 115054 | K36: 121341 | L36: 128162 | M36: 136317 | N36: 124795 | O36: 141642 | P36: 143729 | Q36: 146765 | R36: =R10*R23 | S36: =S10*S23 | T36: =T10*T23 | U36: =U10*U23 | V36: =V10*V23
A37: 40-49세 | B37: 186193 | C37: 194364 | D37: 197341 | E37: 179260 | F37: 160846 | G37: 155333 | H37: 159218 | I37: 163077 | J37: 164682 | K37: 172066 | L37: 177078 | M37: 188877 | N37: 176764 | O37: 200802 | P37: 193171 | Q37: 189380 | R37: =R11*R24 | S37: =S11*S24 | T37: =T11*T24 | U37: =U11*U24 | V37: =V11*V24
A38: 50-59세 | B38: 183476 | C38: 210154 | D38: 228633 | E38: 226930 | F38: 216983 | G38: 212264 | H38: 220085 | I38: 224670 | J38: 226503 | K38: 235230 | L38: 229149 | M38: 233720 | N38: 209986 | O38: 233718 | P38: 216988 | Q38: 208245 | R38: =R12*R25 | S38: =S12*S25 | T38: =T12*T25 | U38: =U12*U25 | V38: =V12*V25
A39: 60-69세 | B39: 142696 | C39: 151713 | D39: 162479 | E39: 161483 | F39: 160733 | G39: 166083 | H39: 184401 | I39: 195728 | J39: 208663 | K39: 227810 | L39: 235289 | M39: 264146 | N39: 245410 | O39: 285692 | P39: 263680 | Q39: 256213 | R39: =R13*R26 | S39: =S13*S26 | T39: =T13*T26 | U39: =U13*U26 | V39: =V13*V26
A40: 70-79세 | B40: 85079 | C40: 94253 | D40: 107145 | E40: 112868 | F40: 112731 | G40: 115519 | H40: 124513 | I40: 131691 | J40: 141224 | K40: 154468 | L40: 154805 | M40: 168787 | N40: 157255 | O40: 182283 | P40: 171560 | Q40: 176851 | R40: =R14*R27 | S40: =S14*S27 | T40: =T14*T27 | U40: =U14*U27 | V40: =V14*V27
A41: 80세 이상 | B41: 16600 | C41: 19224 | D41: 22599 | E41: 24942 | F41: 26737 | G41: 30632 | H41: 35933 | I41: 41037 | J41: 46209 | K41: 52818 | L41: 56532 | M41: 64359 | N41: 64234 | O41: 77794 | P41: 71940 | Q41: 72465 | R41: =R15*R28 | S41: =S15*S28 | T41: =T15*T28 | U41: =U15*U28 | V41: =V15*V28
A42: ▶ 전체 전신마취 환자수 | B42: =SUM(B33:B41) | C42: =SUM(C33:C41) | D42: =SUM(D33:D41) | E42: =SUM(E33:E41) | F42: =SUM(F33:F41) | G42: =SUM(G33:G41) | H42: =SUM(H33:H41) | I42: =SUM(I33:I41) | ... V42: =SUM(V33:V41)
A43: 성장률(YoY) | C43: =C42/B42-1 | D43: =D42/C42-1 | E43: =E42/D42-1 | F43: =F42/E42-1 | G43: =G42/F42-1 | H43: =H42/G42-1 | I43: =I42/H42-1 | J43: =J42/I42-1 | ... V43: =V42/U42-1
B45: [참고]
B46: 1)연령대별 전신마취 환자 비율 추정 방법
B47: *분석 데이터: | C47: 2010~2024년 실측 데이터 (50대 미만에서는 2013년 데이터 구조적 변화 확인으로 이후 구간 적용)
...

Sheet 근거_종별전신마취환자수
A2: 종별 전신마취 환자수 : HIRA 종별 분기 실측 기반 회복모형 (2026년 상한 도달 가정)
B4: ◀ 실측 (NHIS, 2010~2024) | R4: 예측 (2026~2030) ▶
A5: 구분 / CY연도 ▶ | B5: 2010 | C5: 2011 | D5: 2012 | E5: 2013 | F5: 2014 | G5: 2015 | H5: 2016 | I5: 2017 | J5: 2018 | K5: 2019 | L5: 2020 | M5: 2021 | N5: 2022 | O5: 2023 | P5: 2024 | Q5: 2025 | R5: 2026 | S5: 2027 | T5: 2028 | U5: 2029 | V5: 2030
A6: ■ A. 전신마취 환자수 (명) [근거_전신마취환자수 참조]
A7: 전신마취환자수 (전체) | B7: ='근거_전신마취환자수'!B42 | C7: ='근거_전신마취환자수'!C42 | D7: ='근거_전신마취환자수'!D42 | E7: ='근거_전신마취환자수'!E42 | F7: ='근거_전신마취환자수'!F42 | G7: ='근거_전신마취환자수'!G42 | H7: ='근거_전신마취환자수'!H42 | I7: ='근거_전신마취환자수'!I42 | ... V7: ='근거_전신마취환자수'!V42
A9: ■ B. 종별 전신마취환자수 비율 [CY2014~24 : NHIS L1211+1212 | 2025 : 회복모형 | 2026~30 : 상한선(추세) 도달 가정]
A10: 상급종합병원 | B10: 0.40611575 | C10: 0.39892588 | D10: 0.41059265 | E10: 0.41523841 | F10: 0.41285457 | G10: 0.42658297 | H10: 0.43335215 | I10: 0.42967143 | J10: 0.41723829 | K10: 0.41075162 | L10: 0.39369144 | M10: 0.41385486 | N10: 0.40923663 | O10: 0.40352919 | P10: 0.32349471 | Q10: 0.33476881 | R10: =(Z56+AA56+AB56+AC56)/R7 | S10: =(AD56+AE56+AF56+AG56)/S7 | T10: =(AH56+AI56+AJ56+AK56)/T7 | U10: =(AL56+AM56+AN56+AO56)/U7 | V10: =(AP56+AQ56+AR56+AS56)/V7
A11: 종합병원 | B11: 0.34194774 | C11: 0.34789424 | D11: 0.35025632 | E11: 0.34764788 | F11: 0.33372282 | G11: 0.3240481 | H11: 0.32375132 | I11: 0.3257661 | J11: 0.33276331 | K11: 0.34437743 | L11: 0.35498678 | M11: 0.33924543 | N11: 0.34967121 | O11: 0.35835193 | P11: 0.39541189 | Q11: 0.38699743 | R11: =(Z57+AA57+AB57+AC57)/R7 | S11: =(AD57+AE57+AF57+AG57)/S7 | T11: =(AH57+AI57+AJ57+AK57)/T7 | U11: =(AL57+AM57+AN57+AO57)/U7 | V11: =(AP57+AQ57+AR57+AS57)/V7
A12: 병원급 | B12: 0.19372148 | C12: 0.19962898 | D12: 0.20014809 | E12: 0.20717851 | F12: 0.22170493 | G12: 0.22034575 | H12: 0.21655756 | I12: 0.21698443 | J12: 0.2175548 | K12: 0.21005733 | L12: 0.21080823 | M12: 0.20252056 | N12: 0.19259813 | O12: 0.18617874 | P12: 0.21415637 | Q12: 0.20410908 | R12: =(Z58+AA58+AB58+AC58)/R7 | S12: =(AD58+AE58+AF58+AG58)/S7 | T12: =(AH58+AI58+AJ58+AK58)/T7 | U12: =(AL58+AM58+AN58+AO58)/U7 | V12: =(AP58+AQ58+AR58+AS58)/V7
A13: 의원급 | B13: 0.058199908 | C13: 0.053533934 | D13: 0.038989842 | E13: 0.029926745 | F13: 0.031712638 | G13: 0.029019111 | H13: 0.026336061 | I13: 0.02757616 | J13: 0.032442673 | K13: 0.034813628 | L13: 0.040512684 | M13: 0.044378345 | N13: 0.048494027 | O13: 0.051940139 | P13: 0.066937042 | Q13: 0.074124683 | R13: =(Z59+AA59+AB59+AC59)/R7 | S13: =(AD59+AE59+AF59+AG59)/S7 | T13: =(AH59+AI59+AJ59+AK59)/T7 | U13: =(AL59+AM59+AN59+AO59)/U7 | V13: =(AP59+AQ59+AR59+AS59)/V7
A14: 보건기관등 | B14: 1.5123488e-05 | C14: 1.6961741e-05 | D14: 1.3097611e-05 | E14: 8.4568027e-06 | F14: 5.0451236e-06 | G14: 4.0714292e-06 | H14: 2.9141407e-06 | I14: 1.8918881e-06 | J14: 9.1741857e-07 | K14: 0 | L14: 8.5607057e-07 | M14: 8.0022983e-07 | N14: 0 | O14: 0 | P14: 0 | Q14: 0 | R14: 0 | S14: 0 | T14: 0 | U14: 0 | V14: 0
A16: ■ C. 종별 전신마취환자수 [전신마취환자수(A) x 종별 비율(B)]
A17: 상급종합병원 | B17: =B$7*B10 | C17: =C$7*C10 | D17: =D$7*D10 | E17: =E$7*E10 | F17: =F$7*F10 | G17: =G$7*G10 | H17: =H$7*H10 | I17: =I$7*I10 | ... V17: =V$7*V10
A18: 종합병원 | B18: =B$7*B11 | C18: =C$7*C11 | D18: =D$7*D11 | E18: =E$7*E11 | F18: =F$7*F11 | G18: =G$7*G11 | H18: =H$7*H11 | I18: =I$7*I11 | ... V18: =V$7*V11
A19: 병원급 | B19: =B$7*B12 | C19: =C$7*C12 | D19: =D$7*D12 | E19: =E$7*E12 | F19: =F$7*F12 | G19: =G$7*G12 | H19: =H$7*H12 | I19: =I$7*I12 | ... V19: =V$7*V12
A20: 의원급 | B20: =B$7*B13 | C20: =C$7*C13 | D20: =D$7*D13 | E20: =E$7*E13 | F20: =F$7*F13 | G20: =G$7*G13 | H20: =H$7*H13 | I20: =I$7*I13 | ... V20: =V$7*V13
A21: 보건기관등 | B21: =B$7*B14 | C21: =C$7*C14 | D21: =D$7*D14 | E21: =E$7*E14 | F21: =F$7*F14 | G21: =G$7*G14 | H21: =H$7*H14 | I21: =I$7*I14 | ... V21: =V$7*V14
A23: ■ D. 종별 비율 회복모형 파라미터 [분기 실측(2025Q1~2025Q4) 선형추세 · 상한/하한 · 의원 S-curve]
B24: 연령대 | C24: 상한/하한 | D24: 기울기(slope) | E24: 절편(intercept) | F24: 기울기(logit,S-curve)
B25: 상급종합병원 환자비율 | C25: 0.41 | D25: =SLOPE(S44:Y44,$S$40:$Y$40) | E25: =INTERCEPT(S44:Y44,$S$40:$Y$40)
B26: 종합병원 환자비율 (분기) | C26: 0.4 | D26: =SLOPE(S45:Y45,$S$40:$Y$40) | E26: =INTERCEPT(S45:Y45,$S$40:$Y$40)
B27: 병원급 환자비율 (분기) | C27: 0.1 | D27: =SLOPE(S46:Y46,$S$40:$Y$40) | E27: =INTERCEPT(S46:Y46,$S$40:$Y$40)
B28: 의원급 환자비율 (분기) | C28: 0.1 | D28: =SLOPE(S47:Y47,$S$40:$Y$40) | E28: =INTERCEPT(S47:Y47,$S$40:$Y$40) | F28: =SLOPE(S48:Z48,$S$40:$Z$40)
A30: ※ 출처 : NHIS 전신마취환자수 (2010~2025), HIRA 종별 분기 실측 (2020Q1~2026Q1)
A31: ※ 범례
A32: · 외부 입력 데이터: 청색(Blue) 표기
A33: · 예측 변수(또는 예측치): 녹색(Green) 표기
A34: · 최종 산출 결과: 황색(Yellow) 음영 행
A36: ■ B-1. 종별 비율 분기 모델 (B의 산출 근거) [CY 분기 실측 + 롤링 예측 → 4분기 합산으로 B·C의 2025~2030 값 생성]
A37: ※ B(종별환자비율)는 HIRA 분기실측 기반 분기 직접모델링 (백테스트로 연간모델 대비 정확도 확인). 종별 분기 환자수(56~59행)는 근거_Ramosetron 시장 수량의 종별 수량 산출에 사용
A39: 구분 / CY분기 ▶ | B39: 2020Q1 | C39: 2020Q2 | D39: 2020Q3 | E39: 2020Q4 | F39: 2021Q1 | G39: 2021Q2 | H39: 2021Q3 | I39: 2021Q4 | J39: 2022Q1 | K39: 2022Q2 | L39: 2022Q3 | M39: 2022Q4 | N39: 2023Q1 | O39: 2023Q2 | P39: 2023Q3 | Q39: 2023Q4 | R39: 2024Q1 | S39: 2024Q2 | T39: 2024Q3 | U39: 2024Q4 | V39: 2025Q1 | W39: 2025Q2 | X39: 2025Q3 | Y39: 2025Q4 | Z39: 2026Q1 | AA39: 2026Q2 | AB39: 2026Q3 | AC39: 2026Q4 | AD39: 2027Q1 | AE39: 2027Q2 | AF39: 2027Q3 | AG39: 2027Q4 | AH39: 2028Q1 | AI39: 2028Q2 | AJ39: 2028Q3 | AK39: 2028Q4 | AL39: 2029Q1 | AM39: 2029Q2 | AN39: 2029Q3 | AO39: 2029Q4 | AP39: 2030Q1 | AQ39: 2030Q2 | AR39: 2030Q3 | AS39: 2030Q4 | AT39: 2031Q1
A40: 분기 순번(추세계산용) | B40: 1 | C40: 2 | D40: 3 | E40: 4 | F40: 5 | G40: 6 | H40: 7 | I40: 8 | J40: 9 | K40: 10 | L40: 11 | M40: 12 | N40: 13 | O40: 14 | P40: 15 | Q40: 16 | R40: 17 | S40: 18 | T40: 19 | U40: 20 | V40: 21 | W40: 22 | X40: 23 | Y40: 24 | Z40: 25 | AA40: 26 | AB40: 27 | AC40: 28 | AD40: 29 | AE40: 30 | AF40: 31 | AG40: 32 | AH40: 33 | AI40: 34 | AJ40: 35 | AK40: 36 | AL40: 37 | AM40: 38 | AN40: 39 | AO40: 40 | AP40: 41 | AQ40: 42 | AR40: 43 | AS40: 44 | AT40: 45
A41: ▶ 전체 전신마취환자수 (분기) [실측HIRA합계~2025Q4 / 미래는 연령모델 연간환자수×분기비중] | B41: 298057 | C41: 284248 | D41: 287449 | E41: 298374 | F41: 314963 | G41: 308831 | H41: 311462 | I41: 314385 | J41: 304354 | K41: 314775 | L41: 320993 | M41: 320425 | N41: 342701 | O41: 321578 | P41: 325581 | Q41: 323190 | R41: 320414 | S41: 291697 | T41: 308119 | U41: 312869 | V41: 329008 | W41: 322560 | X41: 350758 | Y41: 330334 | Z41: =R7*$B$62/($B$62+$B$63+$B$64+$B$65) | AA41: =R7*$B$63/($B$62+$B$63+$B$64+$B$65) | AB41: =R7*$B$64/($B$62+$B$63+$B$64+$B$65) | AC41: =R7*$B$65/($B$62+$B$63+$B$64+$B$65) | AD41: =S7*$B$62/($B$62+$B$63+$B$64+$B$65) | AE41: =S7*$B$63/($B$62+$B$63+$B$64+$B$65) | AF41: =S7*$B$64/($B$62+$B$63+$B$64+$B$65) | AG41: =S7*$B$65/($B$62+$B$63+$B$64+$B$65) | AH41: =T7*$B$62/($B$62+$B$63+$B$64+$B$65) | AI41: =T7*$B$63/($B$62+$B$63+$B$64+$B$65) | AJ41: =T7*$B$64/($B$62+$B$63+$B$64+$B$65) | AK41: =T7*$B$65/($B$62+$B$63+$B$64+$B$65) | AL41: =U7*$B$62/($B$62+$B$63+$B$64+$B$65) | AM41: =U7*$B$63/($B$62+$B$63+$B$64+$B$65) | AN41: =U7*$B$64/($B$62+$B$63+$B$64+$B$65) | AO41: =U7*$B$65/($B$62+$B$63+$B$64+$B$65) | AP41: =V7*$B$62/($B$62+$B$63+$B$64+$B$65) | AQ41: =V7*$B$63/($B$62+$B$63+$B$64+$B$65) | AR41: =V7*$B$64/($B$62+$B$63+$B$64+$B$65) | AS41: =V7*$B$65/($B$62+$B$63+$B$64+$B$65) | AT41: =(V7*V7/U7)*$B$62/($B$62+$B$63+$B$64+$B$65)
A43: [정규화 전 — 종별 독립 예측치 (상한·하한·S-curve 적용, 합이 100%가 아님 · 중간 계산)]
A44: 상급종합병원 환자비율 (분기) [실측HIRA / 미래는 최근4개분기평균] | B44: =원자료_분기실측!B5/B41 | C44: =원자료_분기실측!C5/C41 | D44: =원자료_분기실측!D5/D41 | E44: =원자료_분기실측!E5/E41 | F44: =원자료_분기실측!F5/F41 | G44: =원자료_분기실측!G5/G41 | H44: =원자료_분기실측!H5/H41 | I44: =원자료_분기실측!I5/I41 | ... Y44: =원자료_분기실측!Y5/Y41 | Z44: =MIN($C$25,$D25*Z$40+$E25) | AA44: =MIN($C$25,$D25*AA$40+$E25) | AB44: =MIN($C$25,$D25*AB$40+$E25) | AC44: =MIN($C$25,$D25*AC$40+$E25) | AD44: =MIN($C$25,$D25*AD$40+$E25) | AE44: =MIN($C$25,$D25*AE$40+$E25) | AF44: =MIN($C$25,$D25*AF$40+$E25) | AG44: =MIN($C$25,$D25*AG$40+$E25) | ... AT44: =MIN($C$25,$D25*AT$40+$E25)
A45: 종합병원 환자비율 (분기) [실측HIRA / 미래는 최근4개분기평균] | B45: =원자료_분기실측!B6/B41 | C45: =원자료_분기실측!C6/C41 | D45: =원자료_분기실측!D6/D41 | E45: =원자료_분기실측!E6/E41 | F45: =원자료_분기실측!F6/F41 | G45: =원자료_분기실측!G6/G41 | H45: =원자료_분기실측!H6/H41 | I45: =원자료_분기실측!I6/I41 | ... Y45: =원자료_분기실측!Y6/Y41 | Z45: =MAX($C$26,$D26*Z$40+$E26) | AA45: =MAX($C$26,$D26*AA$40+$E26) | AB45: =MAX($C$26,$D26*AB$40+$E26) | AC45: =MAX($C$26,$D26*AC$40+$E26) | AD45: =MAX($C$26,$D26*AD$40+$E26) | AE45: =MAX($C$26,$D26*AE$40+$E26) | AF45: =MAX($C$26,$D26*AF$40+$E26) | AG45: =MAX($C$26,$D26*AG$40+$E26) | ... AT45: =MAX($C$26,$D26*AT$40+$E26)
A46: 병원급 환자비율 (분기) [실측HIRA / 미래는 최근4개분기평균] | B46: =원자료_분기실측!B7/B41 | C46: =원자료_분기실측!C7/C41 | D46: =원자료_분기실측!D7/D41 | E46: =원자료_분기실측!E7/E41 | F46: =원자료_분기실측!F7/F41 | G46: =원자료_분기실측!G7/G41 | H46: =원자료_분기실측!H7/H41 | I46: =원자료_분기실측!I7/I41 | ... Y46: =원자료_분기실측!Y7/Y41 | Z46: =MAX($C$27,$D27*Z$40+$E27) | AA46: =MAX($C$27,$D27*AA$40+$E27) | AB46: =MAX($C$27,$D27*AB$40+$E27) | AC46: =MAX($C$27,$D27*AC$40+$E27) | AD46: =MAX($C$27,$D27*AD$40+$E27) | AE46: =MAX($C$27,$D27*AE$40+$E27) | AF46: =MAX($C$27,$D27*AF$40+$E27) | AG46: =MAX($C$27,$D27*AG$40+$E27) | ... AT46: =MAX($C$27,$D27*AT$40+$E27)
A47: 의원급 환자비율 (분기) [실측HIRA / 미래는 최근8개분기선형추세] | B47: =원자료_분기실측!B8/B41 | C47: =원자료_분기실측!C8/C41 | D47: =원자료_분기실측!D8/D41 | E47: =원자료_분기실측!E8/E41 | F47: =원자료_분기실측!F8/F41 | G47: =원자료_분기실측!G8/G41 | H47: =원자료_분기실측!H8/H41 | I47: =원자료_분기실측!I8/I41 | ... Y47: =원자료_분기실측!Y8/Y41 | Z47: =$C$28/(1+EXP(-(LN($Y$47/($C$28-$Y$47))+$F$28*(Z40-$Y$40)))) | AA47: =$C$28/(1+EXP(-(LN($Y$47/($C$28-$Y$47))+$F$28*(AA40-$Y$40)))) | AB47: =$C$28/(1+EXP(-(LN($Y$47/($C$28-$Y$47))+$F$28*(AB40-$Y$40)))) | AC47: =$C$28/(1+EXP(-(LN($Y$47/($C$28-$Y$47))+$F$28*(AC40-$Y$40)))) | AD47: =$C$28/(1+EXP(-(LN($Y$47/($C$28-$Y$47))+$F$28*(AD40-$Y$40)))) | AE47: =$C$28/(1+EXP(-(LN($Y$47/($C$28-$Y$47))+$F$28*(AE40-$Y$40)))) | AF47: =$C$28/(1+EXP(-(LN($Y$47/($C$28-$Y$47))+$F$28*(AF40-$Y$40)))) | AG47: =$C$28/(1+EXP(-(LN($Y$47/($C$28-$Y$47))+$F$28*(AG40-$Y$40)))) | ... AT47: =$C$28/(1+EXP(-(LN($Y$47/($C$28-$Y$47))+$F$28*(AT40-$Y$40))))
A48: [의원급 S-curve 로짓변환] | S48: =LN(S47/($C$28-S47)) | T48: =LN(T47/($C$28-T47)) | U48: =LN(U47/($C$28-U47)) | V48: =LN(V47/($C$28-V47)) | W48: =LN(W47/($C$28-W47)) | X48: =LN(X47/($C$28-X47)) | Y48: =LN(Y47/($C$28-Y47))
A50: [정규화 후 — 4종별 합 = 100%로 조정 (모델 사용값)]
...

Sheet 근거_Ramosetron 시장 수량
A2: Ramosetron 시장 수량 : 종별 전신마취 환자수 × 종별 환자당 사용량 (IQVIA·NHIS 기반)
B4: ◀ 실측 (NHIS, 2010~2024) | R4: 예측 (2026~2030) ▶
A5: 구분 / CY연도 ▶ | B5: 2010 | C5: 2011 | D5: 2012 | E5: 2013 | F5: 2014 | G5: 2015 | H5: 2016 | I5: 2017 | J5: 2018 | K5: 2019 | L5: 2020 | M5: 2021 | N5: 2022 | O5: 2023 | P5: 2024 | Q5: 2025 | R5: 2026 | S5: 2027 | T5: 2028 | U5: 2029 | V5: 2030
A6: ■ A. 종별 전신마취 환자수 (명) [근거_종별전신마취환자수 C 참조]
A7: 상급종합병원 | B7: ='근거_종별전신마취환자수'!B17 | C7: ='근거_종별전신마취환자수'!C17 | D7: ='근거_종별전신마취환자수'!D17 | E7: ='근거_종별전신마취환자수'!E17 | F7: ='근거_종별전신마취환자수'!F17 | G7: ='근거_종별전신마취환자수'!G17 | H7: ='근거_종별전신마취환자수'!H17 | I7: ='근거_종별전신마취환자수'!I17 | ... V7: ='근거_종별전신마취환자수'!V17
A8: 종합병원 | B8: ='근거_종별전신마취환자수'!B18 | C8: ='근거_종별전신마취환자수'!C18 | D8: ='근거_종별전신마취환자수'!D18 | E8: ='근거_종별전신마취환자수'!E18 | F8: ='근거_종별전신마취환자수'!F18 | G8: ='근거_종별전신마취환자수'!G18 | H8: ='근거_종별전신마취환자수'!H18 | I8: ='근거_종별전신마취환자수'!I18 | ... V8: ='근거_종별전신마취환자수'!V18
A9: 병원급 | B9: ='근거_종별전신마취환자수'!B19 | C9: ='근거_종별전신마취환자수'!C19 | D9: ='근거_종별전신마취환자수'!D19 | E9: ='근거_종별전신마취환자수'!E19 | F9: ='근거_종별전신마취환자수'!F19 | G9: ='근거_종별전신마취환자수'!G19 | H9: ='근거_종별전신마취환자수'!H19 | I9: ='근거_종별전신마취환자수'!I19 | ... V9: ='근거_종별전신마취환자수'!V19
A10: 의원급 | B10: ='근거_종별전신마취환자수'!B20 | C10: ='근거_종별전신마취환자수'!C20 | D10: ='근거_종별전신마취환자수'!D20 | E10: ='근거_종별전신마취환자수'!E20 | F10: ='근거_종별전신마취환자수'!F20 | G10: ='근거_종별전신마취환자수'!G20 | H10: ='근거_종별전신마취환자수'!H20 | I10: ='근거_종별전신마취환자수'!I20 | ... V10: ='근거_종별전신마취환자수'!V20
A12: ■ B. Ramosetron 전체 수량 [2020~25 : IQVIA 기준, CY기준 ]
A13: Ramosetron (Vial or Ampoule) | L13: 3086324 | M13: 3529267 | N13: 3623943 | O13: 4166540 | P13: 3554307 | Q13: 3874647
A15: ■ C. 흡입마취제 사용량의 종별 비율 (%) [2020~25 : NHIS N01AB Halogenated hydrocarbons, CY기준]
A16: 상급종합병원 | L16: 0.37283534 | M16: 0.48208734 | N16: 0.52756862 | O16: 0.54469656 | P16: 0.4179469 | Q16: 0.43178314
A17: 종합병원 | L17: 0.32230249 | M17: 0.31692832 | N17: 0.32179792 | O17: 0.3277461 | P17: 0.42863765 | Q17: 0.42890484
A18: 병원 | L18: 0.27831834 | M18: 0.17813561 | N18: 0.1331923 | O18: 0.11046668 | P18: 0.13239123 | Q18: 0.11843795
A19: 의원 | L19: 0.026543837 | M19: 0.022848737 | N19: 0.017441161 | O19: 0.017090654 | P19: 0.021024223 | Q19: 0.020874075
A21: ■ D. 종별 환자당 Ramosetron 사용수량 (추정) [ Ramosetron 수량(B) x 흡입마취제 종별비율(C) ÷ 종별 전신마취 환자수(A) ]
A22: 상급종합병원 | L22: =L16*L$13/L7 | M22: =M16*M$13/M7 | N22: =N16*N$13/N7 | O22: =O16*O$13/O7 | P22: =P16*P$13/P7 | Q22: =Q16*Q$13/Q7 | R22: =MIN(5,SLOPE($L$22:$Q$22,$L$5:$Q$5)*R$5+INTERCEPT($L$22:$Q$22,$L$5:$Q$5)) | S22: =MIN(5,SLOPE($L$22:$Q$22,$L$5:$Q$5)*S$5+INTERCEPT($L$22:$Q$22,$L$5:$Q$5)) | T22: =MIN(5,SLOPE($L$22:$Q$22,$L$5:$Q$5)*T$5+INTERCEPT($L$22:$Q$22,$L$5:$Q$5)) | U22: =MIN(5,SLOPE($L$22:$Q$22,$L$5:$Q$5)*U$5+INTERCEPT($L$22:$Q$22,$L$5:$Q$5)) | V22: =MIN(5,SLOPE($L$22:$Q$22,$L$5:$Q$5)*V$5+INTERCEPT($L$22:$Q$22,$L$5:$Q$5))
A23: 종합병원 | L23: =L17*L$13/L8 | M23: =M17*M$13/M8 | N23: =N17*N$13/N8 | O23: =O17*O$13/O8 | P23: =P17*P$13/P8 | Q23: =Q17*Q$13/Q8 | R23: =MIN(4,SLOPE($L$23:$Q$23,$L$5:$Q$5)*R$5+INTERCEPT($L$23:$Q$23,$L$5:$Q$5)) | S23: =MIN(4,SLOPE($L$23:$Q$23,$L$5:$Q$5)*S$5+INTERCEPT($L$23:$Q$23,$L$5:$Q$5)) | T23: =MIN(4,SLOPE($L$23:$Q$23,$L$5:$Q$5)*T$5+INTERCEPT($L$23:$Q$23,$L$5:$Q$5)) | U23: =MIN(4,SLOPE($L$23:$Q$23,$L$5:$Q$5)*U$5+INTERCEPT($L$23:$Q$23,$L$5:$Q$5)) | V23: =MIN(4,SLOPE($L$23:$Q$23,$L$5:$Q$5)*V$5+INTERCEPT($L$23:$Q$23,$L$5:$Q$5))
A24: 병원 | L24: =L18*L$13/L9 | M24: =M18*M$13/M9 | N24: =N18*N$13/N9 | O24: =O18*O$13/O9 | P24: =P18*P$13/P9 | Q24: =Q18*Q$13/Q9 | R24: =Q24 | S24: =R24 | T24: =S24 | U24: =T24 | V24: =U24
A25: 의원 | L25: =L19*L$13/L10 | M25: =M19*M$13/M10 | N25: =N19*N$13/N10 | O25: =O19*O$13/O10 | P25: =P19*P$13/P10 | Q25: =Q19*Q$13/Q10 | R25: =Q25 | S25: =R25 | T25: =S25 | U25: =T25 | V25: =U25
A28: ■ E. 종별 Ramosetron 수량 (추정) FY기준 [ 종별 전신마취환자수 (A) x 종별 환자당 Ramosetron 사용수량 (D) ]
A29: 상급종합병원 | L29: =SUM(C47:F47) | M29: =SUM(G47:J47) | N29: =SUM(K47:N47) | O29: =SUM(O47:R47) | P29: =SUM(S47:V47) | Q29: =SUM(W47:Z47) | R29: =SUM(AA47:AD47) | S29: =SUM(AE47:AH47) | T29: =SUM(AI47:AL47) | U29: =SUM(AM47:AP47) | V29: =SUM(AQ47:AT47)
A30: 종합병원 | L30: =SUM(C48:F48) | M30: =SUM(G48:J48) | N30: =SUM(K48:N48) | O30: =SUM(O48:R48) | P30: =SUM(S48:V48) | Q30: =SUM(W48:Z48) | R30: =SUM(AA48:AD48) | S30: =SUM(AE48:AH48) | T30: =SUM(AI48:AL48) | U30: =SUM(AM48:AP48) | V30: =SUM(AQ48:AT48)
A31: 병원 | L31: =SUM(C49:F49) | M31: =SUM(G49:J49) | N31: =SUM(K49:N49) | O31: =SUM(O49:R49) | P31: =SUM(S49:V49) | Q31: =SUM(W49:Z49) | R31: =SUM(AA49:AD49) | S31: =SUM(AE49:AH49) | T31: =SUM(AI49:AL49) | U31: =SUM(AM49:AP49) | V31: =SUM(AQ49:AT49)
A32: 의원 | L32: =SUM(C50:F50) | M32: =SUM(G50:J50) | N32: =SUM(K50:N50) | O32: =SUM(O50:R50) | P32: =SUM(S50:V50) | Q32: =SUM(W50:Z50) | R32: =SUM(AA50:AD50) | S32: =SUM(AE50:AH50) | T32: =SUM(AI50:AL50) | U32: =SUM(AM50:AP50) | V32: =SUM(AQ50:AT50)
A33: ▶ Ramosetron 시장 수량 (IQVIA 기준) | L33: =SUM(L29:L32) | M33: =SUM(M29:M32) | N33: =SUM(N29:N32) | O33: =SUM(O29:O32) | P33: =SUM(P29:P32) | Q33: =SUM(Q29:Q32) | R33: =SUM(R29:R32) | S33: =SUM(S29:S32) | ... V33: =SUM(V29:V32)
M34: =M33/L33-1 | N34: =N33/M33-1 | O34: =O33/N33-1 | P34: =P33/O33-1 | Q34: =Q33/P33-1 | R34: =R33/Q33-1 | S34: =S33/R33-1 | T34: =T33/S33-1 | ... V34: =V33/U33-1
A36: ※ 출처 : IQVIA (FY2020~2025) BI 자체 추정, NHIS 흡입마취제(N01AB) 종별 사용량
A37: ※ 범례
A38: · 외부 입력 데이터: 청색(Blue) 표기
A39: · 예측 변수(또는 예측치): 녹색(Green) 표기
A40: · 최종 산출 결과: 황색(Yellow) 음영 행
A42: ■■■ [분기 확장 블록] CY역년분기 실측+롤링예측 → FY 재구성 ■■■
A43: ※ D(환자당사용량)는 표본부족으로 연간모델 유지, 4개분기에 flat 적용. 종별 분기 환자수는 근거_종별전신마취환자수 56~59행 참조
A45: 구분 / CY분기 ▶ | B45: 2020Q1 | C45: 2020Q2 | D45: 2020Q3 | E45: 2020Q4 | F45: 2021Q1 | G45: 2021Q2 | H45: 2021Q3 | I45: 2021Q4 | J45: 2022Q1 | K45: 2022Q2 | L45: 2022Q3 | M45: 2022Q4 | N45: 2023Q1 | O45: 2023Q2 | P45: 2023Q3 | Q45: 2023Q4 | R45: 2024Q1 | S45: 2024Q2 | T45: 2024Q3 | U45: 2024Q4 | V45: 2025Q1 | W45: 2025Q2 | X45: 2025Q3 | Y45: 2025Q4 | Z45: 2026Q1 | AA45: 2026Q2 | AB45: 2026Q3 | AC45: 2026Q4 | AD45: 2027Q1 | AE45: 2027Q2 | AF45: 2027Q3 | AG45: 2027Q4 | AH45: 2028Q1 | AI45: 2028Q2 | AJ45: 2028Q3 | AK45: 2028Q4 | AL45: 2029Q1 | AM45: 2029Q2 | AN45: 2029Q3 | AO45: 2029Q4 | AP45: 2030Q1 | AQ45: 2030Q2 | AR45: 2030Q3 | AS45: 2030Q4 | AT45: 2031Q1
A47: 상급종합병원 Ramosetron 시장수량 (분기) = 종별환자수×D(연,flat) | B47: =B$57*원자료_분기실측!B23 | C47: =C$57*원자료_분기실측!C23 | D47: =D$57*원자료_분기실측!D23 | E47: =E$57*원자료_분기실측!E23 | F47: =F$57*원자료_분기실측!F23 | G47: =G$57*원자료_분기실측!G23 | H47: =H$57*원자료_분기실측!H23 | I47: =I$57*원자료_분기실측!I23 | ... AA47: =AA$57*원자료_분기실측!AA23 | AB47: ='근거_종별전신마취환자수'!AB56*R22 | AC47: ='근거_종별전신마취환자수'!AC56*R22 | AD47: ='근거_종별전신마취환자수'!AD56*S22 | AE47: ='근거_종별전신마취환자수'!AE56*S22 | AF47: ='근거_종별전신마취환자수'!AF56*S22 | AG47: ='근거_종별전신마취환자수'!AG56*S22 | AH47: ='근거_종별전신마취환자수'!AH56*T22 | AI47: ='근거_종별전신마취환자수'!AI56*T22 | AJ47: ='근거_종별전신마취환자수'!AJ56*T22 | AK47: ='근거_종별전신마취환자수'!AK56*T22 | AL47: ='근거_종별전신마취환자수'!AL56*U22 | AM47: ='근거_종별전신마취환자수'!AM56*U22 | AN47: ='근거_종별전신마취환자수'!AN56*U22 | AO47: ='근거_종별전신마취환자수'!AO56*U22 | AP47: ='근거_종별전신마취환자수'!AP56*V22 | AQ47: ='근거_종별전신마취환자수'!AQ56*V22 | AR47: ='근거_종별전신마취환자수'!AR56*V22 | AS47: ='근거_종별전신마취환자수'!AS56*V22 | AT47: ='근거_종별전신마취환자수'!AT56*V22
A48: 종합병원 Ramosetron 시장수량 (분기) = 종별환자수×D(연,flat) | B48: =B$57*원자료_분기실측!B24 | C48: =C$57*원자료_분기실측!C24 | D48: =D$57*원자료_분기실측!D24 | E48: =E$57*원자료_분기실측!E24 | F48: =F$57*원자료_분기실측!F24 | G48: =G$57*원자료_분기실측!G24 | H48: =H$57*원자료_분기실측!H24 | I48: =I$57*원자료_분기실측!I24 | ... AA48: =AA$57*원자료_분기실측!AA24 | AB48: ='근거_종별전신마취환자수'!AB57*R23 | AC48: ='근거_종별전신마취환자수'!AC57*R23 | AD48: ='근거_종별전신마취환자수'!AD57*S23 | AE48: ='근거_종별전신마취환자수'!AE57*S23 | AF48: ='근거_종별전신마취환자수'!AF57*S23 | AG48: ='근거_종별전신마취환자수'!AG57*S23 | AH48: ='근거_종별전신마취환자수'!AH57*T23 | AI48: ='근거_종별전신마취환자수'!AI57*T23 | AJ48: ='근거_종별전신마취환자수'!AJ57*T23 | AK48: ='근거_종별전신마취환자수'!AK57*T23 | AL48: ='근거_종별전신마취환자수'!AL57*U23 | AM48: ='근거_종별전신마취환자수'!AM57*U23 | AN48: ='근거_종별전신마취환자수'!AN57*U23 | AO48: ='근거_종별전신마취환자수'!AO57*U23 | AP48: ='근거_종별전신마취환자수'!AP57*V23 | AQ48: ='근거_종별전신마취환자수'!AQ57*V23 | AR48: ='근거_종별전신마취환자수'!AR57*V23 | AS48: ='근거_종별전신마취환자수'!AS57*V23 | AT48: ='근거_종별전신마취환자수'!AT57*V23
A49: 병원급 Ramosetron 시장수량 (분기) = 종별환자수×D(연,flat) | B49: =B$57*원자료_분기실측!B25 | C49: =C$57*원자료_분기실측!C25 | D49: =D$57*원자료_분기실측!D25 | E49: =E$57*원자료_분기실측!E25 | F49: =F$57*원자료_분기실측!F25 | G49: =G$57*원자료_분기실측!G25 | H49: =H$57*원자료_분기실측!H25 | I49: =I$57*원자료_분기실측!I25 | ... AA49: =AA$57*원자료_분기실측!AA25 | AB49: ='근거_종별전신마취환자수'!AB58*R24 | AC49: ='근거_종별전신마취환자수'!AC58*R24 | AD49: ='근거_종별전신마취환자수'!AD58*S24 | AE49: ='근거_종별전신마취환자수'!AE58*S24 | AF49: ='근거_종별전신마취환자수'!AF58*S24 | AG49: ='근거_종별전신마취환자수'!AG58*S24 | AH49: ='근거_종별전신마취환자수'!AH58*T24 | AI49: ='근거_종별전신마취환자수'!AI58*T24 | AJ49: ='근거_종별전신마취환자수'!AJ58*T24 | AK49: ='근거_종별전신마취환자수'!AK58*T24 | AL49: ='근거_종별전신마취환자수'!AL58*U24 | AM49: ='근거_종별전신마취환자수'!AM58*U24 | AN49: ='근거_종별전신마취환자수'!AN58*U24 | AO49: ='근거_종별전신마취환자수'!AO58*U24 | AP49: ='근거_종별전신마취환자수'!AP58*V24 | AQ49: ='근거_종별전신마취환자수'!AQ58*V24 | AR49: ='근거_종별전신마취환자수'!AR58*V24 | AS49: ='근거_종별전신마취환자수'!AS58*V24 | AT49: ='근거_종별전신마취환자수'!AT58*V24
A50: 의원급 Ramosetron 시장수량 (분기) = 종별환자수×D(연,flat) | B50: =B$57*원자료_분기실측!B26 | C50: =C$57*원자료_분기실측!C26 | D50: =D$57*원자료_분기실측!D26 | E50: =E$57*원자료_분기실측!E26 | F50: =F$57*원자료_분기실측!F26 | G50: =G$57*원자료_분기실측!G26 | H50: =H$57*원자료_분기실측!H26 | I50: =I$57*원자료_분기실측!I26 | ... AA50: =AA$57*원자료_분기실측!AA26 | AB50: ='근거_종별전신마취환자수'!AB59*R25 | AC50: ='근거_종별전신마취환자수'!AC59*R25 | AD50: ='근거_종별전신마취환자수'!AD59*S25 | AE50: ='근거_종별전신마취환자수'!AE59*S25 | AF50: ='근거_종별전신마취환자수'!AF59*S25 | AG50: ='근거_종별전신마취환자수'!AG59*S25 | AH50: ='근거_종별전신마취환자수'!AH59*T25 | AI50: ='근거_종별전신마취환자수'!AI59*T25 | AJ50: ='근거_종별전신마취환자수'!AJ59*T25 | AK50: ='근거_종별전신마취환자수'!AK59*T25 | AL50: ='근거_종별전신마취환자수'!AL59*U25 | AM50: ='근거_종별전신마취환자수'!AM59*U25 | AN50: ='근거_종별전신마취환자수'!AN59*U25 | AO50: ='근거_종별전신마취환자수'!AO59*U25 | AP50: ='근거_종별전신마취환자수'!AP59*V25 | AQ50: ='근거_종별전신마취환자수'!AQ59*V25 | AR50: ='근거_종별전신마취환자수'!AR59*V25 | AS50: ='근거_종별전신마취환자수'!AS59*V25 | AT50: ='근거_종별전신마취환자수'!AT59*V25
A52: 상급종합병원 환자당 Ramo 사용수량 | B52: =IFERROR(B47/'근거_종별전신마취환자수'!B56,"") | C52: =IFERROR(C47/'근거_종별전신마취환자수'!C56,"") | D52: =IFERROR(D47/'근거_종별전신마취환자수'!D56,"") | E52: =IFERROR(E47/'근거_종별전신마취환자수'!E56,"") | F52: =IFERROR(F47/'근거_종별전신마취환자수'!F56,"") | G52: =IFERROR(G47/'근거_종별전신마취환자수'!G56,"") | H52: =IFERROR(H47/'근거_종별전신마취환자수'!H56,"") | I52: =IFERROR(I47/'근거_종별전신마취환자수'!I56,"") | ... AT52: =IFERROR(AT47/'근거_종별전신마취환자수'!AT56,"")
...

Sheet 근거_NSA수량(IQVIA기준)
A2: NSA 수량 산출 : IQVIA 데이터 기반 예측 (로짓 변환 회귀)
B4: ◀ 실측 (UBIST MS, FY18~25) | J4: 예측 ▶
A5: 구분 / 회계연도 ▶ | B5: FY2018 | C5: FY2019 | D5: FY2020 | E5: FY2021 | F5: FY2022 | G5: FY2023 | H5: FY2024 | I5: FY2025 | J5: FY2026 | K5: FY2027 | L5: FY2028 | M5: FY2029 | N5: FY2030 | P5: FY26 1분기
A6: ■ A. Ramosetron 시장 수량 [근거_Ramosetron 시장 수량]
A7: Ramosetron 주사제 전체 수량 (시장) | D7: ='근거_Ramosetron 시장 수량'!L33 | E7: ='근거_Ramosetron 시장 수량'!M33 | F7: ='근거_Ramosetron 시장 수량'!N33 | G7: ='근거_Ramosetron 시장 수량'!O33 | H7: ='근거_Ramosetron 시장 수량'!P33 | I7: ='근거_Ramosetron 시장 수량'!Q33 | J7: ='근거_Ramosetron 시장 수량'!R33 | K7: ='근거_Ramosetron 시장 수량'!S33 | ... N7: ='근거_Ramosetron 시장 수량'!V33
A9: ■ B. 종별 Ramosetron 수량 : [근거_Ramosetron 시장 수량]
A10: 상급종합병원 | D10: ='근거_Ramosetron 시장 수량'!L29 | E10: ='근거_Ramosetron 시장 수량'!M29 | F10: ='근거_Ramosetron 시장 수량'!N29 | G10: ='근거_Ramosetron 시장 수량'!O29 | H10: ='근거_Ramosetron 시장 수량'!P29 | I10: ='근거_Ramosetron 시장 수량'!Q29 | J10: ='근거_Ramosetron 시장 수량'!R29 | K10: ='근거_Ramosetron 시장 수량'!S29 | ... N10: ='근거_Ramosetron 시장 수량'!V29
A11: 종합병원 | D11: ='근거_Ramosetron 시장 수량'!L30 | E11: ='근거_Ramosetron 시장 수량'!M30 | F11: ='근거_Ramosetron 시장 수량'!N30 | G11: ='근거_Ramosetron 시장 수량'!O30 | H11: ='근거_Ramosetron 시장 수량'!P30 | I11: ='근거_Ramosetron 시장 수량'!Q30 | J11: ='근거_Ramosetron 시장 수량'!R30 | K11: ='근거_Ramosetron 시장 수량'!S30 | ... N11: ='근거_Ramosetron 시장 수량'!V30
A12: 병원 | D12: ='근거_Ramosetron 시장 수량'!L31 | E12: ='근거_Ramosetron 시장 수량'!M31 | F12: ='근거_Ramosetron 시장 수량'!N31 | G12: ='근거_Ramosetron 시장 수량'!O31 | H12: ='근거_Ramosetron 시장 수량'!P31 | I12: ='근거_Ramosetron 시장 수량'!Q31 | J12: ='근거_Ramosetron 시장 수량'!R31 | K12: ='근거_Ramosetron 시장 수량'!S31 | ... N12: ='근거_Ramosetron 시장 수량'!V31
A13: 의원 | D13: ='근거_Ramosetron 시장 수량'!L32 | E13: ='근거_Ramosetron 시장 수량'!M32 | F13: ='근거_Ramosetron 시장 수량'!N32 | G13: ='근거_Ramosetron 시장 수량'!O32 | H13: ='근거_Ramosetron 시장 수량'!P32 | I13: ='근거_Ramosetron 시장 수량'!Q32 | J13: ='근거_Ramosetron 시장 수량'!R32 | K13: ='근거_Ramosetron 시장 수량'!S32 | ... N13: ='근거_Ramosetron 시장 수량'!V32
A15: ■ E. 종별 NSA MS : [ NSA 수량 (C) x NSA 종별 비율 (D) / 종별 Ramosetron 수량 (B) ]
A16: 상급종합병원 | E16: =(G49+H49+I49+J49)/E10 | F16: =(K49+L49+M49+N49)/F10 | G16: =(O49+P49+Q49+R49)/G10 | H16: =(S49+T49+U49+V49)/H10 | I16: =(W49+X49+Y49+Z49)/I10 | J16: =(AA49+AB49+AC49+AD49)/J10 | K16: =(AE49+AF49+AG49+AH49)/K10 | L16: =(AI49+AJ49+AK49+AL49)/L10 | M16: =(AM49+AN49+AO49+AP49)/M10 | N16: =(AQ49+AR49+AS49+AT49)/N10
A17: 종합병원 | E17: =(G50+H50+I50+J50)/E11 | F17: =(K50+L50+M50+N50)/F11 | G17: =(O50+P50+Q50+R50)/G11 | H17: =(S50+T50+U50+V50)/H11 | I17: =(W50+X50+Y50+Z50)/I11 | J17: =(AA50+AB50+AC50+AD50)/J11 | K17: =(AE50+AF50+AG50+AH50)/K11 | L17: =(AI50+AJ50+AK50+AL50)/L11 | M17: =(AM50+AN50+AO50+AP50)/M11 | N17: =(AQ50+AR50+AS50+AT50)/N11
A18: 병원 | E18: =(G51+H51+I51+J51)/E12 | F18: =(K51+L51+M51+N51)/F12 | G18: =(O51+P51+Q51+R51)/G12 | H18: =(S51+T51+U51+V51)/H12 | I18: =(W51+X51+Y51+Z51)/I12 | J18: =(AA51+AB51+AC51+AD51)/J12 | K18: =(AE51+AF51+AG51+AH51)/K12 | L18: =(AI51+AJ51+AK51+AL51)/L12 | M18: =(AM51+AN51+AO51+AP51)/M12 | N18: =(AQ51+AR51+AS51+AT51)/N12
A19: 의원 | E19: =(G52+H52+I52+J52)/E13 | F19: =(K52+L52+M52+N52)/F13 | G19: =(O52+P52+Q52+R52)/G13 | H19: =(S52+T52+U52+V52)/H13 | I19: =(W52+X52+Y52+Z52)/I13 | J19: =(AA52+AB52+AC52+AD52)/J13 | K19: =(AE52+AF52+AG52+AH52)/K13 | L19: =(AI52+AJ52+AK52+AL52)/L13 | M19: =(AM52+AN52+AO52+AP52)/M13 | N19: =(AQ52+AR52+AS52+AT52)/N13
A20: 전체 MS | E20: =E27/E7 | F20: =F27/F7 | G20: =G27/G7 | H20: =H27/H7 | I20: =I27/I7 | J20: =J27/J7 | K20: =K27/K7 | L20: =L27/L7 | ... N20: =N27/N7
A22: ■ F. 종별 NSA 수량 : [ 종별 Ramosetron 수량 (B) x 종별 NSA MS (E) ]
A23: 상급종합병원 | E23: =E10*E16 | F23: =F10*F16 | G23: =G10*G16 | H23: =H10*H16 | I23: =I10*I16 | J23: =J10*J16 | K23: =K10*K16 | L23: =L10*L16 | ... N23: =N10*N16
A24: 종합병원 | E24: =E11*E17 | F24: =F11*F17 | G24: =G11*G17 | H24: =H11*H17 | I24: =I11*I17 | J24: =J11*J17 | K24: =K11*K17 | L24: =L11*L17 | ... N24: =N11*N17
A25: 병원 | E25: =E12*E18 | F25: =F12*F18 | G25: =G12*G18 | H25: =H12*H18 | I25: =I12*I18 | J25: =J12*J18 | K25: =K12*K18 | L25: =L12*L18 | ... N25: =N12*N18
A26: 의원 | E26: =E13*E19 | F26: =F13*F19 | G26: =G13*G19 | H26: =H13*H19 | I26: =I13*I19 | J26: =J13*J19 | K26: =K13*K19 | L26: =L13*L19 | ... N26: =N13*N19
A27: ▶ NSA 수량 (IQVIA 기준) | D27: 1601660 | E27: =SUM(E23:E26) | F27: =SUM(F23:F26) | G27: =SUM(G23:G26) | H27: =SUM(H23:H26) | I27: =SUM(I23:I26) | J27: =SUM(J23:J26) | K27: =SUM(K23:K26) | L27: =SUM(L23:L26) | ... N27: =SUM(N23:N26)
E28: =E27/E7 | F28: =F27/F7 | G28: =G27/G7 | H28: =H27/H7 | I28: =I27/I7 | J28: =J27/J7 | K28: =K27/K7 | L28: =L27/L7 | ... N28: =N27/N7
B30: [참고] 종별 NSA MS 예측 파라미터 (2026Q2~2031Q1 적용)
B31: 유형 | C31: 예측방식 | D31: 분기당 기울기 | E31: 상한/하한 | F31: 백테스트 MAPE
B32: 상급종합병원 | C32: 전체기간선형(레벨보정) | D32: =SLOPE($F$43:$Z$43,$F$40:$Z$40) | E32: 0.55 | F32: 2.92%
B33: 종합병원 | C33: S-curve(로짓변환+저점앵커) | D33: =SLOPE($U$54:$Z$54,$U$40:$Z$40) | E33: 0.56 | F33: 3.83%
B34: 병원 | C34: 롤링4분기평균(갱신) | D34: - | E34: 4분기 이동평균 | F34: 8.89%
B35: 의원 | C35: EWMA(α=0.3) | D35: - | E35: EWMA 마지막값 flat | F35: 10.30%
B36: ※ 채택근거: 2020Q1~2026Q1 실측 walk-forward 백테스트. 상급종합·종합병원은 레벨보정 방식으로 통일(실측→예측 연속성 보장, 갱신 시 급락 리스크 방지)
A39: 구분 / CY분기 ▶ | B39: 2020Q1 | C39: 2020Q2 | D39: 2020Q3 | E39: 2020Q4 | F39: 2021Q1 | G39: 2021Q2 | H39: 2021Q3 | I39: 2021Q4 | J39: 2022Q1 | K39: 2022Q2 | L39: 2022Q3 | M39: 2022Q4 | N39: 2023Q1 | O39: 2023Q2 | P39: 2023Q3 | Q39: 2023Q4 | R39: 2024Q1 | S39: 2024Q2 | T39: 2024Q3 | U39: 2024Q4 | V39: 2025Q1 | W39: 2025Q2 | X39: 2025Q3 | Y39: 2025Q4 | Z39: 2026Q1 | AA39: 2026Q2 | AB39: 2026Q3 | AC39: 2026Q4 | AD39: 2027Q1 | AE39: 2027Q2 | AF39: 2027Q3 | AG39: 2027Q4 | AH39: 2028Q1 | AI39: 2028Q2 | AJ39: 2028Q3 | AK39: 2028Q4 | AL39: 2029Q1 | AM39: 2029Q2 | AN39: 2029Q3 | AO39: 2029Q4 | AP39: 2030Q1 | AQ39: 2030Q2 | AR39: 2030Q3 | AS39: 2030Q4 | AT39: 2031Q1
A40: 분기 순번(추세계산용) | B40: 1 | C40: 2 | D40: 3 | E40: 4 | F40: 5 | G40: 6 | H40: 7 | I40: 8 | J40: 9 | K40: 10 | L40: 11 | M40: 12 | N40: 13 | O40: 14 | P40: 15 | Q40: 16 | R40: 17 | S40: 18 | T40: 19 | U40: 20 | V40: 21 | W40: 22 | X40: 23 | Y40: 24 | Z40: 25 | AA40: 26 | AB40: 27 | AC40: 28 | AD40: 29 | AE40: 30 | AF40: 31 | AG40: 32 | AH40: 33 | AI40: 34 | AJ40: 35 | AK40: 36 | AL40: 37 | AM40: 38 | AN40: 39 | AO40: 40 | AP40: 41 | AQ40: 42 | AR40: 43 | AS40: 44 | AT40: 45
A42: ■ E. 종별 NSA MS : [ NSA 수량 (C) x NSA 종별 비율 (D) / 종별 Ramosetron 수량 (B) ]
A43: 상급종합병원 | B43: =원자료_분기실측!B46 | C43: =원자료_분기실측!C46 | D43: =원자료_분기실측!D46 | E43: =원자료_분기실측!E46 | F43: =원자료_분기실측!F46 | G43: =원자료_분기실측!G46 | H43: =원자료_분기실측!H46 | I43: =원자료_분기실측!I46 | ... Z43: =원자료_분기실측!Z46 | AA43: =MAX($E$32,$Z$43+$D$32*(AA40-$Z$40)) | AB43: =MAX($E$32,$Z$43+$D$32*(AB40-$Z$40)) | AC43: =MAX($E$32,$Z$43+$D$32*(AC40-$Z$40)) | AD43: =MAX($E$32,$Z$43+$D$32*(AD40-$Z$40)) | AE43: =MAX($E$32,$Z$43+$D$32*(AE40-$Z$40)) | AF43: =MAX($E$32,$Z$43+$D$32*(AF40-$Z$40)) | AG43: =MAX($E$32,$Z$43+$D$32*(AG40-$Z$40)) | AH43: =MAX($E$32,$Z$43+$D$32*(AH40-$Z$40)) | ... AT43: =MAX($E$32,$Z$43+$D$32*(AT40-$Z$40))
A44: 종합병원 | B44: =원자료_분기실측!B47 | C44: =원자료_분기실측!C47 | D44: =원자료_분기실측!D47 | E44: =원자료_분기실측!E47 | F44: =원자료_분기실측!F47 | G44: =원자료_분기실측!G47 | H44: =원자료_분기실측!H47 | I44: =원자료_분기실측!I47 | ... Z44: =원자료_분기실측!Z47 | AA44: =$E$33/(1+EXP(-(LN($Z$44/($E$33-$Z$44))+$D$33*(AA40-$Z$40)))) | AB44: =$E$33/(1+EXP(-(LN($Z$44/($E$33-$Z$44))+$D$33*(AB40-$Z$40)))) | AC44: =$E$33/(1+EXP(-(LN($Z$44/($E$33-$Z$44))+$D$33*(AC40-$Z$40)))) | AD44: =$E$33/(1+EXP(-(LN($Z$44/($E$33-$Z$44))+$D$33*(AD40-$Z$40)))) | AE44: =$E$33/(1+EXP(-(LN($Z$44/($E$33-$Z$44))+$D$33*(AE40-$Z$40)))) | AF44: =$E$33/(1+EXP(-(LN($Z$44/($E$33-$Z$44))+$D$33*(AF40-$Z$40)))) | AG44: =$E$33/(1+EXP(-(LN($Z$44/($E$33-$Z$44))+$D$33*(AG40-$Z$40)))) | AH44: =$E$33/(1+EXP(-(LN($Z$44/($E$33-$Z$44))+$D$33*(AH40-$Z$40)))) | ... AT44: =$E$33/(1+EXP(-(LN($Z$44/($E$33-$Z$44))+$D$33*(AT40-$Z$40))))
A45: 병원 | B45: =원자료_분기실측!B48 | C45: =원자료_분기실측!C48 | D45: =원자료_분기실측!D48 | E45: =원자료_분기실측!E48 | F45: =원자료_분기실측!F48 | G45: =원자료_분기실측!G48 | H45: =원자료_분기실측!H48 | I45: =원자료_분기실측!I48 | ... Z45: =원자료_분기실측!Z48 | AA45: =AVERAGE(W45,X45,Y45,Z45) | AB45: =AVERAGE(X45,Y45,Z45,AA45) | AC45: =AVERAGE(Y45,Z45,AA45,AB45) | AD45: =AVERAGE(Z45,AA45,AB45,AC45) | AE45: =AVERAGE(AA45,AB45,AC45,AD45) | AF45: =AVERAGE(AB45,AC45,AD45,AE45) | AG45: =AVERAGE(AC45,AD45,AE45,AF45) | AH45: =AVERAGE(AD45,AE45,AF45,AG45) | ... AT45: =AVERAGE(AP45,AQ45,AR45,AS45)
A46: 의원 | B46: =원자료_분기실측!B49 | C46: =원자료_분기실측!C49 | D46: =원자료_분기실측!D49 | E46: =원자료_분기실측!E49 | F46: =원자료_분기실측!F49 | G46: =원자료_분기실측!G49 | H46: =원자료_분기실측!H49 | I46: =원자료_분기실측!I49 | ... Z46: =원자료_분기실측!Z49 | AA46: =$Z$47 | AB46: =$Z$47 | AC46: =$Z$47 | AD46: =$Z$47 | AE46: =$Z$47 | AF46: =$Z$47 | AG46: =$Z$47 | AH46: =$Z$47 | ... AT46: =$Z$47
A47: [의원 EWMA 계산용, alpha=0.3] | F47: =F46 | G47: =0.3*G46+0.7*F47 | H47: =0.3*H46+0.7*G47 | I47: =0.3*I46+0.7*H47 | J47: =0.3*J46+0.7*I47 | K47: =0.3*K46+0.7*J47 | L47: =0.3*L46+0.7*K47 | M47: =0.3*M46+0.7*L47 | N47: =0.3*N46+0.7*M47 | ... Z47: =0.3*Z46+0.7*Y47
A48: ■ F. 종별 NSA 수량 : [ 종별 Ramosetron 수량 (B) x 종별 NSA MS (E) ]
A49: 상급종합병원 | B49: ='근거_Ramosetron 시장 수량'!B47*B43 | C49: ='근거_Ramosetron 시장 수량'!C47*C43 | D49: ='근거_Ramosetron 시장 수량'!D47*D43 | E49: ='근거_Ramosetron 시장 수량'!E47*E43 | F49: ='근거_Ramosetron 시장 수량'!F47*F43 | G49: ='근거_Ramosetron 시장 수량'!G47*G43 | H49: ='근거_Ramosetron 시장 수량'!H47*H43 | I49: ='근거_Ramosetron 시장 수량'!I47*I43 | ... Z49: ='근거_Ramosetron 시장 수량'!Z47*Z43 | AA49: ='근거_Ramosetron 시장 수량'!AA47*'근거_NSA수량(IQVIA기준)'!AA43 | AB49: ='근거_Ramosetron 시장 수량'!AB47*'근거_NSA수량(IQVIA기준)'!AB43 | AC49: ='근거_Ramosetron 시장 수량'!AC47*'근거_NSA수량(IQVIA기준)'!AC43 | AD49: ='근거_Ramosetron 시장 수량'!AD47*'근거_NSA수량(IQVIA기준)'!AD43 | AE49: ='근거_Ramosetron 시장 수량'!AE47*'근거_NSA수량(IQVIA기준)'!AE43 | AF49: ='근거_Ramosetron 시장 수량'!AF47*'근거_NSA수량(IQVIA기준)'!AF43 | AG49: ='근거_Ramosetron 시장 수량'!AG47*'근거_NSA수량(IQVIA기준)'!AG43 | AH49: ='근거_Ramosetron 시장 수량'!AH47*'근거_NSA수량(IQVIA기준)'!AH43 | ... AT49: ='근거_Ramosetron 시장 수량'!AT47*'근거_NSA수량(IQVIA기준)'!AT43
...

Sheet 근거_매출
A2: DSKR NSA (SAP)매출 산출 : IQVIA 데이터 기반 예측 (FY26 목표단가 적용)
B4: ◀ 실측 (DSKR, FY2020~2025) | J4: 예측 ▶
A5: 구분 / 회계연도 ▶ | B5: FY2018 | C5: FY2019 | D5: FY2020 | E5: FY2021 | F5: FY2022 | G5: FY2023 | H5: FY2024 | I5: FY2025 | J5: FY2026 | K5: FY2027 | L5: FY2028 | M5: FY2029 | N5: FY2030
A6: ■ A. NSA 수량 (A, IQVIA 기준) [근거_NSA수량(IQVIA기준) 참조]
A7: NSA 수량 | B7: =IF('근거_NSA수량(IQVIA기준)'!B27=0,"",'근거_NSA수량(IQVIA기준)'!B27) | C7: =IF('근거_NSA수량(IQVIA기준)'!C27=0,"",'근거_NSA수량(IQVIA기준)'!C27) | D7: =IF('근거_NSA수량(IQVIA기준)'!D27=0,"",'근거_NSA수량(IQVIA기준)'!D27) | E7: =IF('근거_NSA수량(IQVIA기준)'!E27=0,"",'근거_NSA수량(IQVIA기준)'!E27) | F7: =IF('근거_NSA수량(IQVIA기준)'!F27=0,"",'근거_NSA수량(IQVIA기준)'!F27) | G7: =IF('근거_NSA수량(IQVIA기준)'!G27=0,"",'근거_NSA수량(IQVIA기준)'!G27) | H7: =IF('근거_NSA수량(IQVIA기준)'!H27=0,"",'근거_NSA수량(IQVIA기준)'!H27) | I7: =IF('근거_NSA수량(IQVIA기준)'!I27=0,"",'근거_NSA수량(IQVIA기준)'!I27) | ... N7: =IF('근거_NSA수량(IQVIA기준)'!N27=0,"",'근거_NSA수량(IQVIA기준)'!N27)
A9: ■ B. DSKR 매출수량 (A) [FY2020~2025 : SAP 실측 | FY2026~FY2030 : NSA 수량(A) ÷ 전환비율(C)]
A10: ▶ 1) Model Base | D10: 1609310 | E10: 1938415 | F10: 1836815 | G10: 2035465 | H10: 1595925 | I10: 1905010 | J10: =J7/J24 | K10: =K7/K24 | L10: =L7/L24 | M10: =M7/M24 | N10: =N7/N24
A11: : 모듈 산출치로 시나리오 기준선 역할
A12: ▶ 2) MKT Base [FY2026 : MKT 제공 예측치 (J12 직접 입력) | FY2027~FY2030 : 전년 × Model Base 증감률] | K12: =IF($J$12="","",J12*K10/J10) | L12: =IF($J$12="","",K12*L10/K10) | M12: =IF($J$12="","",L12*M10/L10) | N12: =IF($J$12="","",M12*N10/M10)
A13: : '26 MKT 제출 수치를 J12(노랑)에 입력하면 MKT Base 행·차트가 자동 활성화 (미입력 시 공란) | J13: =IF($J$12="","",J12/J10-1) | K13: =IF($J$12="","",K12/K10-1) | L13: =IF($J$12="","",L12/L10-1) | M13: =IF($J$12="","",M12/M10-1) | N13: =IF($J$12="","",N12/N10-1)
A14: ▶ 3) Best Scenario (±10%p) [FY2027~FY2030 : (Base NSA 수량 + NSA MS +10%p 효과 (MS 100% 상한 적용)) ÷ 전환비율] | J14: =('근거_NSA수량(IQVIA기준)'!J27)/J24 | K14: =(MIN('근거_NSA수량(IQVIA기준)'!K27+0.1*'근거_NSA수량(IQVIA기준)'!K7,'근거_NSA수량(IQVIA기준)'!K7))/K24 | L14: =(MIN('근거_NSA수량(IQVIA기준)'!L27+0.1*'근거_NSA수량(IQVIA기준)'!L7,'근거_NSA수량(IQVIA기준)'!L7))/L24 | M14: =(MIN('근거_NSA수량(IQVIA기준)'!M27+0.1*'근거_NSA수량(IQVIA기준)'!M7,'근거_NSA수량(IQVIA기준)'!M7))/M24 | N14: =(MIN('근거_NSA수량(IQVIA기준)'!N27+0.1*'근거_NSA수량(IQVIA기준)'!N7,'근거_NSA수량(IQVIA기준)'!N7))/N24
A15: : Model Base 기준, Ramosetron 시장 내 NSA MS +10%p 확대 시나리오 (전 종별 동시 적용) | J15: =J14/J10-1 | K15: =K14/K10-1 | L15: =L14/L10-1 | M15: =M14/M10-1 | N15: =N14/N10-1
A16: ▶ 4) Worst Scenario (±10%p) [FY2027~FY2030 : (Base NSA 수량 + NSA MS -10%p 효과) ÷ 전환비율] | J16: =('근거_NSA수량(IQVIA기준)'!J27)/J24 | K16: =('근거_NSA수량(IQVIA기준)'!K27-0.1*'근거_NSA수량(IQVIA기준)'!K7)/K24 | L16: =('근거_NSA수량(IQVIA기준)'!L27-0.1*'근거_NSA수량(IQVIA기준)'!L7)/L24 | M16: =('근거_NSA수량(IQVIA기준)'!M27-0.1*'근거_NSA수량(IQVIA기준)'!M7)/M24 | N16: =('근거_NSA수량(IQVIA기준)'!N27-0.1*'근거_NSA수량(IQVIA기준)'!N7)/N24
A17: : Model Base 기준, Ramosetron 시장 내 NSA MS -10%p 잠식 시나리오 (전 종별 동시 적용) | J17: =J16/J10-1 | K17: =K16/K10-1 | L17: =L16/L10-1 | M17: =M16/M10-1 | N17: =N16/N10-1
A18: ▶ 5) Best Scenario (±5%p) [FY2027~FY2030 : (Base NSA 수량 + NSA MS +5%p 효과 (MS 100% 상한 적용)) ÷ 전환비율] | J18: =('근거_NSA수량(IQVIA기준)'!J27)/J24 | K18: =(MIN('근거_NSA수량(IQVIA기준)'!K27+0.05*'근거_NSA수량(IQVIA기준)'!K7,'근거_NSA수량(IQVIA기준)'!K7))/K24 | L18: =(MIN('근거_NSA수량(IQVIA기준)'!L27+0.05*'근거_NSA수량(IQVIA기준)'!L7,'근거_NSA수량(IQVIA기준)'!L7))/L24 | M18: =(MIN('근거_NSA수량(IQVIA기준)'!M27+0.05*'근거_NSA수량(IQVIA기준)'!M7,'근거_NSA수량(IQVIA기준)'!M7))/M24 | N18: =(MIN('근거_NSA수량(IQVIA기준)'!N27+0.05*'근거_NSA수량(IQVIA기준)'!N7,'근거_NSA수량(IQVIA기준)'!N7))/N24
A19: : Model Base 기준, Ramosetron 시장 내 NSA MS +5%p 확대 시나리오 (전 종별 동시 적용) | J19: =J18/J10-1 | K19: =K18/K10-1 | L19: =L18/L10-1 | M19: =M18/M10-1 | N19: =N18/N10-1
A20: ▶ 6) Worst Scenario (±5%p) [FY2027~FY2030 : (Base NSA 수량 + NSA MS -5%p 효과) ÷ 전환비율] | J20: =('근거_NSA수량(IQVIA기준)'!J27)/J24 | K20: =('근거_NSA수량(IQVIA기준)'!K27-0.05*'근거_NSA수량(IQVIA기준)'!K7)/K24 | L20: =('근거_NSA수량(IQVIA기준)'!L27-0.05*'근거_NSA수량(IQVIA기준)'!L7)/L24 | M20: =('근거_NSA수량(IQVIA기준)'!M27-0.05*'근거_NSA수량(IQVIA기준)'!M7)/M24 | N20: =('근거_NSA수량(IQVIA기준)'!N27-0.05*'근거_NSA수량(IQVIA기준)'!N7)/N24
A21: : Model Base 기준, Ramosetron 시장 내 NSA MS -5%p 잠식 시나리오 (전 종별 동시 적용) | J21: =J20/J10-1 | K21: =K20/K10-1 | L21: =L20/L10-1 | M21: =M20/M10-1 | N21: =N20/N10-1
A23: ■ C. 전환비율 (IQVIA 수량 ÷ SAP 매출수량) [FY2020~2025 : 산출치 | FY2026~2030 : FY24~25 평균 (원 모델 기준 유지)]
A24: 전환비율 | D24: =IFERROR(D7/D10,"") | E24: =IFERROR(E7/E10,"") | F24: =IFERROR(F7/F10,"") | G24: =IFERROR(G7/G10,"") | H24: =IFERROR(H7/H10,"") | I24: =IFERROR(I7/I10,"") | J24: =AVERAGE(H24:I24) | K24: =J24 | L24: =K24 | M24: =L24 | N24: =M24
A26: ■ D. 단가 (원/A) [연도별 단가 : FY2026 목표단가(백만원/5A) ÷ 5 × 연도별 약가 배율 (인하 고시 시 28행 수정) ]
A27: 환산 단가 (원/A) | B27: =$B$59/5*1000000 | C27: (NASEA Inj. 0.3mg/5A FY2026 목표단가 ÷ 5 — 하단 [참고] 목표단가 참조)
A28: 약가 배율 (%) | J28: 1 | K28: 1 | L28: 1 | M28: 1 | N28: 1 | O28: ◀ 약가 인하 고시 없음 → 100% 유지 (인하 확정 시 해당 연도 배율만 수정)
A29: 단가 (원/A) | J29: =$B$27*J28 | K29: =$B$27*K28 | L29: =$B$27*L28 | M29: =$B$27*M28 | N29: =$B$27*N28
A31: ■ E. DSKR SAP매출액 (백만원) [FY2020~2025 : 실측 수량 × FY2026 목표단가 | FY2026~FY2030 : DSKR 매출 수량(B) × 단가(D) ]
A32: ▶ 1) Model Base : (B-1) × (D) | D32: 22226.502 | E32: 26771.837 | F32: 25368.619 | G32: 28112.214 | H32: 22041.639 | I32: 26310.474 | J32: =J10*J29/1000000 | K32: =K10*K29/1000000 | L32: =L10*L29/1000000 | M32: =M10*M29/1000000 | N32: =N10*N29/1000000
A33: YoY 증감률 | C33: =IFERROR(C32/B32-1,"") | D33: =IFERROR(D32/C32-1,"") | E33: =IFERROR(E32/D32-1,"") | F33: =IFERROR(F32/E32-1,"") | G33: =IFERROR(G32/F32-1,"") | H33: =IFERROR(H32/G32-1,"") | I33: =IFERROR(I32/H32-1,"") | J33: =IFERROR(J32/I32-1,"") | ... N33: =IFERROR(N32/M32-1,"")
A34: ▶ 2) MKT Base : MKT Base(B-2) × 단가(D) | J34: =IF($J$12="","",J12*J29/1000000) | K34: =IF($J$12="","",K12*K29/1000000) | L34: =IF($J$12="","",L12*L29/1000000) | M34: =IF($J$12="","",M12*M29/1000000) | N34: =IF($J$12="","",N12*N29/1000000)
A35: ▶ 3) Best (±10%p) : Best 수량(B-3) × 단가(D) | J35: =J14*J29/1000000 | K35: =K14*K29/1000000 | L35: =L14*L29/1000000 | M35: =M14*M29/1000000 | N35: =N14*N29/1000000
A36: ▶ 4) Worst (±10%p) : Worst 수량(B-4) × 단가(D) | J36: =J16*J29/1000000 | K36: =K16*K29/1000000 | L36: =L16*L29/1000000 | M36: =M16*M29/1000000 | N36: =N16*N29/1000000
A37: ▶ 5) Best (±5%p) : Best 수량(B-5) × 단가(D) | J37: =J18*J29/1000000 | K37: =K18*K29/1000000 | L37: =L18*L29/1000000 | M37: =M18*M29/1000000 | N37: =N18*N29/1000000
A38: ▶ 6) Worst (±5%p) : Worst 수량(B-6) × 단가(D) | J38: =J20*J29/1000000 | K38: =K20*K29/1000000 | L38: =L20*L29/1000000 | M38: =M20*M29/1000000 | N38: =N20*N29/1000000
B40: [참고]
B41: *시나리오 밴드 설정 및 산출 기준
B42: · 시나리오 기준 (민감도 1위 지표: Ramosetron 시장 내 NSA MS) — ±10%p(주 밴드)·±5%p(보조 밴드) 2단계
B43: - Best (MS 확대): 상급종합·종합병원 코드인 유지 및 병원급 확대로 NSA MS +10%p / +5%p → 매출 상단
B44: - Worst (MS 잠식): 제네릭 저가 입찰·처방 전환으로 NSA MS -10%p / -5%p → 매출 하단
B45: · 핵심 산출 근거: 종별 NSA MS 분기 실측(2020Q1~2026Q1, 근거_NSA수량 [참고]) 기준 가감. 시장 수량(Ramosetron)은 Base 고정
B46: · 전략적 시사점
B47: - Best와 Worst 시나리오 간의 최종 매출 격차(Band 폭)는 예측 오차가 아니라, 영업·마케팅의 종별 MS 방어·확대 활동이 창출해야 할 '전략적 목표 가치(Value)'를 의미
...

Sheet 근거_민감도
A2: NSA FCST 민감도 : 변동요인별 ± 이동이 Model Base 매출에 주는 영향
A4: ■ A. 방법
A5: · 방법: 한 번에 한 레버씩 하방/상방 조건으로 이동시켜 Model Base 매출(근거_매출 ■E-1)을 재계산. 레버 간 상관 미반영(일원 민감도). 사본 재계산(LibreOffice 전체 재계산) 결과의 정적 기록
A8: ■ B. 레버 정의
B9: 모델 내 위치 | C9: 기준값 | D9: 하방조건 | E9: 상방조건 | F9: 범위설정 근거
A10: L1 전신마취환자수 | B10: 근거_전신마취환자수 42행 (2026~2030 연간) | C10: 연령별 회귀/평균 | D10: -2% | E10: +2% | F10: 동등 산포의 레벨 쇼크(±2%) 근사
A11: L2 상급종합 환자비율 상한 | B11: 근거_종별전신마취환자수 C25 | C11: 0.41 | D11: 0.38 | E11: 0.44 | F11: 회복모형 상한 ±3%p
A12: L3 종합병원 환자비율 하한 | B12: 근거_종별전신마취환자수 C26 | C12: 0.4 | D12: 0.37 | E12: 0.43 | F12: 회복모형 하한 ±3%p
A13: L4 환자당 Ramo 사용량 | B13: 근거_Ramosetron 시장 수량 22~25행 (2026~2030) | C13: 선형회귀(상한) / flat | D13: -5% | E13: +5% | F13: 연간모델 표본 부족에 따른 레벨 쇼크 ±5%
A14: L5 NSA MS 상급종합 하한 | B14: 근거_NSA수량 E32 (레벨보정 하한) | C14: 0.55 | D14: 0.52 | E14: 0.58 | F14: 백테스트 MAPE 2.9% 기준 ±3%p
A15: L6 NSA MS 종합병원 상한 | B15: 근거_NSA수량 E33 (S-curve 상한) | C15: 0.56 | D15: 0.53 | E15: 0.59 | F15: 백테스트 MAPE 3.8% 기준 ±3%p
A16: L7 NSA MS 병원·의원 | B16: 근거_NSA수량 51~52행 (2026Q2~2030Q4 수량) | C16: 롤링4Q / EWMA | D16: -10% | E16: +10% | F16: 백테스트 MAPE 8.9~10.3% 기준 ±10%
A17: L8 NSA MS 전체 (시나리오) | B17: 근거_매출 14·16행 (NSA 수량 ± MS×시장) | C17: 종별 회귀 합산 | D17: MS -10%p | E17: MS +10%p | F17: MTS 밴드와 동일 정의 (라이브 수식)
A18: L9 전환비율 | B18: 근거_매출 24행 (FY24~25 평균) | C18: 1.044 | D18: 1.047 | E18: 1.01 | F18: FY2023~25 실측 최소·최대
A21: ■ C. 결과 — 기준 대비 매출 변화율
B22: FY2027하방 | C22: FY2027상방 | D22: FY2030하방 | E22: FY2030상방 | F22: FY2030 최대영향(±)
A23: L8 NSA MS 전체 (시나리오) | B23: =근거_매출!K36/근거_매출!K32-1 | C23: =근거_매출!K35/근거_매출!K32-1 | D23: =근거_매출!N36/근거_매출!N32-1 | E23: =근거_매출!N35/근거_매출!N32-1 | F23: =MAX(ABS(D23),ABS(E23))
A24: L4 환자당 Ramo 사용량 | B24: =-0.05237 | C24: =0.052672 | D24: =-0.054968 | E24: =0.056379 | F24: =MAX(ABS(D24),ABS(E24))
A25: L9 전환비율 | B25: =-0.002857 | C25: =0.033672 | D25: =-0.002857 | E25: =0.033672 | F25: =MAX(ABS(D25),ABS(E25))
A26: L5 NSA MS 상급종합 하한 | B26: =-0.000419 | C26: =0.020518 | D26: =-0.029562 | E26: =0.029562 | F26: =MAX(ABS(D26),ABS(E26))
A27: L6 NSA MS 종합병원 상한 | B27: =-0.014146 | C27: =0.011442 | D27: =-0.022372 | E27: =0.021518 | F27: =MAX(ABS(D27),ABS(E27))
A28: L1 전신마취환자수 | B28: =-0.02 | C28: =0.02 | D28: =-0.02 | E28: =0.02 | F28: =MAX(ABS(D28),ABS(E28))
A29: L2 상급종합 환자비율 상한 | B29: =-0.009362 | C29: =0.000539 | D29: =-0.010356 | E29: =0.009761 | F29: =MAX(ABS(D29),ABS(E29))
A30: L7 NSA MS 병원·의원 | B30: =-0.004034 | C30: =0.004034 | D30: =-0.002819 | E30: =0.002819 | F30: =MAX(ABS(D30),ABS(E30))
A31: L3 종합병원 환자비율 하한 | B31: =-0.0025 | C31: =0.002361 | D31: =-0.00271 | E31: =0.002554 | F31: =MAX(ABS(D31),ABS(E31))
A33: · L8 NSA MS 전체는 MTS 밴드(근거_매출 35·36행, ±10%p)와 동일 정의라 수식 참조(라이브). 나머지는 사본 재계산의 정적 기록
A34: · NSA 모델은 CY 분기 모델(2026Q1 실측 → 2026Q2~ 예측)이며 FY2026(2026Q2~2027Q1)은 전량 예측 구간 — 환자수·비율 레버도 FY2026부터 영향
A35: · L4 환자당 사용량은 종별 4행을 동시에 이동. L7은 병원·의원 NSA 수량(=시장×MS)에 직접 적용해 롤링평균 누적효과를 배제
A36: · 결과 수치는 산출 시점(2026-09-15)의 모델 상태 기준이며, 원자료_분기실측 갱신 시 L8 외 정적 값은 재산출 필요
A39: ■ D. 차트 소스 데이터
A40: 요인(±%) | B40: L3 종합병원 환자비율 하한 | C40: L7 NSA MS 병원·의원 | D40: L2 상급종합 환자비율 상한 | E40: L1 전신마취환자수 | F40: L6 NSA MS 종합병원 상한 | G40: L5 NSA MS 상급종합 하한 | H40: L9 전환비율 | I40: L4 환자당 Ramo 사용량 | J40: L8 NSA MS 전체 (시나리오)
A41: 영향(%) | B41: =ROUND(F31*100,1) | C41: =ROUND(F30*100,1) | D41: =ROUND(F29*100,1) | E41: =ROUND(F28*100,1) | F41: =ROUND(F27*100,1) | G41: =ROUND(F26*100,1) | H41: =ROUND(F25*100,1) | I41: =ROUND(F24*100,1) | J41: =ROUND(F23*100,1)
A43: FY2030(억) | B43: MS 잠식(-10%p) | C43: Base | D43: MS 확대(+10%p)
A44: 매출 | B44: =ROUND(근거_매출!N36/100,0) | C44: =ROUND(근거_매출!N32/100,0) | D44: =ROUND(근거_매출!N35/100,0)
A45: 매출 (±5%p 밴드) | B45: =ROUND(근거_매출!N38/100,0) | C45: =ROUND(근거_매출!N32/100,0) | D45: =ROUND(근거_매출!N37/100,0)

Sheet CALC
B2: Part 1) 전신마취환자수&시장 예측 [CY 기준 · 역년 1~12월] / IQVIA 처방량 예측 [FY 기준 · 회계연도 4~3월]
B3: 연도 | C3: 전신마취환자수 | E3: Ramosetron 시장 수량 (IQVIA 기준) | H3: NSA 수량 (IQVIA기준)
A4: 전체인구수 | B4: CY연도기준 | C4: 환자수 | D4: 비율 | E4: Ramosetron 시장 수량 | F4: 환자당 연간 처방량 | G4: YoY | H4: NSA 수량 | I4: MS | J4: YoY
A5: ='근거_전신마취환자수'!B17 | B5: 2010 | C5: ='근거_전신마취환자수'!B42 | D5: =IFERROR(C5/A5,"") | E5: ='근거_Ramosetron 시장 수량'!B33 | F5: =IFERROR(E5/C5,"")
A6: ='근거_전신마취환자수'!C17 | B6: 2011 | C6: ='근거_전신마취환자수'!C42 | D6: =IFERROR(C6/A6,"") | E6: ='근거_Ramosetron 시장 수량'!C33 | F6: =IFERROR(E6/C6,"") | G6: =IFERROR(E6/E5-1,"")
A7: ='근거_전신마취환자수'!D17 | B7: 2012 | C7: ='근거_전신마취환자수'!D42 | D7: =IFERROR(C7/A7,"") | E7: ='근거_Ramosetron 시장 수량'!D33 | F7: =IFERROR(E7/C7,"") | G7: =IFERROR(E7/E6-1,"")
A8: ='근거_전신마취환자수'!E17 | B8: 2013 | C8: ='근거_전신마취환자수'!E42 | D8: =IFERROR(C8/A8,"") | E8: ='근거_Ramosetron 시장 수량'!E33 | F8: =IFERROR(E8/C8,"") | G8: =IFERROR(E8/E7-1,"")
