Workbook
Name 표시연도: 'FCST RESULT'!$P$4
Name 표시연도: [1]DASHBOARD!$G$3

Sheet 표지

Sheet FCST RESULT
B3: NSA SALES FORECAST
P4: 2026
B6: 1. 매출수량 (백만 A)
B21: 구분 | C21: FY2026 | D21: FY2027 | E21: FY2028 | F21: FY2029 | G21: FY2030
B22: Model Base | C22: =근거_매출!J10/1000000 | D22: =근거_매출!K10/1000000 | E22: =근거_매출!L10/1000000 | F22: =근거_매출!M10/1000000 | G22: =근거_매출!N10/1000000
B23: MKT Base | C23: =IF(근거_매출!$J$12="",NA(),근거_매출!J12/1000000) | D23: =IF(근거_매출!$J$12="",NA(),근거_매출!K12/1000000) | E23: =IF(근거_매출!$J$12="",NA(),근거_매출!L12/1000000) | F23: =IF(근거_매출!$J$12="",NA(),근거_매출!M12/1000000) | G23: =IF(근거_매출!$J$12="",NA(),근거_매출!N12/1000000)
B24: Best (MS +10%p) | C24: =근거_매출!J14/1000000 | D24: =근거_매출!K14/1000000 | E24: =근거_매출!L14/1000000 | F24: =근거_매출!M14/1000000 | G24: =근거_매출!N14/1000000
B25: Worst (MS -10%p) | C25: =근거_매출!J16/1000000 | D25: =근거_매출!K16/1000000 | E25: =근거_매출!L16/1000000 | F25: =근거_매출!M16/1000000 | G25: =근거_매출!N16/1000000
B26: Best (MS +5%p) | C26: =근거_매출!J18/1000000 | D26: =근거_매출!K18/1000000 | E26: =근거_매출!L18/1000000 | F26: =근거_매출!M18/1000000 | G26: =근거_매출!N18/1000000
B27: Worst (MS -5%p) | C27: =근거_매출!J20/1000000 | D27: =근거_매출!K20/1000000 | E27: =근거_매출!L20/1000000 | F27: =근거_매출!M20/1000000 | G27: =근거_매출!N20/1000000
B29: 2. 매출액 (백만원)
B44: 구분 | C44: FY2026 | D44: FY2027 | E44: FY2028 | F44: FY2029 | G44: FY2030
B45: Model Base | C45: =근거_매출!J32 | D45: =근거_매출!K32 | E45: =근거_매출!L32 | F45: =근거_매출!M32 | G45: =근거_매출!N32
B46: MKT Base | C46: =IF(근거_매출!$J$12="",NA(),근거_매출!J34) | D46: =IF(근거_매출!$J$12="",NA(),근거_매출!K34) | E46: =IF(근거_매출!$J$12="",NA(),근거_매출!L34) | F46: =IF(근거_매출!$J$12="",NA(),근거_매출!M34) | G46: =IF(근거_매출!$J$12="",NA(),근거_매출!N34)
B47: Best (MS +10%p) | C47: =근거_매출!J35 | D47: =근거_매출!K35 | E47: =근거_매출!L35 | F47: =근거_매출!M35 | G47: =근거_매출!N35
B48: Worst (MS -10%p) | C48: =근거_매출!J36 | D48: =근거_매출!K36 | E48: =근거_매출!L36 | F48: =근거_매출!M36 | G48: =근거_매출!N36
B49: Best (MS +5%p) | C49: =근거_매출!J37 | D49: =근거_매출!K37 | E49: =근거_매출!L37 | F49: =근거_매출!M37 | G49: =근거_매출!N37
B50: Worst (MS -5%p) | C50: =근거_매출!J38 | D50: =근거_매출!K38 | E50: =근거_매출!L38 | F50: =근거_매출!M38 | G50: =근거_매출!N38

Sheet 변동요인분석
A2: NSA FCST 변동 요인 분석과 시뮬레이션
A4: ① 변동 요인 분석
A5: - 핵심 변동 요인 : NSA MS (Ramosetron 시장 내 점유율) (매출 변동성 ±18.9%로, 타 요인 대비 압도적인 영향력을 행사함)
A6: - 기타 변동 요인: 환자당 Ramo 사용량(±5.6%), 전환비율(±3.4%), NSA MS 상급종합 하한(±3.0%) 등 (구조 파라미터 성격, 분기 실측 갱신 시 자동 재추정)
A7: - 예외 요인: 약가 인하 고시(현재 없음) 및 MKT 제출 수치와의 차이는 본 시뮬레이션 외 별도 리스크로 분류 · 입찰(저가 제네릭) 단발 이벤트는 분기 모니터링으로 감시
A25: ② 시뮬레이션 : NSA MS 변동의 재무적 가치
A26: - Best (MS 확대): NSA MS +10%p 시 → FY2030 매출 437억 (상단) · +5%p 시 402억
A27: - Worst (MS 잠식): NSA MS -10%p 시 → FY2030 매출 298억 (하단) · -5%p 시 332억
A28: (※ 기준선 Base: 367억 · 세일즈 포캐스트 밴드는 FY2027부터 적용)
A47: · 근거: 근거_민감도 참조

Sheet FCST FLOW
A2: NSA Sales FCST FLOW
J3: 각 행의 [▶ 근거] 를 클릭하면 해당 백데이터 시트로 이동 (기준수치·예측수치는 백데이터 참조)
A5: 단계 | B5: 항목 | C5: 기준 수치 | D5: 모델 방법 | E5: FY2026E | F5: FY2027 | G5: FY2028 | H5: FY2029 | I5: FY2030 | J5: 근거
A6: ① 환자 현황 | B6: 전신마취 환자수 | C6: =CALC!C20 | D6: · 추계인구(통계청 중위) × 연령별 전신마취 비율 (30~50대 선형회귀 연장, 그 외 최근 5개년 평균) | E6: =INDEX(CALC!$C$5:$C$25,MATCH(표시연도,CALC!$B$5:$B$25,0)) | F6: =INDEX(CALC!$C$5:$C$25,MATCH(2027,CALC!$B$5:$B$25,0)) | G6: =INDEX(CALC!$C$5:$C$25,MATCH(2028,CALC!$B$5:$B$25,0)) | H6: =INDEX(CALC!$C$5:$C$25,MATCH(2029,CALC!$B$5:$B$25,0)) | I6: =INDEX(CALC!$C$5:$C$25,MATCH(2030,CALC!$B$5:$B$25,0)) | J6: ▶ 근거
A7: ② 시장 구조 | B7: 종별 환자비율 (상급종합병원) | C7: ='근거_Ramosetron 시장 수량'!Q10 | D7: · HIRA 분기 실측(~2026Q1) 기반 회복모형 — 상급종합 상한 41%·종합 하한 40%·병원 하한 10%·의원 S-curve, 4종별 정규화 | E7: ='근거_Ramosetron 시장 수량'!R10 | F7: ='근거_Ramosetron 시장 수량'!S10 | G7: ='근거_Ramosetron 시장 수량'!T10 | H7: ='근거_Ramosetron 시장 수량'!U10 | I7: ='근거_Ramosetron 시장 수량'!V10 | J7: ▶ 근거
B8: 환자당 Ramosetron 사용량 (상급종합, A/명) | C8: ='근거_Ramosetron 시장 수량'!Q33 | D8: · 연간 선형회귀(상한 5A) / 종합 상한 4A / 병원·의원 최근값 flat — 4개 분기 동일 적용 | E8: ='근거_Ramosetron 시장 수량'!R33 | F8: ='근거_Ramosetron 시장 수량'!S33 | G8: ='근거_Ramosetron 시장 수량'!T33 | H8: ='근거_Ramosetron 시장 수량'!U33 | I8: ='근거_Ramosetron 시장 수량'!V33 | J8: ▶ 근거
B9: Ramosetron 시장 수량 (A) | C9: =CALC!E20 | D9: · Σ 종별 전신마취환자수 × 종별 환자당 사용량 (CY 분기 → FY 재구성) | E9: =INDEX(CALC!$E$5:$E$25,MATCH(표시연도,CALC!$B$5:$B$25,0)) | F9: =INDEX(CALC!$E$5:$E$25,MATCH(2027,CALC!$B$5:$B$25,0)) | G9: =INDEX(CALC!$E$5:$E$25,MATCH(2028,CALC!$B$5:$B$25,0)) | H9: =INDEX(CALC!$E$5:$E$25,MATCH(2029,CALC!$B$5:$B$25,0)) | I9: =INDEX(CALC!$E$5:$E$25,MATCH(2030,CALC!$B$5:$B$25,0)) | J9: ▶ 근거
A10: ③ 경쟁 현황 | B10: NSA MS (상급종합병원) | C10: ='근거_NSA수량(IQVIA기준)'!I16 | D10: · 전체기간 선형(레벨보정, 하한 55%) — 백테스트 MAPE 2.9% | E10: ='근거_NSA수량(IQVIA기준)'!J16 | F10: ='근거_NSA수량(IQVIA기준)'!K16 | G10: ='근거_NSA수량(IQVIA기준)'!L16 | H10: ='근거_NSA수량(IQVIA기준)'!M16 | I10: ='근거_NSA수량(IQVIA기준)'!N16 | J10: ▶ 근거
B11: NSA MS (종합병원) | C11: ='근거_NSA수량(IQVIA기준)'!I17 | D11: · S-curve(로짓변환+저점앵커, 상한 56%) — 백테스트 MAPE 3.8% | E11: ='근거_NSA수량(IQVIA기준)'!J17 | F11: ='근거_NSA수량(IQVIA기준)'!K17 | G11: ='근거_NSA수량(IQVIA기준)'!L17 | H11: ='근거_NSA수량(IQVIA기준)'!M17 | I11: ='근거_NSA수량(IQVIA기준)'!N17 | J11: ▶ 근거
B12: NSA MS (병원·의원) | C12: ='근거_NSA수량(IQVIA기준)'!I18 | D12: · 병원 롤링 4분기 평균 / 의원 EWMA(α=0.3) flat — MAPE 8.9~10.3% (표시값은 병원) | E12: ='근거_NSA수량(IQVIA기준)'!J18 | F12: ='근거_NSA수량(IQVIA기준)'!K18 | G12: ='근거_NSA수량(IQVIA기준)'!L18 | H12: ='근거_NSA수량(IQVIA기준)'!M18 | I12: ='근거_NSA수량(IQVIA기준)'!N18 | J12: ▶ 근거
B13: NSA MS (전체) | C13: =CALC!I20 | D13: · Σ 종별 NSA 수량 ÷ Ramosetron 시장 수량 | E13: =INDEX(CALC!$I$5:$I$25,MATCH(표시연도,CALC!$B$5:$B$25,0)) | F13: =INDEX(CALC!$I$5:$I$25,MATCH(2027,CALC!$B$5:$B$25,0)) | G13: =INDEX(CALC!$I$5:$I$25,MATCH(2028,CALC!$B$5:$B$25,0)) | H13: =INDEX(CALC!$I$5:$I$25,MATCH(2029,CALC!$B$5:$B$25,0)) | I13: =INDEX(CALC!$I$5:$I$25,MATCH(2030,CALC!$B$5:$B$25,0)) | J13: ▶ 근거
A14: ④ 시장매출 | B14: DSKR 매출수량 (A) | C14: =INDEX(근거_매출!$B$10:$N$10,표시연도-1-2017) | D14: · NSA 수량(IQVIA, A) ÷ 전환비율(FY24~25 평균 1.044) → SAP 판매 수량 환산 | E14: =INDEX(근거_매출!$B$10:$N$10,표시연도-2017) | F14: =INDEX(근거_매출!$B$10:$N$10,2027-2017) | G14: =INDEX(근거_매출!$B$10:$N$10,2028-2017) | H14: =INDEX(근거_매출!$B$10:$N$10,2029-2017) | I14: =INDEX(근거_매출!$B$10:$N$10,2030-2017) | J14: ▶ 근거
B15: 연도별 단가 (원/A) | C15: =근거_매출!B27 | D15: · FY2026 목표단가 69,056원/5A ÷ 5 = 13,811원/A × 약가 배율 (인하 고시 없음 → 100% 유지, 근거_매출 28행에서 조정) | E15: =INDEX(근거_매출!$B$29:$N$29,표시연도-2017) | F15: =INDEX(근거_매출!$B$29:$N$29,2027-2017) | G15: =INDEX(근거_매출!$B$29:$N$29,2028-2017) | H15: =INDEX(근거_매출!$B$29:$N$29,2029-2017) | I15: =INDEX(근거_매출!$B$29:$N$29,2030-2017) | J15: ▶ 근거
A17: ▶ 결과 | B17: Ramosetron 시장 (수량, A) | C17: =CALC!E20 | D17: Σ 종별 전신마취환자수 × 종별 환자당 사용량 | E17: =INDEX(CALC!$E$5:$E$25,MATCH(표시연도,CALC!$B$5:$B$25,0)) | F17: =INDEX(CALC!$E$5:$E$25,MATCH(2027,CALC!$B$5:$B$25,0)) | G17: =INDEX(CALC!$E$5:$E$25,MATCH(2028,CALC!$B$5:$B$25,0)) | H17: =INDEX(CALC!$E$5:$E$25,MATCH(2029,CALC!$B$5:$B$25,0)) | I17: =INDEX(CALC!$E$5:$E$25,MATCH(2030,CALC!$B$5:$B$25,0)) | J17: ▶ 근거
B18: NSA 수량 (IQVIA, A) | C18: =CALC!H20 | D18: Σ 종별 Ramosetron 수량 × 종별 NSA MS | E18: =INDEX(CALC!$H$5:$H$25,MATCH(표시연도,CALC!$B$5:$B$25,0)) | F18: =INDEX(CALC!$H$5:$H$25,MATCH(2027,CALC!$B$5:$B$25,0)) | G18: =INDEX(CALC!$H$5:$H$25,MATCH(2028,CALC!$B$5:$B$25,0)) | H18: =INDEX(CALC!$H$5:$H$25,MATCH(2029,CALC!$B$5:$B$25,0)) | I18: =INDEX(CALC!$H$5:$H$25,MATCH(2030,CALC!$B$5:$B$25,0)) | J18: ▶ 근거
B19: NSA SAP매출 (백만원) | C19: =INDEX(근거_매출!$B$32:$N$32,표시연도-1-2017) | D19: DSKR 매출수량 × 연도별 단가 | E19: =INDEX(근거_매출!$B$32:$N$32,표시연도-2017) | F19: =INDEX(근거_매출!$B$32:$N$32,2027-2017) | G19: =INDEX(근거_매출!$B$32:$N$32,2028-2017) | H19: =INDEX(근거_매출!$B$32:$N$32,2029-2017) | I19: =INDEX(근거_매출!$B$32:$N$32,2030-2017) | J19: ▶ 근거
H20: ="※ 시나리오 밴드(FY2030): "&TEXT(근거_매출!N36,"#,##0")&" ~ "&TEXT(근거_매출!N35,"#,##0")&" (MS ±10%p) · "&TEXT(근거_매출!N38,"#,##0")&" ~ "&TEXT(근거_매출!N37,"#,##0")&" (±5%p) →" | I20: =HYPERLINK("#'FCST RESULT'!A1","상세: FCST RESULT ▶")
B22: ※ 기준 수치 - 출처 및 기준연도
B23: ① 환자 현황 (연령별 전신마취환자수): NHIS 진료행위 통계 L1211·L1212, CY2025
B24: ② 시장 구조: 종별 환자비율 HIRA 분기 실측(~2026Q1) / Ramosetron 시장 수량 IQVIA, CY2025 / 흡입마취제 종별 비율 NHIS N01AB, CY2025
B25: ③ 경쟁 현황 (종별 NSA MS): IQVIA NASEA 수량 × SS-Chart 종별 비율 ÷ 종별 Ramosetron 수량, 2026Q1
B26: ④ 시장매출(수량·단가): SAP 실측 FY2025 / 단가: FY2026 목표단가 (NASEA Inj. 0.3mg/5A)
B29: ■ 부록 — 백테스트 (종별 NSA MS 예측방식 walk-forward, 2020Q1~2026Q1)
B30: 종별 NSA MS | C30: 예측 방식 | D30: 백테스트 MAPE | E30: 판정
B31: 상급종합병원 MS | C31: 전체기간선형(레벨보정) | D31: 2.92% | E31: 채택
B32: 종합병원 MS | C32: S-curve(로짓+저점앵커) | D32: 3.83% | E32: 채택
B33: 병원 MS | C33: 롤링 4분기 평균 | D33: 8.89% | E33: 채택 (표본 소)
B34: 의원 MS | C34: EWMA(α=0.3) | D34: 10.30% | E34: 채택 (표본 소)
B35: · 방법: 2020Q1~2026Q1 분기 실측 walk-forward 백테스트(근거_NSA수량 [참고] 30~36행에서 이관). 각 종별 MS 예측 방식을 후보 중 MAPE 최소 방식으로 채택.
B36: · 결론: 상급종합·종합병원(NSA 수량의 95%)은 MAPE 3~4%로 안정, 병원·의원은 표본이 작아 오차 9~10% — 분기 모니터링 대상

Sheet 근거_전신마취환자수
A2: 전신마취 환자수 산출 : NHIS 데이터 기반 예측 (선형회귀∙평균)
B4: ◀ 실측 (NHIS, 2010~2025) | R4: 예측 (2025~2030) ▶
A5: 구분 / 연도 ▶ | B5: 2010 | C5: 2011 | D5: 2012 | E5: 2013 | F5: 2014 | G5: 2015 | H5: 2016 | I5: 2017 | J5: 2018 | K5: 2019 | L5: 2020 | M5: 2021 | N5: 2022 | O5: 2023 | P5: 2024 | Q5: 2025 | R5: 2026 | S5: 2027 | T5: 2028 | U5: 2029 | V5: 2030
A6: ■ A. 인구 (명) [통계청 장래인구추계, 중위]
A7: 0-9세 | B7: 4769730 | C7: 4651969 | D7: 4607872 | E7: 4589149 | F7: 4547518 | G7: 4541197 | H7: 4537256 | I7: 4460206 | J7: 4327663 | K7: 4206519 | L7: 4054901 | M7: 3850627 | N7: 3636125 | O7: 3415474 | P7: 3211594 | Q7: 2986799 | R7: 2774527 | S7: 2617033 | T7: 2507428 | U7: 2434549 | V7: 2396575
A8: 10-19세 | B8: 6638502 | C8: 6588027 | D8: 6404935 | E8: 6176138 | F8: 5955904 | G8: 5710954 | H8: 5459511 | I8: 5246532 | J8: 5087396 | K8: 4927537 | L8: 4769187 | M8: 4643600 | N8: 4599712 | O8: 4590838 | P8: 4546494 | Q8: 4538674 | R8: 4530952 | S8: 4460471 | T8: 4324683 | U8: 4195539 | V8: 4046514
A9: 20-29세 | B9: 6973154 | C9: 6840475 | D9: 6733813 | E9: 6686161 | F9: 6716535 | G9: 6781422 | H9: 6839660 | I9: 6897818 | J9: 6991259 | K9: 7026828 | L9: 7037893 | M9: 6953529 | N9: 6734021 | O9: 6548381 | P9: 6372432 | Q9: 6136764 | R9: 5887622 | S9: 5678166 | T9: 5510243 | U9: 5341561 | V9: 5157518
A10: 30-39세 | B10: 8264820 | C10: 8208754 | D10: 8146381 | E10: 8035971 | F10: 7899840 | G10: 7763702 | H10: 7652940 | I10: 7545842 | J10: 7456227 | K10: 7358231 | L10: 7174782 | M10: 6989477 | N10: 6872945 | O10: 6874383 | P10: 6913023 | Q10: 6975568 | R10: 7037580 | S10: 7096790 | T10: 7152255 | U10: 7158328 | V10: 7156565
A11: 40-49세 | B11: 8578079 | C11: 8600111 | D11: 8657375 | E11: 8653288 | F11: 8774714 | G11: 8752417 | H11: 8671799 | I11: 8585346 | J11: 8504579 | K11: 8335481 | L11: 8257903 | M11: 8158318 | N11: 8097011 | O11: 7993159 | P11: 7852297 | Q11: 7717016 | R11: 7624180 | S11: 7530657 | T11: 7417118 | U11: 7309393 | V11: 7147423
A12: 50-59세 | B12: 6751678 | C12: 7229163 | D12: 7504944 | E12: 7821975 | F12: 8033801 | G12: 8173256 | H12: 8305212 | I12: 8389739 | J12: 8462781 | K12: 8593283 | L12: 8575336 | M12: 8539374 | N12: 8603509 | O12: 8596363 | P12: 8705899 | Q12: 8660370 | R12: 8586606 | S12: 8508537 | T12: 8417195 | U12: 8247351 | V12: 8195954
A13: 60-69세 | B13: 4090354 | C13: 4149296 | D13: 4252495 | E13: 4358060 | F13: 4546950 | G13: 4856462 | H13: 5204346 | I13: 5456887 | J13: 5745656 | K13: 6076571 | L13: 6476602 | M13: 6959660 | N13: 7211963 | O13: 7532388 | P13: 7720341 | Q13: 7844071 | R13: 7980101 | S13: 8068291 | T13: 8139161 | U13: 8263910 | V13: 8262115
A14: 70-79세 | B14: 2565169 | C14: 2688344 | D14: 2841451 | E14: 2982923 | F14: 3062150 | G14: 3130047 | H14: 3129288 | I14: 3251115 | J14: 3374539 | K14: 3475741 | L14: 3598811 | M14: 3657969 | N14: 3761305 | O14: 3871775 | P14: 4046445 | Q14: 4347619 | R14: 4665354 | S14: 4907263 | T14: 5183887 | U14: 5496486 | V14: 5869554
A15: 80세 이상 | B15: 922626 | C15: 980499 | D15: 1050587 | E15: 1125228 | F15: 1209247 | G15: 1305490 | H15: 1417791 | I15: 1528426 | J15: 1634958 | K15: 1764631 | L15: 1890824 | M15: 2016985 | N15: 2155978 | O15: 2289858 | P15: 2382540 | Q15: 2477683 | R15: 2522199 | S15: 2667343 | T15: 2807907 | U15: 2936935 | V15: 3073495
A16: 전체 인구 | B16: =SUM(B7:B15) | C16: =SUM(C7:C15) | D16: =SUM(D7:D15) | E16: =SUM(E7:E15) | F16: =SUM(F7:F15) | G16: =SUM(G7:G15) | H16: =SUM(H7:H15) | I16: =SUM(I7:I15) | ... V16: =SUM(V7:V15)
A18: ■ B. 연령별 비율 (%) [2010~24 : 전신마취 환자바율 | 2026~30 : 연령대별 다른 방법으로 예측1]
A19: 0-9세 | B19: =B31/B7 | C19: =C31/C7 | D19: =D31/D7 | E19: =E31/E7 | F19: =F31/F7 | G19: =G31/G7 | H19: =H31/H7 | I19: =I31/I7 | ... Q19: =Q31/Q7 | R19: =$G53 | S19: =$G53 | T19: =$G53 | U19: =$G53 | V19: =$G53
A20: 10-19세 | B20: =B32/B8 | C20: =C32/C8 | D20: =D32/D8 | E20: =E32/E8 | F20: =F32/F8 | G20: =G32/G8 | H20: =H32/H8 | I20: =I32/I8 | ... Q20: =Q32/Q8 | R20: =$G54 | S20: =$G54 | T20: =$G54 | U20: =$G54 | V20: =$G54
A21: 20-29세 | B21: =B33/B9 | C21: =C33/C9 | D21: =D33/D9 | E21: =E33/E9 | F21: =F33/F9 | G21: =G33/G9 | H21: =H33/H9 | I21: =I33/I9 | ... Q21: =Q33/Q9 | R21: =$G55 | S21: =$G55 | T21: =$G55 | U21: =$G55 | V21: =$G55
A22: 30-39세 | B22: =B34/B10 | C22: =C34/C10 | D22: =D34/D10 | E22: =E34/E10 | F22: =F34/F10 | G22: =G34/G10 | H22: =H34/H10 | I22: =I34/I10 | ... Q22: =Q34/Q10 | R22: =$B$56*R$5+$C$56 | S22: =$B$56*S$5+$C$56 | T22: =$B$56*T$5+$C$56 | U22: =$B$56*U$5+$C$56 | V22: =$B$56*V$5+$C$56
A23: 40-49세 | B23: =B35/B11 | C23: =C35/C11 | D23: =D35/D11 | E23: =E35/E11 | F23: =F35/F11 | G23: =G35/G11 | H23: =H35/H11 | I23: =I35/I11 | ... Q23: =Q35/Q11 | R23: =$B$57*R$5+$C$57 | S23: =$B$57*S$5+$C$57 | T23: =$B$57*T$5+$C$57 | U23: =$B$57*U$5+$C$57 | V23: =$B$57*V$5+$C$57
A24: 50-59세 | B24: =B36/B12 | C24: =C36/C12 | D24: =D36/D12 | E24: =E36/E12 | F24: =F36/F12 | G24: =G36/G12 | H24: =H36/H12 | I24: =I36/I12 | ... Q24: =Q36/Q12 | R24: =$B$58*R$5+$C$58 | S24: =$B$58*S$5+$C$58 | T24: =$B$58*T$5+$C$58 | U24: =$B$58*U$5+$C$58 | V24: =$B$58*V$5+$C$58
A25: 60-69세 | B25: =B37/B13 | C25: =C37/C13 | D25: =D37/D13 | E25: =E37/E13 | F25: =F37/F13 | G25: =G37/G13 | H25: =H37/H13 | I25: =I37/I13 | ... Q25: =Q37/Q13 | R25: =$G59 | S25: =$G59 | T25: =$G59 | U25: =$G59 | V25: =$G59
A26: 70-79세 | B26: =B38/B14 | C26: =C38/C14 | D26: =D38/D14 | E26: =E38/E14 | F26: =F38/F14 | G26: =G38/G14 | H26: =H38/H14 | I26: =I38/I14 | ... Q26: =Q38/Q14 | R26: =$G60 | S26: =$G60 | T26: =$G60 | U26: =$G60 | V26: =$G60
A27: 80세 이상 | B27: =B39/B15 | C27: =C39/C15 | D27: =D39/D15 | E27: =E39/E15 | F27: =F39/F15 | G27: =G39/G15 | H27: =H39/H15 | I27: =I39/I15 | ... Q27: =Q39/Q15 | R27: =$G61 | S27: =$G61 | T27: =$G61 | U27: =$G61 | V27: =$G61
A28: 전체 비율 | B28: =B40/B16 | C28: =C40/C16 | D28: =D40/D16 | E28: =E40/E16 | F28: =F40/F16 | G28: =G40/G16 | H28: =H40/H16 | I28: =I40/I16 | ... V28: =V40/V16
A30: ■ C. 전신마취 환자수 (명) [CY2010~25 : NHIS L1211+1212 | 2026~30 : 유병률(B) × 인구(A)]
A31: 0-9세 | B31: 91549 | C31: 94141 | D31: 91485 | E31: 81220 | F31: 69973 | G31: 68365 | H31: 69178 | I31: 66073 | J31: 63030 | K31: 65230 | L31: 60427 | M31: 60799 | N31: 52238 | O31: 56676 | P31: 51839 | Q31: 50130 | R31: =R7*R19 | S31: =S7*S19 | T31: =T7*T19 | U31: =U7*U19 | V31: =V7*V19
A32: 10-19세 | B32: 85028 | C32: 85974 | D32: 83270 | E32: 68438 | F32: 59440 | G32: 57229 | H32: 54783 | I32: 52126 | J32: 50607 | K32: 52324 | L32: 46041 | M32: 48668 | N32: 47831 | O32: 54607 | P32: 50925 | Q32: 48269 | R32: =R8*R20 | S32: =S8*S20 | T32: =T8*T20 | U32: =U8*U20 | V32: =V8*V20
A33: 20-29세 | B33: 106295 | C33: 104595 | D33: 96499 | E33: 79774 | F33: 71919 | G33: 70926 | H33: 72683 | I33: 72896 | J33: 73407 | K33: 76718 | L33: 80056 | M33: 83325 | N33: 73269 | O33: 79137 | P33: 68668 | Q33: 63263 | R33: =R9*R21 | S33: =S9*S21 | T33: =T9*T21 | U33: =U9*U21 | V33: =V9*V21
A34: 30-39세 | B34: 160278 | C34: 164919 | D34: 155026 | E34: 128602 | F34: 111068 | G34: 105403 | H34: 108007 | I34: 109215 | J34: 115054 | K34: 121341 | L34: 128162 | M34: 136317 | N34: 124795 | O34: 141642 | P34: 143729 | Q34: 146765 | R34: =R10*R22 | S34: =S10*S22 | T34: =T10*T22 | U34: =U10*U22 | V34: =V10*V22
A35: 40-49세 | B35: 186193 | C35: 194364 | D35: 197341 | E35: 179260 | F35: 160846 | G35: 155333 | H35: 159218 | I35: 163077 | J35: 164682 | K35: 172066 | L35: 177078 | M35: 188877 | N35: 176764 | O35: 200802 | P35: 193171 | Q35: 189380 | R35: =R11*R23 | S35: =S11*S23 | T35: =T11*T23 | U35: =U11*U23 | V35: =V11*V23
A36: 50-59세 | B36: 183476 | C36: 210154 | D36: 228633 | E36: 226930 | F36: 216983 | G36: 212264 | H36: 220085 | I36: 224670 | J36: 226503 | K36: 235230 | L36: 229149 | M36: 233720 | N36: 209986 | O36: 233718 | P36: 216988 | Q36: 208245 | R36: =R12*R24 | S36: =S12*S24 | T36: =T12*T24 | U36: =U12*U24 | V36: =V12*V24
A37: 60-69세 | B37: 142696 | C37: 151713 | D37: 162479 | E37: 161483 | F37: 160733 | G37: 166083 | H37: 184401 | I37: 195728 | J37: 208663 | K37: 227810 | L37: 235289 | M37: 264146 | N37: 245410 | O37: 285692 | P37: 263680 | Q37: 256213 | R37: =R13*R25 | S37: =S13*S25 | T37: =T13*T25 | U37: =U13*U25 | V37: =V13*V25
A38: 70-79세 | B38: 85079 | C38: 94253 | D38: 107145 | E38: 112868 | F38: 112731 | G38: 115519 | H38: 124513 | I38: 131691 | J38: 141224 | K38: 154468 | L38: 154805 | M38: 168787 | N38: 157255 | O38: 182283 | P38: 171560 | Q38: 176851 | R38: =R14*R26 | S38: =S14*S26 | T38: =T14*T26 | U38: =U14*U26 | V38: =V14*V26
A39: 80세 이상 | B39: 16600 | C39: 19224 | D39: 22599 | E39: 24942 | F39: 26737 | G39: 30632 | H39: 35933 | I39: 41037 | J39: 46209 | K39: 52818 | L39: 56532 | M39: 64359 | N39: 64234 | O39: 77794 | P39: 71940 | Q39: 72465 | R39: =R15*R27 | S39: =S15*S27 | T39: =T15*T27 | U39: =U15*U27 | V39: =V15*V27
A40: ▶ 전체 전신마취 환자수 | B40: =SUM(B31:B39) | C40: =SUM(C31:C39) | D40: =SUM(D31:D39) | E40: =SUM(E31:E39) | F40: =SUM(F31:F39) | G40: =SUM(G31:G39) | H40: =SUM(H31:H39) | I40: =SUM(I31:I39) | ... V40: =SUM(V31:V39)
A41: 성장률(YoY) | F41: =F40/E40-1 | G41: =G40/F40-1 | H41: =H40/G40-1 | I41: =I40/H40-1 | J41: =J40/I40-1 | K41: =K40/J40-1 | L41: =L40/K40-1 | M41: =M40/L40-1 | ... V41: =V40/U40-1
B43: [참고]
B44: 추정 산출 흐름
B45: ① 추세 유의성 판단 → ② 유의하면 선형회귀 연장 / 아니면 최근 5개년 평균 → ③ 인구 곱
...

Sheet 근거_Ramosetron 시장 수량
A2: Ramosetron 시장 수량 : NHIS&IQVIA 데이터 기반 예측 (회복모형, 2026년 상한 도달 가정)
B4: ◀ 실측 (NHIS, 2010~2024) | R4: 예측 (2026~2030) ▶
A5: 구분 / CY연도 ▶ | B5: 2010 | C5: 2011 | D5: 2012 | E5: 2013 | F5: 2014 | G5: 2015 | H5: 2016 | I5: 2017 | J5: 2018 | K5: 2019 | L5: 2020 | M5: 2021 | N5: 2022 | O5: 2023 | P5: 2024 | Q5: 2025 | R5: 2026 | S5: 2027 | T5: 2028 | U5: 2029 | V5: 2030
A6: ■ A. 전신마취 환자수 (명) [근거_전신마취환자수 참조]
A7: 전신마취환자수 (전체) | B7: =근거_전신마취환자수!B40 | C7: =근거_전신마취환자수!C40 | D7: =근거_전신마취환자수!D40 | E7: =근거_전신마취환자수!E40 | F7: =근거_전신마취환자수!F40 | G7: =근거_전신마취환자수!G40 | H7: =근거_전신마취환자수!H40 | I7: =근거_전신마취환자수!I40 | ... V7: =근거_전신마취환자수!V40
A9: ■ B. 종별 전신마취환자수 비율 [CY2014~24 : NHIS L1211+1212 | 2025 : 회복모형 | 2026~30 : 상한선(추세) 도달 가정]
A10: 상급종합병원 | B10: 0.40611575 | C10: 0.39892588 | D10: 0.41059265 | E10: 0.41523841 | F10: 0.41285457 | G10: 0.42658297 | H10: 0.43335215 | I10: 0.42967143 | J10: 0.41723829 | K10: 0.41075162 | L10: 0.39369144 | M10: 0.41385486 | N10: 0.40923663 | O10: 0.40352919 | P10: 0.32349471 | Q10: 0.33476881 | R10: =(Z81+AA81+AB81+AC81)/R7 | S10: =(AD81+AE81+AF81+AG81)/S7 | T10: =(AH81+AI81+AJ81+AK81)/T7 | U10: =(AL81+AM81+AN81+AO81)/U7 | V10: =(AP81+AQ81+AR81+AS81)/V7
A11: 종합병원 | B11: 0.34194774 | C11: 0.34789424 | D11: 0.35025632 | E11: 0.34764788 | F11: 0.33372282 | G11: 0.3240481 | H11: 0.32375132 | I11: 0.3257661 | J11: 0.33276331 | K11: 0.34437743 | L11: 0.35498678 | M11: 0.33924543 | N11: 0.34967121 | O11: 0.35835193 | P11: 0.39541189 | Q11: 0.38699743 | R11: =(Z82+AA82+AB82+AC82)/R7 | S11: =(AD82+AE82+AF82+AG82)/S7 | T11: =(AH82+AI82+AJ82+AK82)/T7 | U11: =(AL82+AM82+AN82+AO82)/U7 | V11: =(AP82+AQ82+AR82+AS82)/V7
A12: 병원급 | B12: 0.19372148 | C12: 0.19962898 | D12: 0.20014809 | E12: 0.20717851 | F12: 0.22170493 | G12: 0.22034575 | H12: 0.21655756 | I12: 0.21698443 | J12: 0.2175548 | K12: 0.21005733 | L12: 0.21080823 | M12: 0.20252056 | N12: 0.19259813 | O12: 0.18617874 | P12: 0.21415637 | Q12: 0.20410908 | R12: =(Z83+AA83+AB83+AC83)/R7 | S12: =(AD83+AE83+AF83+AG83)/S7 | T12: =(AH83+AI83+AJ83+AK83)/T7 | U12: =(AL83+AM83+AN83+AO83)/U7 | V12: =(AP83+AQ83+AR83+AS83)/V7
A13: 의원급 | B13: 0.058199908 | C13: 0.053533934 | D13: 0.038989842 | E13: 0.029926745 | F13: 0.031712638 | G13: 0.029019111 | H13: 0.026336061 | I13: 0.02757616 | J13: 0.032442673 | K13: 0.034813628 | L13: 0.040512684 | M13: 0.044378345 | N13: 0.048494027 | O13: 0.051940139 | P13: 0.066937042 | Q13: 0.074124683 | R13: =(Z84+AA84+AB84+AC84)/R7 | S13: =(AD84+AE84+AF84+AG84)/S7 | T13: =(AH84+AI84+AJ84+AK84)/T7 | U13: =(AL84+AM84+AN84+AO84)/U7 | V13: =(AP84+AQ84+AR84+AS84)/V7
A14: 보건기관등 | B14: 1.5123488e-05 | C14: 1.6961741e-05 | D14: 1.3097611e-05 | E14: 8.4568027e-06 | F14: 5.0451236e-06 | G14: 4.0714292e-06 | H14: 2.9141407e-06 | I14: 1.8918881e-06 | J14: 9.1741857e-07 | K14: 0 | L14: 8.5607057e-07 | M14: 8.0022983e-07 | N14: 0 | O14: 0 | P14: 0 | Q14: 0 | R14: 0 | S14: 0 | T14: 0 | U14: 0 | V14: 0
A16: ■ C. 종별 전신마취환자수 [전신마취환자수(A) x 종별 비율(B)]
A17: 상급종합병원 | B17: =B$7*B10 | C17: =C$7*C10 | D17: =D$7*D10 | E17: =E$7*E10 | F17: =F$7*F10 | G17: =G$7*G10 | H17: =H$7*H10 | I17: =I$7*I10 | ... V17: =V$7*V10
A18: 종합병원 | B18: =B$7*B11 | C18: =C$7*C11 | D18: =D$7*D11 | E18: =E$7*E11 | F18: =F$7*F11 | G18: =G$7*G11 | H18: =H$7*H11 | I18: =I$7*I11 | ... V18: =V$7*V11
A19: 병원급 | B19: =B$7*B12 | C19: =C$7*C12 | D19: =D$7*D12 | E19: =E$7*E12 | F19: =F$7*F12 | G19: =G$7*G12 | H19: =H$7*H12 | I19: =I$7*I12 | ... V19: =V$7*V12
A20: 의원급 | B20: =B$7*B13 | C20: =C$7*C13 | D20: =D$7*D13 | E20: =E$7*E13 | F20: =F$7*F13 | G20: =G$7*G13 | H20: =H$7*H13 | I20: =I$7*I13 | ... V20: =V$7*V13
A21: 보건기관등 | B21: =B$7*B14 | C21: =C$7*C14 | D21: =D$7*D14 | E21: =E$7*E14 | F21: =F$7*F14 | G21: =G$7*G14 | H21: =H$7*H14 | I21: =I$7*I14 | ... V21: =V$7*V14
A23: ■ D. Ramosetron 전체 수량 [2020~25 : IQVIA 기준, CY기준 ]
A24: Ramosetron (Vial or Ampoule) | L24: 3086324 | M24: 3529267 | N24: 3623943 | O24: 4166540 | P24: 3554307 | Q24: 3874647
A26: ■ E. 흡입마취제 사용량의 종별 비율 (%) [2020~25 : NHIS N01AB Halogenated hydrocarbons, CY기준]
A27: 상급종합병원 | L27: 0.37283534 | M27: 0.48208734 | N27: 0.52756862 | O27: 0.54469656 | P27: 0.4179469 | Q27: 0.43178314
A28: 종합병원 | L28: 0.32230249 | M28: 0.31692832 | N28: 0.32179792 | O28: 0.3277461 | P28: 0.42863765 | Q28: 0.42890484
A29: 병원 | L29: 0.27831834 | M29: 0.17813561 | N29: 0.1331923 | O29: 0.11046668 | P29: 0.13239123 | Q29: 0.11843795
A30: 의원 | L30: 0.026543837 | M30: 0.022848737 | N30: 0.017441161 | O30: 0.017090654 | P30: 0.021024223 | Q30: 0.020874075
A32: ■ F. 종별 환자당 Ramosetron 사용수량 (추정) [ Ramosetron 수량(D) x 흡입마취제 종별비율(E) ÷ 종별 전신마취 환자수(C) ]
A33: 상급종합병원 | L33: =L27*L$24/L17 | M33: =M27*M$24/M17 | N33: =N27*N$24/N17 | O33: =O27*O$24/O17 | P33: =P27*P$24/P17 | Q33: =Q27*Q$24/Q17 | R33: =MIN(5,SLOPE($L$33:$Q$33,$L$5:$Q$5)*R$5+INTERCEPT($L$33:$Q$33,$L$5:$Q$5)) | S33: =MIN(5,SLOPE($L$33:$Q$33,$L$5:$Q$5)*S$5+INTERCEPT($L$33:$Q$33,$L$5:$Q$5)) | T33: =MIN(5,SLOPE($L$33:$Q$33,$L$5:$Q$5)*T$5+INTERCEPT($L$33:$Q$33,$L$5:$Q$5)) | U33: =MIN(5,SLOPE($L$33:$Q$33,$L$5:$Q$5)*U$5+INTERCEPT($L$33:$Q$33,$L$5:$Q$5)) | V33: =MIN(5,SLOPE($L$33:$Q$33,$L$5:$Q$5)*V$5+INTERCEPT($L$33:$Q$33,$L$5:$Q$5))
A34: 종합병원 | L34: =L28*L$24/L18 | M34: =M28*M$24/M18 | N34: =N28*N$24/N18 | O34: =O28*O$24/O18 | P34: =P28*P$24/P18 | Q34: =Q28*Q$24/Q18 | R34: =MIN(4,SLOPE($L$34:$Q$34,$L$5:$Q$5)*R$5+INTERCEPT($L$34:$Q$34,$L$5:$Q$5)) | S34: =MIN(4,SLOPE($L$34:$Q$34,$L$5:$Q$5)*S$5+INTERCEPT($L$34:$Q$34,$L$5:$Q$5)) | T34: =MIN(4,SLOPE($L$34:$Q$34,$L$5:$Q$5)*T$5+INTERCEPT($L$34:$Q$34,$L$5:$Q$5)) | U34: =MIN(4,SLOPE($L$34:$Q$34,$L$5:$Q$5)*U$5+INTERCEPT($L$34:$Q$34,$L$5:$Q$5)) | V34: =MIN(4,SLOPE($L$34:$Q$34,$L$5:$Q$5)*V$5+INTERCEPT($L$34:$Q$34,$L$5:$Q$5))
A35: 병원 | L35: =L29*L$24/L19 | M35: =M29*M$24/M19 | N35: =N29*N$24/N19 | O35: =O29*O$24/O19 | P35: =P29*P$24/P19 | Q35: =Q29*Q$24/Q19 | R35: =Q35 | S35: =R35 | T35: =S35 | U35: =T35 | V35: =U35
A36: 의원 | L36: =L30*L$24/L20 | M36: =M30*M$24/M20 | N36: =N30*N$24/N20 | O36: =O30*O$24/O20 | P36: =P30*P$24/P20 | Q36: =Q30*Q$24/Q20 | R36: =Q36 | S36: =R36 | T36: =S36 | U36: =T36 | V36: =U36
A38: ■ F. 종별 Ramosetron 수량 (추정) FY기준 [ 종별 전신마취환자수 (C) x 종별 환자당 Ramosetron 사용수량 (F) ]
A39: 상급종합병원 | L39: =SUM(C86:F86) | M39: =SUM(G86:J86) | N39: =SUM(K86:N86) | O39: =SUM(O86:R86) | P39: =SUM(S86:V86) | Q39: =SUM(W86:Z86) | R39: =SUM(AA86:AD86) | S39: =SUM(AE86:AH86) | T39: =SUM(AI86:AL86) | U39: =SUM(AM86:AP86) | V39: =SUM(AQ86:AT86)
A40: 종합병원 | L40: =SUM(C87:F87) | M40: =SUM(G87:J87) | N40: =SUM(K87:N87) | O40: =SUM(O87:R87) | P40: =SUM(S87:V87) | Q40: =SUM(W87:Z87) | R40: =SUM(AA87:AD87) | S40: =SUM(AE87:AH87) | T40: =SUM(AI87:AL87) | U40: =SUM(AM87:AP87) | V40: =SUM(AQ87:AT87)
A41: 병원 | L41: =SUM(C88:F88) | M41: =SUM(G88:J88) | N41: =SUM(K88:N88) | O41: =SUM(O88:R88) | P41: =SUM(S88:V88) | Q41: =SUM(W88:Z88) | R41: =SUM(AA88:AD88) | S41: =SUM(AE88:AH88) | T41: =SUM(AI88:AL88) | U41: =SUM(AM88:AP88) | V41: =SUM(AQ88:AT88)
A42: 의원 | L42: =SUM(C89:F89) | M42: =SUM(G89:J89) | N42: =SUM(K89:N89) | O42: =SUM(O89:R89) | P42: =SUM(S89:V89) | Q42: =SUM(W89:Z89) | R42: =SUM(AA89:AD89) | S42: =SUM(AE89:AH89) | T42: =SUM(AI89:AL89) | U42: =SUM(AM89:AP89) | V42: =SUM(AQ89:AT89)
A43: ▶ Ramosetron 시장 수량 (IQVIA 기준) | L43: =SUM(L39:L42) | M43: =SUM(M39:M42) | N43: =SUM(N39:N42) | O43: =SUM(O39:O42) | P43: =SUM(P39:P42) | Q43: =SUM(Q39:Q42) | R43: =SUM(R39:R42) | S43: =SUM(S39:S42) | ... V43: =SUM(V39:V42)
M44: =M43/L43-1 | N44: =N43/M43-1 | O44: =O43/N43-1 | P44: =P43/O43-1 | Q44: =Q43/P43-1 | R44: =R43/Q43-1 | S44: =S43/R43-1 | T44: =T43/S43-1 | ... V44: =V43/U43-1
B46: [참고] 종별 비율 예측 파라미터 : 회복모형모델 | L46: =L17*L33
B47: 연령대 | C47: 상한/하한 | D47: 기울기(slope) | E47: 절편(intercept) | F47: 기울기(logit,S-curve)
B48: 상급종합병원 환자비율 | C48: 0.41 | D48: =SLOPE(S69:Y69,$S$65:$Y$65) | E48: =INTERCEPT(S69:Y69,$S$65:$Y$65)
B49: 종합병원 환자비율 (분기) | C49: 0.4 | D49: =SLOPE(S70:Y70,$S$65:$Y$65) | E49: =INTERCEPT(S70:Y70,$S$65:$Y$65)
...

Sheet 근거_NSA수량(IQVIA기준)
A2: NSA 수량 산출 : IQVIA 데이터 기반 예측 (로짓 변환 회귀)
B4: ◀ 실측 (UBIST MS, FY18~25) | J4: 예측 ▶
A5: 구분 / 회계연도 ▶ | B5: FY2018 | C5: FY2019 | D5: FY2020 | E5: FY2021 | F5: FY2022 | G5: FY2023 | H5: FY2024 | I5: FY2025 | J5: FY2026 | K5: FY2027 | L5: FY2028 | M5: FY2029 | N5: FY2030 | P5: FY26 1분기
A6: ■ A. Ramosetron 시장 수량 [근거_Ramosetron 시장 수량]
A7: Ramosetron 주사제 전체 수량 (시장) | D7: ='근거_Ramosetron 시장 수량'!L43 | E7: ='근거_Ramosetron 시장 수량'!M43 | F7: ='근거_Ramosetron 시장 수량'!N43 | G7: ='근거_Ramosetron 시장 수량'!O43 | H7: ='근거_Ramosetron 시장 수량'!P43 | I7: ='근거_Ramosetron 시장 수량'!Q43 | J7: ='근거_Ramosetron 시장 수량'!R43 | K7: ='근거_Ramosetron 시장 수량'!S43 | ... N7: ='근거_Ramosetron 시장 수량'!V43
A9: ■ B. 종별 Ramosetron 수량 : [근거_Ramosetron 시장 수량]
A10: 상급종합병원 | D10: ='근거_Ramosetron 시장 수량'!L39 | E10: ='근거_Ramosetron 시장 수량'!M39 | F10: ='근거_Ramosetron 시장 수량'!N39 | G10: ='근거_Ramosetron 시장 수량'!O39 | H10: ='근거_Ramosetron 시장 수량'!P39 | I10: ='근거_Ramosetron 시장 수량'!Q39 | J10: ='근거_Ramosetron 시장 수량'!R39 | K10: ='근거_Ramosetron 시장 수량'!S39 | ... N10: ='근거_Ramosetron 시장 수량'!V39
A11: 종합병원 | D11: ='근거_Ramosetron 시장 수량'!L40 | E11: ='근거_Ramosetron 시장 수량'!M40 | F11: ='근거_Ramosetron 시장 수량'!N40 | G11: ='근거_Ramosetron 시장 수량'!O40 | H11: ='근거_Ramosetron 시장 수량'!P40 | I11: ='근거_Ramosetron 시장 수량'!Q40 | J11: ='근거_Ramosetron 시장 수량'!R40 | K11: ='근거_Ramosetron 시장 수량'!S40 | ... N11: ='근거_Ramosetron 시장 수량'!V40
A12: 병원 | D12: ='근거_Ramosetron 시장 수량'!L41 | E12: ='근거_Ramosetron 시장 수량'!M41 | F12: ='근거_Ramosetron 시장 수량'!N41 | G12: ='근거_Ramosetron 시장 수량'!O41 | H12: ='근거_Ramosetron 시장 수량'!P41 | I12: ='근거_Ramosetron 시장 수량'!Q41 | J12: ='근거_Ramosetron 시장 수량'!R41 | K12: ='근거_Ramosetron 시장 수량'!S41 | ... N12: ='근거_Ramosetron 시장 수량'!V41
A13: 의원 | D13: ='근거_Ramosetron 시장 수량'!L42 | E13: ='근거_Ramosetron 시장 수량'!M42 | F13: ='근거_Ramosetron 시장 수량'!N42 | G13: ='근거_Ramosetron 시장 수량'!O42 | H13: ='근거_Ramosetron 시장 수량'!P42 | I13: ='근거_Ramosetron 시장 수량'!Q42 | J13: ='근거_Ramosetron 시장 수량'!R42 | K13: ='근거_Ramosetron 시장 수량'!S42 | ... N13: ='근거_Ramosetron 시장 수량'!V42
A15: ■ E. 종별 NSA MS : [ NSA 수량 (C) x NSA 종별 비율 (D) / 종별 Ramosetron 수량 (B) ]
A16: 상급종합병원 | E16: =(G49+H49+I49+J49)/E10 | F16: =(K49+L49+M49+N49)/F10 | G16: =(O49+P49+Q49+R49)/G10 | H16: =(S49+T49+U49+V49)/H10 | I16: =(W49+X49+Y49+Z49)/I10 | J16: =(AA49+AB49+AC49+AD49)/J10 | K16: =(AE49+AF49+AG49+AH49)/K10 | L16: =(AI49+AJ49+AK49+AL49)/L10 | M16: =(AM49+AN49+AO49+AP49)/M10 | N16: =(AQ49+AR49+AS49+AT49)/N10
A17: 종합병원 | E17: =(G50+H50+I50+J50)/E11 | F17: =(K50+L50+M50+N50)/F11 | G17: =(O50+P50+Q50+R50)/G11 | H17: =(S50+T50+U50+V50)/H11 | I17: =(W50+X50+Y50+Z50)/I11 | J17: =(AA50+AB50+AC50+AD50)/J11 | K17: =(AE50+AF50+AG50+AH50)/K11 | L17: =(AI50+AJ50+AK50+AL50)/L11 | M17: =(AM50+AN50+AO50+AP50)/M11 | N17: =(AQ50+AR50+AS50+AT50)/N11
A18: 병원 | E18: =(G51+H51+I51+J51)/E12 | F18: =(K51+L51+M51+N51)/F12 | G18: =(O51+P51+Q51+R51)/G12 | H18: =(S51+T51+U51+V51)/H12 | I18: =(W51+X51+Y51+Z51)/I12 | J18: =(AA51+AB51+AC51+AD51)/J12 | K18: =(AE51+AF51+AG51+AH51)/K12 | L18: =(AI51+AJ51+AK51+AL51)/L12 | M18: =(AM51+AN51+AO51+AP51)/M12 | N18: =(AQ51+AR51+AS51+AT51)/N12
A19: 의원 | E19: =(G52+H52+I52+J52)/E13 | F19: =(K52+L52+M52+N52)/F13 | G19: =(O52+P52+Q52+R52)/G13 | H19: =(S52+T52+U52+V52)/H13 | I19: =(W52+X52+Y52+Z52)/I13 | J19: =(AA52+AB52+AC52+AD52)/J13 | K19: =(AE52+AF52+AG52+AH52)/K13 | L19: =(AI52+AJ52+AK52+AL52)/L13 | M19: =(AM52+AN52+AO52+AP52)/M13 | N19: =(AQ52+AR52+AS52+AT52)/N13
A20: 전체 MS | E20: =E27/E7 | F20: =F27/F7 | G20: =G27/G7 | H20: =H27/H7 | I20: =I27/I7 | J20: =J27/J7 | K20: =K27/K7 | L20: =L27/L7 | ... N20: =N27/N7
A22: ■ F. 종별 NSA 수량 : [ 종별 Ramosetron 수량 (B) x 종별 NSA MS (E) ]
A23: 상급종합병원 | E23: =E10*E16 | F23: =F10*F16 | G23: =G10*G16 | H23: =H10*H16 | I23: =I10*I16 | J23: =J10*J16 | K23: =K10*K16 | L23: =L10*L16 | ... N23: =N10*N16
A24: 종합병원 | E24: =E11*E17 | F24: =F11*F17 | G24: =G11*G17 | H24: =H11*H17 | I24: =I11*I17 | J24: =J11*J17 | K24: =K11*K17 | L24: =L11*L17 | ... N24: =N11*N17
A25: 병원 | E25: =E12*E18 | F25: =F12*F18 | G25: =G12*G18 | H25: =H12*H18 | I25: =I12*I18 | J25: =J12*J18 | K25: =K12*K18 | L25: =L12*L18 | ... N25: =N12*N18
A26: 의원 | E26: =E13*E19 | F26: =F13*F19 | G26: =G13*G19 | H26: =H13*H19 | I26: =I13*I19 | J26: =J13*J19 | K26: =K13*K19 | L26: =L13*L19 | ... N26: =N13*N19
A27: ▶ NSA 수량 (IQVIA 기준) | D27: 1601660 | E27: =SUM(E23:E26) | F27: =SUM(F23:F26) | G27: =SUM(G23:G26) | H27: =SUM(H23:H26) | I27: =SUM(I23:I26) | J27: =SUM(J23:J26) | K27: =SUM(K23:K26) | L27: =SUM(L23:L26) | ... N27: =SUM(N23:N26)
E28: =E27/E7 | F28: =F27/F7 | G28: =G27/G7 | H28: =H27/H7 | I28: =I27/I7 | J28: =J27/J7 | K28: =K27/K7 | L28: =L27/L7 | ... N28: =N27/N7
B30: [참고] 종별 NSA MS 예측 파라미터 (2026Q2~2031Q1 적용)
B31: 유형 | C31: 예측방식 | D31: 분기당 기울기 | E31: 상한/하한 | F31: 백테스트 MAPE
B32: 상급종합병원 | C32: 전체기간선형(레벨보정) | D32: =SLOPE($F$43:$Z$43,$F$40:$Z$40) | E32: 0.55 | F32: 2.92%
B33: 종합병원 | C33: S-curve(로짓변환+저점앵커) | D33: =SLOPE($U$54:$Z$54,$U$40:$Z$40) | E33: 0.56 | F33: 3.83%
B34: 병원 | C34: 롤링4분기평균(갱신) | D34: - | E34: 4분기 이동평균 | F34: 8.89%
B35: 의원 | C35: EWMA(α=0.3) | D35: - | E35: EWMA 마지막값 flat | F35: 10.30%
B36: ※ 채택근거: 2020Q1~2026Q1 실측 walk-forward 백테스트. 상급종합·종합병원은 레벨보정 방식으로 통일(실측→예측 연속성 보장, 갱신 시 급락 리스크 방지)
A39: 구분 / CY분기 ▶ | B39: 2020Q1 | C39: 2020Q2 | D39: 2020Q3 | E39: 2020Q4 | F39: 2021Q1 | G39: 2021Q2 | H39: 2021Q3 | I39: 2021Q4 | J39: 2022Q1 | K39: 2022Q2 | L39: 2022Q3 | M39: 2022Q4 | N39: 2023Q1 | O39: 2023Q2 | P39: 2023Q3 | Q39: 2023Q4 | R39: 2024Q1 | S39: 2024Q2 | T39: 2024Q3 | U39: 2024Q4 | V39: 2025Q1 | W39: 2025Q2 | X39: 2025Q3 | Y39: 2025Q4 | Z39: 2026Q1 | AA39: 2026Q2 | AB39: 2026Q3 | AC39: 2026Q4 | AD39: 2027Q1 | AE39: 2027Q2 | AF39: 2027Q3 | AG39: 2027Q4 | AH39: 2028Q1 | AI39: 2028Q2 | AJ39: 2028Q3 | AK39: 2028Q4 | AL39: 2029Q1 | AM39: 2029Q2 | AN39: 2029Q3 | AO39: 2029Q4 | AP39: 2030Q1 | AQ39: 2030Q2 | AR39: 2030Q3 | AS39: 2030Q4 | AT39: 2031Q1
A40: 분기 순번(추세계산용) | B40: 1 | C40: 2 | D40: 3 | E40: 4 | F40: 5 | G40: 6 | H40: 7 | I40: 8 | J40: 9 | K40: 10 | L40: 11 | M40: 12 | N40: 13 | O40: 14 | P40: 15 | Q40: 16 | R40: 17 | S40: 18 | T40: 19 | U40: 20 | V40: 21 | W40: 22 | X40: 23 | Y40: 24 | Z40: 25 | AA40: 26 | AB40: 27 | AC40: 28 | AD40: 29 | AE40: 30 | AF40: 31 | AG40: 32 | AH40: 33 | AI40: 34 | AJ40: 35 | AK40: 36 | AL40: 37 | AM40: 38 | AN40: 39 | AO40: 40 | AP40: 41 | AQ40: 42 | AR40: 43 | AS40: 44 | AT40: 45
A42: ■ E. 종별 NSA MS : [ NSA 수량 (C) x NSA 종별 비율 (D) / 종별 Ramosetron 수량 (B) ]
A43: 상급종합병원 | B43: =원자료_분기실측!B46 | C43: =원자료_분기실측!C46 | D43: =원자료_분기실측!D46 | E43: =원자료_분기실측!E46 | F43: =원자료_분기실측!F46 | G43: =원자료_분기실측!G46 | H43: =원자료_분기실측!H46 | I43: =원자료_분기실측!I46 | ... Z43: =원자료_분기실측!Z46 | AA43: =MAX($E$32,$Z$43+$D$32*(AA40-$Z$40)) | AB43: =MAX($E$32,$Z$43+$D$32*(AB40-$Z$40)) | AC43: =MAX($E$32,$Z$43+$D$32*(AC40-$Z$40)) | AD43: =MAX($E$32,$Z$43+$D$32*(AD40-$Z$40)) | AE43: =MAX($E$32,$Z$43+$D$32*(AE40-$Z$40)) | AF43: =MAX($E$32,$Z$43+$D$32*(AF40-$Z$40)) | AG43: =MAX($E$32,$Z$43+$D$32*(AG40-$Z$40)) | AH43: =MAX($E$32,$Z$43+$D$32*(AH40-$Z$40)) | ... AT43: =MAX($E$32,$Z$43+$D$32*(AT40-$Z$40))
A44: 종합병원 | B44: =원자료_분기실측!B47 | C44: =원자료_분기실측!C47 | D44: =원자료_분기실측!D47 | E44: =원자료_분기실측!E47 | F44: =원자료_분기실측!F47 | G44: =원자료_분기실측!G47 | H44: =원자료_분기실측!H47 | I44: =원자료_분기실측!I47 | ... Z44: =원자료_분기실측!Z47 | AA44: =$E$33/(1+EXP(-(LN($Z$44/($E$33-$Z$44))+$D$33*(AA40-$Z$40)))) | AB44: =$E$33/(1+EXP(-(LN($Z$44/($E$33-$Z$44))+$D$33*(AB40-$Z$40)))) | AC44: =$E$33/(1+EXP(-(LN($Z$44/($E$33-$Z$44))+$D$33*(AC40-$Z$40)))) | AD44: =$E$33/(1+EXP(-(LN($Z$44/($E$33-$Z$44))+$D$33*(AD40-$Z$40)))) | AE44: =$E$33/(1+EXP(-(LN($Z$44/($E$33-$Z$44))+$D$33*(AE40-$Z$40)))) | AF44: =$E$33/(1+EXP(-(LN($Z$44/($E$33-$Z$44))+$D$33*(AF40-$Z$40)))) | AG44: =$E$33/(1+EXP(-(LN($Z$44/($E$33-$Z$44))+$D$33*(AG40-$Z$40)))) | AH44: =$E$33/(1+EXP(-(LN($Z$44/($E$33-$Z$44))+$D$33*(AH40-$Z$40)))) | ... AT44: =$E$33/(1+EXP(-(LN($Z$44/($E$33-$Z$44))+$D$33*(AT40-$Z$40))))
A45: 병원 | B45: =원자료_분기실측!B48 | C45: =원자료_분기실측!C48 | D45: =원자료_분기실측!D48 | E45: =원자료_분기실측!E48 | F45: =원자료_분기실측!F48 | G45: =원자료_분기실측!G48 | H45: =원자료_분기실측!H48 | I45: =원자료_분기실측!I48 | ... Z45: =원자료_분기실측!Z48 | AA45: =AVERAGE(W45,X45,Y45,Z45) | AB45: =AVERAGE(X45,Y45,Z45,AA45) | AC45: =AVERAGE(Y45,Z45,AA45,AB45) | AD45: =AVERAGE(Z45,AA45,AB45,AC45) | AE45: =AVERAGE(AA45,AB45,AC45,AD45) | AF45: =AVERAGE(AB45,AC45,AD45,AE45) | AG45: =AVERAGE(AC45,AD45,AE45,AF45) | AH45: =AVERAGE(AD45,AE45,AF45,AG45) | ... AT45: =AVERAGE(AP45,AQ45,AR45,AS45)
A46: 의원 | B46: =원자료_분기실측!B49 | C46: =원자료_분기실측!C49 | D46: =원자료_분기실측!D49 | E46: =원자료_분기실측!E49 | F46: =원자료_분기실측!F49 | G46: =원자료_분기실측!G49 | H46: =원자료_분기실측!H49 | I46: =원자료_분기실측!I49 | ... Z46: =원자료_분기실측!Z49 | AA46: =$Z$47 | AB46: =$Z$47 | AC46: =$Z$47 | AD46: =$Z$47 | AE46: =$Z$47 | AF46: =$Z$47 | AG46: =$Z$47 | AH46: =$Z$47 | ... AT46: =$Z$47
A47: [의원 EWMA 계산용, alpha=0.3] | F47: =F46 | G47: =0.3*G46+0.7*F47 | H47: =0.3*H46+0.7*G47 | I47: =0.3*I46+0.7*H47 | J47: =0.3*J46+0.7*I47 | K47: =0.3*K46+0.7*J47 | L47: =0.3*L46+0.7*K47 | M47: =0.3*M46+0.7*L47 | N47: =0.3*N46+0.7*M47 | ... Z47: =0.3*Z46+0.7*Y47
A48: ■ F. 종별 NSA 수량 : [ 종별 Ramosetron 수량 (B) x 종별 NSA MS (E) ]
A49: 상급종합병원 | B49: ='근거_Ramosetron 시장 수량'!B86*B43 | C49: ='근거_Ramosetron 시장 수량'!C86*C43 | D49: ='근거_Ramosetron 시장 수량'!D86*D43 | E49: ='근거_Ramosetron 시장 수량'!E86*E43 | F49: ='근거_Ramosetron 시장 수량'!F86*F43 | G49: ='근거_Ramosetron 시장 수량'!G86*G43 | H49: ='근거_Ramosetron 시장 수량'!H86*H43 | I49: ='근거_Ramosetron 시장 수량'!I86*I43 | ... Z49: ='근거_Ramosetron 시장 수량'!Z86*Z43 | AA49: ='근거_Ramosetron 시장 수량'!AA86*'근거_NSA수량(IQVIA기준)'!AA43 | AB49: ='근거_Ramosetron 시장 수량'!AB86*'근거_NSA수량(IQVIA기준)'!AB43 | AC49: ='근거_Ramosetron 시장 수량'!AC86*'근거_NSA수량(IQVIA기준)'!AC43 | AD49: ='근거_Ramosetron 시장 수량'!AD86*'근거_NSA수량(IQVIA기준)'!AD43 | AE49: ='근거_Ramosetron 시장 수량'!AE86*'근거_NSA수량(IQVIA기준)'!AE43 | AF49: ='근거_Ramosetron 시장 수량'!AF86*'근거_NSA수량(IQVIA기준)'!AF43 | AG49: ='근거_Ramosetron 시장 수량'!AG86*'근거_NSA수량(IQVIA기준)'!AG43 | AH49: ='근거_Ramosetron 시장 수량'!AH86*'근거_NSA수량(IQVIA기준)'!AH43 | ... AT49: ='근거_Ramosetron 시장 수량'!AT86*'근거_NSA수량(IQVIA기준)'!AT43
...

Sheet 근거_매출
A2: DSKR NSA (SAP)매출 산출 : IQVIA 데이터 기반 예측 (FY26 목표단가 적용)
B4: ◀ 실측 (DSKR, FY2020~2025) | J4: 예측 ▶
A5: 구분 / 회계연도 ▶ | B5: FY2018 | C5: FY2019 | D5: FY2020 | E5: FY2021 | F5: FY2022 | G5: FY2023 | H5: FY2024 | I5: FY2025 | J5: FY2026 | K5: FY2027 | L5: FY2028 | M5: FY2029 | N5: FY2030
A6: ■ A. NSA 수량 (A, IQVIA 기준) [근거_NSA수량(IQVIA기준) 참조]
A7: NSA 수량 | B7: =IF('근거_NSA수량(IQVIA기준)'!B27=0,"",'근거_NSA수량(IQVIA기준)'!B27) | C7: =IF('근거_NSA수량(IQVIA기준)'!C27=0,"",'근거_NSA수량(IQVIA기준)'!C27) | D7: =IF('근거_NSA수량(IQVIA기준)'!D27=0,"",'근거_NSA수량(IQVIA기준)'!D27) | E7: =IF('근거_NSA수량(IQVIA기준)'!E27=0,"",'근거_NSA수량(IQVIA기준)'!E27) | F7: =IF('근거_NSA수량(IQVIA기준)'!F27=0,"",'근거_NSA수량(IQVIA기준)'!F27) | G7: =IF('근거_NSA수량(IQVIA기준)'!G27=0,"",'근거_NSA수량(IQVIA기준)'!G27) | H7: =IF('근거_NSA수량(IQVIA기준)'!H27=0,"",'근거_NSA수량(IQVIA기준)'!H27) | I7: =IF('근거_NSA수량(IQVIA기준)'!I27=0,"",'근거_NSA수량(IQVIA기준)'!I27) | ... N7: =IF('근거_NSA수량(IQVIA기준)'!N27=0,"",'근거_NSA수량(IQVIA기준)'!N27)
A9: ■ B. DSKR 매출수량 (A) [FY2020~2025 : SAP 실측 | FY2026~FY2030 : NSA 수량(A) ÷ 전환비율(C)]
A10: ▶ 1) Model Base | D10: 1609310 | E10: 1938415 | F10: 1836815 | G10: 2035465 | H10: 1595925 | I10: 1905010 | J10: =J7/J24 | K10: =K7/K24 | L10: =L7/L24 | M10: =M7/M24 | N10: =N7/N24
A11: : 모듈 산출치로 시나리오 기준선 역할
A12: ▶ 2) MKT Base [FY2026 : MKT 제공 예측치 (J12 직접 입력) | FY2027~FY2030 : 전년 × Model Base 증감률] | K12: =IF($J$12="","",J12*K10/J10) | L12: =IF($J$12="","",K12*L10/K10) | M12: =IF($J$12="","",L12*M10/L10) | N12: =IF($J$12="","",M12*N10/M10)
A13: : '26 MKT 제출 수치를 J12(노랑)에 입력하면 MKT Base 행·차트가 자동 활성화 (미입력 시 공란) | J13: =IF($J$12="","",J12/J10-1) | K13: =IF($J$12="","",K12/K10-1) | L13: =IF($J$12="","",L12/L10-1) | M13: =IF($J$12="","",M12/M10-1) | N13: =IF($J$12="","",N12/N10-1)
A14: ▶ 3) Best Scenario (±10%p) [FY2027~FY2030 : (Base NSA 수량 + NSA MS +10%p 효과 (MS 100% 상한 적용)) ÷ 전환비율] | J14: =('근거_NSA수량(IQVIA기준)'!J27)/J24 | K14: =(MIN('근거_NSA수량(IQVIA기준)'!K27+0.1*'근거_NSA수량(IQVIA기준)'!K7,'근거_NSA수량(IQVIA기준)'!K7))/K24 | L14: =(MIN('근거_NSA수량(IQVIA기준)'!L27+0.1*'근거_NSA수량(IQVIA기준)'!L7,'근거_NSA수량(IQVIA기준)'!L7))/L24 | M14: =(MIN('근거_NSA수량(IQVIA기준)'!M27+0.1*'근거_NSA수량(IQVIA기준)'!M7,'근거_NSA수량(IQVIA기준)'!M7))/M24 | N14: =(MIN('근거_NSA수량(IQVIA기준)'!N27+0.1*'근거_NSA수량(IQVIA기준)'!N7,'근거_NSA수량(IQVIA기준)'!N7))/N24
A15: : Model Base 기준, Ramosetron 시장 내 NSA MS +10%p 확대 시나리오 (전 종별 동시 적용) | J15: =J14/J10-1 | K15: =K14/K10-1 | L15: =L14/L10-1 | M15: =M14/M10-1 | N15: =N14/N10-1
A16: ▶ 4) Worst Scenario (±10%p) [FY2027~FY2030 : (Base NSA 수량 + NSA MS -10%p 효과) ÷ 전환비율] | J16: =('근거_NSA수량(IQVIA기준)'!J27)/J24 | K16: =('근거_NSA수량(IQVIA기준)'!K27-0.1*'근거_NSA수량(IQVIA기준)'!K7)/K24 | L16: =('근거_NSA수량(IQVIA기준)'!L27-0.1*'근거_NSA수량(IQVIA기준)'!L7)/L24 | M16: =('근거_NSA수량(IQVIA기준)'!M27-0.1*'근거_NSA수량(IQVIA기준)'!M7)/M24 | N16: =('근거_NSA수량(IQVIA기준)'!N27-0.1*'근거_NSA수량(IQVIA기준)'!N7)/N24
A17: : Model Base 기준, Ramosetron 시장 내 NSA MS -10%p 잠식 시나리오 (전 종별 동시 적용) | J17: =J16/J10-1 | K17: =K16/K10-1 | L17: =L16/L10-1 | M17: =M16/M10-1 | N17: =N16/N10-1
A18: ▶ 5) Best Scenario (±5%p) [FY2027~FY2030 : (Base NSA 수량 + NSA MS +5%p 효과 (MS 100% 상한 적용)) ÷ 전환비율] | J18: =('근거_NSA수량(IQVIA기준)'!J27)/J24 | K18: =(MIN('근거_NSA수량(IQVIA기준)'!K27+0.05*'근거_NSA수량(IQVIA기준)'!K7,'근거_NSA수량(IQVIA기준)'!K7))/K24 | L18: =(MIN('근거_NSA수량(IQVIA기준)'!L27+0.05*'근거_NSA수량(IQVIA기준)'!L7,'근거_NSA수량(IQVIA기준)'!L7))/L24 | M18: =(MIN('근거_NSA수량(IQVIA기준)'!M27+0.05*'근거_NSA수량(IQVIA기준)'!M7,'근거_NSA수량(IQVIA기준)'!M7))/M24 | N18: =(MIN('근거_NSA수량(IQVIA기준)'!N27+0.05*'근거_NSA수량(IQVIA기준)'!N7,'근거_NSA수량(IQVIA기준)'!N7))/N24
A19: : Model Base 기준, Ramosetron 시장 내 NSA MS +5%p 확대 시나리오 (전 종별 동시 적용) | J19: =J18/J10-1 | K19: =K18/K10-1 | L19: =L18/L10-1 | M19: =M18/M10-1 | N19: =N18/N10-1
A20: ▶ 6) Worst Scenario (±5%p) [FY2027~FY2030 : (Base NSA 수량 + NSA MS -5%p 효과) ÷ 전환비율] | J20: =('근거_NSA수량(IQVIA기준)'!J27)/J24 | K20: =('근거_NSA수량(IQVIA기준)'!K27-0.05*'근거_NSA수량(IQVIA기준)'!K7)/K24 | L20: =('근거_NSA수량(IQVIA기준)'!L27-0.05*'근거_NSA수량(IQVIA기준)'!L7)/L24 | M20: =('근거_NSA수량(IQVIA기준)'!M27-0.05*'근거_NSA수량(IQVIA기준)'!M7)/M24 | N20: =('근거_NSA수량(IQVIA기준)'!N27-0.05*'근거_NSA수량(IQVIA기준)'!N7)/N24
A21: : Model Base 기준, Ramosetron 시장 내 NSA MS -5%p 잠식 시나리오 (전 종별 동시 적용) | J21: =J20/J10-1 | K21: =K20/K10-1 | L21: =L20/L10-1 | M21: =M20/M10-1 | N21: =N20/N10-1
A23: ■ C. 전환비율 (IQVIA 수량 ÷ SAP 매출수량) [FY2020~2025 : 산출치 | FY2026~2030 : FY24~25 평균 (원 모델 기준 유지)]
A24: 전환비율 | D24: =IFERROR(D7/D10,"") | E24: =IFERROR(E7/E10,"") | F24: =IFERROR(F7/F10,"") | G24: =IFERROR(G7/G10,"") | H24: =IFERROR(H7/H10,"") | I24: =IFERROR(I7/I10,"") | J24: =AVERAGE(H24:I24) | K24: =J24 | L24: =K24 | M24: =L24 | N24: =M24
A26: ■ D. 단가 (원/A) [연도별 단가 : FY2026 목표단가(백만원/5A) ÷ 5 × 연도별 약가 배율 (인하 고시 시 28행 수정) ]
A27: 환산 단가 (원/A) | B27: =$B$59/5*1000000 | C27: (NASEA Inj. 0.3mg/5A FY2026 목표단가 ÷ 5 — 하단 [참고] 목표단가 참조)
A28: 약가 배율 (%) | J28: 1 | K28: 1 | L28: 1 | M28: 1 | N28: 1 | O28: ◀ 약가 인하 고시 없음 → 100% 유지 (인하 확정 시 해당 연도 배율만 수정)
A29: 단가 (원/A) | J29: =$B$27*J28 | K29: =$B$27*K28 | L29: =$B$27*L28 | M29: =$B$27*M28 | N29: =$B$27*N28
A31: ■ E. DSKR SAP매출액 (백만원) [FY2020~2025 : 실측 수량 × FY2026 목표단가 | FY2026~FY2030 : DSKR 매출 수량(B) × 단가(D) ]
A32: ▶ 1) Model Base : (B-1) × (D) | D32: 22226.502 | E32: 26771.837 | F32: 25368.619 | G32: 28112.214 | H32: 22041.639 | I32: 26310.474 | J32: =J10*J29/1000000 | K32: =K10*K29/1000000 | L32: =L10*L29/1000000 | M32: =M10*M29/1000000 | N32: =N10*N29/1000000
A33: YoY 증감률 | C33: =IFERROR(C32/B32-1,"") | D33: =IFERROR(D32/C32-1,"") | E33: =IFERROR(E32/D32-1,"") | F33: =IFERROR(F32/E32-1,"") | G33: =IFERROR(G32/F32-1,"") | H33: =IFERROR(H32/G32-1,"") | I33: =IFERROR(I32/H32-1,"") | J33: =IFERROR(J32/I32-1,"") | ... N33: =IFERROR(N32/M32-1,"")
A34: ▶ 2) MKT Base : MKT Base(B-2) × 단가(D) | J34: =IF($J$12="","",J12*J29/1000000) | K34: =IF($J$12="","",K12*K29/1000000) | L34: =IF($J$12="","",L12*L29/1000000) | M34: =IF($J$12="","",M12*M29/1000000) | N34: =IF($J$12="","",N12*N29/1000000)
A35: ▶ 3) Best (±10%p) : Best 수량(B-3) × 단가(D) | J35: =J14*J29/1000000 | K35: =K14*K29/1000000 | L35: =L14*L29/1000000 | M35: =M14*M29/1000000 | N35: =N14*N29/1000000
A36: ▶ 4) Worst (±10%p) : Worst 수량(B-4) × 단가(D) | J36: =J16*J29/1000000 | K36: =K16*K29/1000000 | L36: =L16*L29/1000000 | M36: =M16*M29/1000000 | N36: =N16*N29/1000000
A37: ▶ 5) Best (±5%p) : Best 수량(B-5) × 단가(D) | J37: =J18*J29/1000000 | K37: =K18*K29/1000000 | L37: =L18*L29/1000000 | M37: =M18*M29/1000000 | N37: =N18*N29/1000000
A38: ▶ 6) Worst (±5%p) : Worst 수량(B-6) × 단가(D) | J38: =J20*J29/1000000 | K38: =K20*K29/1000000 | L38: =L20*L29/1000000 | M38: =M20*M29/1000000 | N38: =N20*N29/1000000
B40: [참고]
B41: *시나리오 밴드 설정 및 산출 기준
B42: · 시나리오 기준 (민감도 1위 지표: Ramosetron 시장 내 NSA MS) — ±10%p(주 밴드)·±5%p(보조 밴드) 2단계
B43: - Best (MS 확대): 상급종합·종합병원 코드인 유지 및 병원급 확대로 NSA MS +10%p / +5%p → 매출 상단
B44: - Worst (MS 잠식): 제네릭 저가 입찰·처방 전환으로 NSA MS -10%p / -5%p → 매출 하단
B45: · 핵심 산출 근거: 종별 NSA MS 분기 실측(2020Q1~2026Q1, 근거_NSA수량 [참고]) 기준 가감. 시장 수량(Ramosetron)은 Base 고정
B46: · 전략적 시사점
B47: - Best와 Worst 시나리오 간의 최종 매출 격차(Band 폭)는 예측 오차가 아니라, 영업·마케팅의 종별 MS 방어·확대 활동이 창출해야 할 '전략적 목표 가치(Value)'를 의미
...

Sheet 근거_민감도
A2: NSA FCST 민감도 : 변동요인별 ± 이동이 Model Base 매출에 주는 영향
A4: ■ A. 방법
A5: · 방법: 한 번에 한 레버씩 하방/상방 조건으로 이동시켜 Model Base 매출(근거_매출 ■E-1)을 재계산. 레버 간 상관 미반영(일원 민감도). 사본 재계산(LibreOffice 전체 재계산) 결과의 정적 기록
A8: ■ B. 레버 정의
B9: 모델 내 위치 | C9: 기준값 | D9: 하방조건 | E9: 상방조건 | F9: 범위설정 근거
A10: L1 전신마취환자수 | B10: 근거_전신마취환자수 40행 (2026~2030 연간) | C10: 연령별 회귀/평균 | D10: -2% | E10: +2% | F10: 동등 산포의 레벨 쇼크(±2%) 근사
A11: L2 상급종합 환자비율 상한 | B11: 근거_Ramosetron 시장 수량 C48 | C11: 0.41 | D11: 0.38 | E11: 0.44 | F11: 회복모형 상한 ±3%p
A12: L3 종합병원 환자비율 하한 | B12: 근거_Ramosetron 시장 수량 C49 | C12: 0.4 | D12: 0.37 | E12: 0.43 | F12: 회복모형 하한 ±3%p
A13: L4 환자당 Ramo 사용량 | B13: 근거_Ramosetron 시장 수량 33~36행 (2026~2030) | C13: 선형회귀(상한) / flat | D13: -5% | E13: +5% | F13: 연간모델 표본 부족에 따른 레벨 쇼크 ±5%
A14: L5 NSA MS 상급종합 하한 | B14: 근거_NSA수량 E32 (레벨보정 하한) | C14: 0.55 | D14: 0.52 | E14: 0.58 | F14: 백테스트 MAPE 2.9% 기준 ±3%p
A15: L6 NSA MS 종합병원 상한 | B15: 근거_NSA수량 E33 (S-curve 상한) | C15: 0.56 | D15: 0.53 | E15: 0.59 | F15: 백테스트 MAPE 3.8% 기준 ±3%p
A16: L7 NSA MS 병원·의원 | B16: 근거_NSA수량 51~52행 (2026Q2~2030Q4 수량) | C16: 롤링4Q / EWMA | D16: -10% | E16: +10% | F16: 백테스트 MAPE 8.9~10.3% 기준 ±10%
A17: L8 NSA MS 전체 (시나리오) | B17: 근거_매출 14·16행 (NSA 수량 ± MS×시장) | C17: 종별 회귀 합산 | D17: MS -10%p | E17: MS +10%p | F17: MTS 밴드와 동일 정의 (라이브 수식)
A18: L9 전환비율 | B18: 근거_매출 24행 (FY24~25 평균) | C18: 1.044 | D18: 1.047 | E18: 1.01 | F18: FY2023~25 실측 최소·최대
A21: ■ C. 결과 — 기준 대비 매출 변화율
B22: FY2027하방 | C22: FY2027상방 | D22: FY2030하방 | E22: FY2030상방 | F22: FY2030 최대영향(±)
A23: L8 NSA MS 전체 (시나리오) | B23: =근거_매출!K36/근거_매출!K32-1 | C23: =근거_매출!K35/근거_매출!K32-1 | D23: =근거_매출!N36/근거_매출!N32-1 | E23: =근거_매출!N35/근거_매출!N32-1 | F23: =MAX(ABS(D23),ABS(E23))
A24: L4 환자당 Ramo 사용량 | B24: =-0.05237 | C24: =0.052672 | D24: =-0.054968 | E24: =0.056379 | F24: =MAX(ABS(D24),ABS(E24))
A25: L9 전환비율 | B25: =-0.002857 | C25: =0.033672 | D25: =-0.002857 | E25: =0.033672 | F25: =MAX(ABS(D25),ABS(E25))
A26: L5 NSA MS 상급종합 하한 | B26: =-0.000419 | C26: =0.020518 | D26: =-0.029562 | E26: =0.029562 | F26: =MAX(ABS(D26),ABS(E26))
A27: L6 NSA MS 종합병원 상한 | B27: =-0.014146 | C27: =0.011442 | D27: =-0.022372 | E27: =0.021518 | F27: =MAX(ABS(D27),ABS(E27))
A28: L1 전신마취환자수 | B28: =-0.02 | C28: =0.02 | D28: =-0.02 | E28: =0.02 | F28: =MAX(ABS(D28),ABS(E28))
A29: L2 상급종합 환자비율 상한 | B29: =-0.009362 | C29: =0.000539 | D29: =-0.010356 | E29: =0.009761 | F29: =MAX(ABS(D29),ABS(E29))
A30: L7 NSA MS 병원·의원 | B30: =-0.004034 | C30: =0.004034 | D30: =-0.002819 | E30: =0.002819 | F30: =MAX(ABS(D30),ABS(E30))
A31: L3 종합병원 환자비율 하한 | B31: =-0.0025 | C31: =0.002361 | D31: =-0.00271 | E31: =0.002554 | F31: =MAX(ABS(D31),ABS(E31))
A33: · L8 NSA MS 전체는 MTS 밴드(근거_매출 35·36행, ±10%p)와 동일 정의라 수식 참조(라이브). 나머지는 사본 재계산의 정적 기록
A34: · NSA 모델은 CY 분기 모델(2026Q1 실측 → 2026Q2~ 예측)이며 FY2026(2026Q2~2027Q1)은 전량 예측 구간 — 환자수·비율 레버도 FY2026부터 영향
A35: · L4 환자당 사용량은 종별 4행을 동시에 이동. L7은 병원·의원 NSA 수량(=시장×MS)에 직접 적용해 롤링평균 누적효과를 배제
A36: · 결과 수치는 산출 시점(2026-09-15)의 모델 상태 기준이며, 원자료_분기실측 갱신 시 L8 외 정적 값은 재산출 필요
A39: ■ D. 차트 소스 데이터
A40: 요인(±%) | B40: L3 종합병원 환자비율 하한 | C40: L7 NSA MS 병원·의원 | D40: L2 상급종합 환자비율 상한 | E40: L1 전신마취환자수 | F40: L6 NSA MS 종합병원 상한 | G40: L5 NSA MS 상급종합 하한 | H40: L9 전환비율 | I40: L4 환자당 Ramo 사용량 | J40: L8 NSA MS 전체 (시나리오)
A41: 영향(%) | B41: =ROUND(F31*100,1) | C41: =ROUND(F30*100,1) | D41: =ROUND(F29*100,1) | E41: =ROUND(F28*100,1) | F41: =ROUND(F27*100,1) | G41: =ROUND(F26*100,1) | H41: =ROUND(F25*100,1) | I41: =ROUND(F24*100,1) | J41: =ROUND(F23*100,1)
A43: FY2030(억) | B43: MS 잠식(-10%p) | C43: Base | D43: MS 확대(+10%p)
A44: 매출 | B44: =ROUND(근거_매출!N36/100,0) | C44: =ROUND(근거_매출!N32/100,0) | D44: =ROUND(근거_매출!N35/100,0)
A45: 매출 (±5%p 밴드) | B45: =ROUND(근거_매출!N38/100,0) | C45: =ROUND(근거_매출!N32/100,0) | D45: =ROUND(근거_매출!N37/100,0)

Sheet CALC
B2: Part 1) 전신마취환자수&시장 예측 [CY 기준 · 역년 1~12월] / IQVIA 처방량 예측 [FY 기준 · 회계연도 4~3월]
B3: 연도 | C3: 전신마취환자수 | E3: Ramosetron 시장 수량 (IQVIA 기준) | H3: NSA 수량 (IQVIA기준)
A4: 전체인구수 | B4: CY연도기준 | C4: 환자수 | D4: 비율 | E4: Ramosetron 시장 수량 | F4: 환자당 연간 처방량 | G4: YoY | H4: NSA 수량 | I4: MS | J4: YoY
A5: =근거_전신마취환자수!B16 | B5: 2010 | C5: =근거_전신마취환자수!B40 | D5: =IFERROR(C5/A5,"") | E5: ='근거_Ramosetron 시장 수량'!B43 | F5: =IFERROR(E5/C5,"")
A6: =근거_전신마취환자수!C16 | B6: 2011 | C6: =근거_전신마취환자수!C40 | D6: =IFERROR(C6/A6,"") | E6: ='근거_Ramosetron 시장 수량'!C43 | F6: =IFERROR(E6/C6,"") | G6: =IFERROR(E6/E5-1,"")
A7: =근거_전신마취환자수!D16 | B7: 2012 | C7: =근거_전신마취환자수!D40 | D7: =IFERROR(C7/A7,"") | E7: ='근거_Ramosetron 시장 수량'!D43 | F7: =IFERROR(E7/C7,"") | G7: =IFERROR(E7/E6-1,"")
A8: =근거_전신마취환자수!E16 | B8: 2013 | C8: =근거_전신마취환자수!E40 | D8: =IFERROR(C8/A8,"") | E8: ='근거_Ramosetron 시장 수량'!E43 | F8: =IFERROR(E8/C8,"") | G8: =IFERROR(E8/E7-1,"")
A9: =근거_전신마취환자수!F16 | B9: 2014 | C9: =근거_전신마취환자수!F40 | D9: =IFERROR(C9/A9,"") | E9: ='근거_Ramosetron 시장 수량'!F43 | F9: =IFERROR(E9/C9,"") | G9: =IFERROR(E9/E8-1,"")
A10: =근거_전신마취환자수!G16 | B10: 2015 | C10: =근거_전신마취환자수!G40 | D10: =IFERROR(C10/A10,"") | E10: ='근거_Ramosetron 시장 수량'!G43 | F10: =IFERROR(E10/C10,"") | G10: =IFERROR(E10/E9-1,"")
A11: =근거_전신마취환자수!H16 | B11: 2016 | C11: =근거_전신마취환자수!H40 | D11: =IFERROR(C11/A11,"") | E11: ='근거_Ramosetron 시장 수량'!H43 | F11: =IFERROR(E11/C11,"") | G11: =IFERROR(E11/E10-1,"")
A12: =근거_전신마취환자수!I16 | B12: 2017 | C12: =근거_전신마취환자수!I40 | D12: =IFERROR(C12/A12,"") | E12: ='근거_Ramosetron 시장 수량'!I43 | F12: =IFERROR(E12/C12,"") | G12: =IFERROR(E12/E11-1,"")
A13: =근거_전신마취환자수!J16 | B13: 2018 | C13: =근거_전신마취환자수!J40 | D13: =IFERROR(C13/A13,"") | E13: ='근거_Ramosetron 시장 수량'!J43 | F13: =IFERROR(E13/C13,"") | G13: =IFERROR(E13/E12-1,"") | H13: 0
A14: =근거_전신마취환자수!K16 | B14: 2019 | C14: =근거_전신마취환자수!K40 | D14: =IFERROR(C14/A14,"") | E14: ='근거_Ramosetron 시장 수량'!K43 | F14: =IFERROR(E14/C14,"") | G14: =IFERROR(E14/E13-1,"") | H14: 0
A15: =근거_전신마취환자수!L16 | B15: 2020 | C15: =근거_전신마취환자수!L40 | D15: =IFERROR(C15/A15,"") | E15: ='근거_Ramosetron 시장 수량'!L43 | F15: =IFERROR(E15/C15,"") | G15: =IFERROR(E15/E14-1,"") | H15: ='근거_NSA수량(IQVIA기준)'!D27 | I15: =IFERROR(H15/E15,"")
A16: =근거_전신마취환자수!M16 | B16: 2021 | C16: =근거_전신마취환자수!M40 | D16: =IFERROR(C16/A16,"") | E16: ='근거_Ramosetron 시장 수량'!M43 | F16: =IFERROR(E16/C16,"") | G16: =IFERROR(E16/E15-1,"") | H16: ='근거_NSA수량(IQVIA기준)'!E27 | I16: =IFERROR(H16/E16,"") | J16: =IFERROR(H16/H15-1,"")
A17: =근거_전신마취환자수!N16 | B17: 2022 | C17: =근거_전신마취환자수!N40 | D17: =IFERROR(C17/A17,"") | E17: ='근거_Ramosetron 시장 수량'!N43 | F17: =IFERROR(E17/C17,"") | G17: =IFERROR(E17/E16-1,"") | H17: ='근거_NSA수량(IQVIA기준)'!F27 | I17: =IFERROR(H17/E17,"") | J17: =IFERROR(H17/H16-1,"")
A18: =근거_전신마취환자수!O16 | B18: 2023 | C18: =근거_전신마취환자수!O40 | D18: =IFERROR(C18/A18,"") | E18: ='근거_Ramosetron 시장 수량'!O43 | F18: =IFERROR(E18/C18,"") | G18: =IFERROR(E18/E17-1,"") | H18: ='근거_NSA수량(IQVIA기준)'!G27 | I18: =IFERROR(H18/E18,"") | J18: =IFERROR(H18/H17-1,"")
A19: =근거_전신마취환자수!P16 | B19: 2024 | C19: =근거_전신마취환자수!P40 | D19: =IFERROR(C19/A19,"") | E19: ='근거_Ramosetron 시장 수량'!P43 | F19: =IFERROR(E19/C19,"") | G19: =IFERROR(E19/E18-1,"") | H19: ='근거_NSA수량(IQVIA기준)'!H27 | I19: =IFERROR(H19/E19,"") | J19: =IFERROR(H19/H18-1,"")
A20: =근거_전신마취환자수!Q16 | B20: 2025 | C20: =근거_전신마취환자수!Q40 | D20: =IFERROR(C20/A20,"") | E20: ='근거_Ramosetron 시장 수량'!Q43 | F20: =IFERROR(E20/C20,"") | G20: =IFERROR(E20/E19-1,"") | H20: ='근거_NSA수량(IQVIA기준)'!I27 | I20: =IFERROR(H20/E20,"") | J20: =IFERROR(H20/H19-1,"")
A21: =근거_전신마취환자수!R16 | B21: 2026 | C21: =근거_전신마취환자수!R40 | D21: =IFERROR(C21/A21,"") | E21: ='근거_Ramosetron 시장 수량'!R43 | F21: =IFERROR(E21/C21,"") | G21: =IFERROR(E21/E20-1,"") | H21: ='근거_NSA수량(IQVIA기준)'!J27 | I21: =IFERROR(H21/E21,"") | J21: =IFERROR(H21/H20-1,"")
A22: =근거_전신마취환자수!S16 | B22: 2027 | C22: =근거_전신마취환자수!S40 | D22: =IFERROR(C22/A22,"") | E22: ='근거_Ramosetron 시장 수량'!S43 | F22: =IFERROR(E22/C22,"") | G22: =IFERROR(E22/E21-1,"") | H22: ='근거_NSA수량(IQVIA기준)'!K27 | I22: =IFERROR(H22/E22,"") | J22: =IFERROR(H22/H21-1,"")
A23: =근거_전신마취환자수!T16 | B23: 2028 | C23: =근거_전신마취환자수!T40 | D23: =IFERROR(C23/A23,"") | E23: ='근거_Ramosetron 시장 수량'!T43 | F23: =IFERROR(E23/C23,"") | G23: =IFERROR(E23/E22-1,"") | H23: ='근거_NSA수량(IQVIA기준)'!L27 | I23: =IFERROR(H23/E23,"") | J23: =IFERROR(H23/H22-1,"")
A24: =근거_전신마취환자수!U16 | B24: 2029 | C24: =근거_전신마취환자수!U40 | D24: =IFERROR(C24/A24,"") | E24: ='근거_Ramosetron 시장 수량'!U43 | F24: =IFERROR(E24/C24,"") | G24: =IFERROR(E24/E23-1,"") | H24: ='근거_NSA수량(IQVIA기준)'!M27 | I24: =IFERROR(H24/E24,"") | J24: =IFERROR(H24/H23-1,"")
A25: =근거_전신마취환자수!V16 | B25: 2030 | C25: =근거_전신마취환자수!V40 | D25: =IFERROR(C25/A25,"") | E25: ='근거_Ramosetron 시장 수량'!V43 | F25: =IFERROR(E25/C25,"") | G25: =IFERROR(E25/E24-1,"") | H25: ='근거_NSA수량(IQVIA기준)'!N27 | I25: =IFERROR(H25/E25,"") | J25: =IFERROR(H25/H24-1,"")
B27: Part 2) NSA SAP매출 예측 [FY 기준 · 회계연도 4~3월] | K27: 확정FY(ACT) ▶
B28: 연도 | C28: NSA 수량 (IQVIA 기준) | E28: DSKR NSA SAP 매출 | G28: IQVIA vs.시장매출 | H28: DSKR NSA SAP매출금액 (FY2026 목표단가 반영) | K28: 2025 | N28: 탑다운 검증 (참고, 억원)
B29: 회계연도기준 | C29: 수량(A) | D29: YoY | E29: 수량(A) | F29: YoY | G29: 처방량÷시장매출 | H29: 백만원 | K29: ◀ 매년 실적확정 시 이 값을 +1 (예: FY2026 확정되면 2026). 표지 태그·EST/ACT 플래그가 자동 갱신. | L29: 상태 | N29: 억원(탑다운) | O29: ◀ 원본_NSA_연간예측(고정비율 k) 탑다운 트랙 — FY2026만 독립 대조
B30: FY2018 | E30: =IF(근거_매출!B10="","",근거_매출!B10) | G30: =IFERROR(C30/E30,"") | H30: =IF(근거_매출!B32="","",근거_매출!B32) | I30: =IFERROR(H30/E30,"") | L30: =IF(VALUE(MID(B30,3,4))<=$K$28,"ACT","EST")
B31: FY2019 | D31: =IFERROR(C31/C30-1,"") | E31: =IF(근거_매출!C10="","",근거_매출!C10) | F31: =IFERROR(E31/E30-1,"") | G31: =IFERROR(C31/E31,"") | H31: =IF(근거_매출!C32="","",근거_매출!C32) | I31: =IFERROR(H31/E31,"") | L31: =IF(VALUE(MID(B31,3,4))<=$K$28,"ACT","EST")
B32: FY2020 | C32: ='근거_NSA수량(IQVIA기준)'!D27 | D32: =IFERROR(C32/C31-1,"") | E32: =IF(근거_매출!D10="","",근거_매출!D10) | F32: =IFERROR(E32/E31-1,"") | G32: =IFERROR(C32/E32,"") | H32: =IF(근거_매출!D32="","",근거_매출!D32) | I32: =IFERROR(H32/E32,"") | L32: =IF(VALUE(MID(B32,3,4))<=$K$28,"ACT","EST")
B33: FY2021 | C33: ='근거_NSA수량(IQVIA기준)'!E27 | D33: =IFERROR(C33/C32-1,"") | E33: =IF(근거_매출!E10="","",근거_매출!E10) | F33: =IFERROR(E33/E32-1,"") | G33: =IFERROR(C33/E33,"") | H33: =IF(근거_매출!E32="","",근거_매출!E32) | I33: =IFERROR(H33/E33,"") | L33: =IF(VALUE(MID(B33,3,4))<=$K$28,"ACT","EST")
B34: FY2022 | C34: ='근거_NSA수량(IQVIA기준)'!F27 | D34: =IFERROR(C34/C33-1,"") | E34: =IF(근거_매출!F10="","",근거_매출!F10) | F34: =IFERROR(E34/E33-1,"") | G34: =IFERROR(C34/E34,"") | H34: =IF(근거_매출!F32="","",근거_매출!F32) | I34: =IFERROR(H34/E34,"") | L34: =IF(VALUE(MID(B34,3,4))<=$K$28,"ACT","EST")
B35: FY2023 | C35: ='근거_NSA수량(IQVIA기준)'!G27 | D35: =IFERROR(C35/C34-1,"") | E35: =IF(근거_매출!G10="","",근거_매출!G10) | F35: =IFERROR(E35/E34-1,"") | G35: =IFERROR(C35/E35,"") | H35: =IF(근거_매출!G32="","",근거_매출!G32) | I35: =IFERROR(H35/E35,"") | L35: =IF(VALUE(MID(B35,3,4))<=$K$28,"ACT","EST")
B36: FY2024 | C36: ='근거_NSA수량(IQVIA기준)'!H27 | D36: =IFERROR(C36/C35-1,"") | E36: =IF(근거_매출!H10="","",근거_매출!H10) | F36: =IFERROR(E36/E35-1,"") | G36: =IFERROR(C36/E36,"") | H36: =IF(근거_매출!H32="","",근거_매출!H32) | I36: =IFERROR(H36/E36,"") | L36: =IF(VALUE(MID(B36,3,4))<=$K$28,"ACT","EST")
B37: FY2025 | C37: ='근거_NSA수량(IQVIA기준)'!I27 | D37: =IFERROR(C37/C36-1,"") | E37: =IF(근거_매출!I10="","",근거_매출!I10) | F37: =IFERROR(E37/E36-1,"") | G37: =IFERROR(C37/E37,"") | H37: =IF(근거_매출!I32="","",근거_매출!I32) | I37: =IFERROR(H37/E37,"") | L37: =IF(VALUE(MID(B37,3,4))<=$K$28,"ACT","EST")
B38: FY2026 | C38: ='근거_NSA수량(IQVIA기준)'!J27 | D38: =IFERROR(C38/C37-1,"") | E38: =근거_매출!J10 | F38: =IFERROR(E38/E37-1,"") | G38: =IFERROR(C38/E38,"") | H38: =E38*I38 | I38: =근거_매출!J29/1000000 | J38: ◀ 단가(I열)는 근거_매출 연도별 단가행(29행) 참조 — 약가 배율 변경 시 자동 반영 | L38: =IF(VALUE(MID(B38,3,4))<=$K$28,"ACT","EST") | N38: =원본_NSA_연간예측!B25*근거_매출!J29/1000000/100 | O38: =IFERROR(N38/(H38/100)-1,"")
B39: FY2027 | C39: ='근거_NSA수량(IQVIA기준)'!K27 | D39: =IFERROR(C39/C38-1,"") | E39: =근거_매출!K10 | F39: =IFERROR(E39/E38-1,"") | G39: =IFERROR(C39/E39,"") | H39: =E39*I39 | I39: =근거_매출!K29/1000000 | L39: =IF(VALUE(MID(B39,3,4))<=$K$28,"ACT","EST")
B40: FY2028 | C40: ='근거_NSA수량(IQVIA기준)'!L27 | D40: =IFERROR(C40/C39-1,"") | E40: =근거_매출!L10 | F40: =IFERROR(E40/E39-1,"") | G40: =IFERROR(C40/E40,"") | H40: =E40*I40 | I40: =근거_매출!L29/1000000 | L40: =IF(VALUE(MID(B40,3,4))<=$K$28,"ACT","EST")
B41: FY2029 | C41: ='근거_NSA수량(IQVIA기준)'!M27 | D41: =IFERROR(C41/C40-1,"") | E41: =근거_매출!M10 | F41: =IFERROR(E41/E40-1,"") | G41: =IFERROR(C41/E41,"") | H41: =E41*I41 | I41: =근거_매출!M29/1000000 | L41: =IF(VALUE(MID(B41,3,4))<=$K$28,"ACT","EST")
B42: FY2030 | C42: ='근거_NSA수량(IQVIA기준)'!N27 | D42: =IFERROR(C42/C41-1,"") | E42: =근거_매출!N10 | F42: =IFERROR(E42/E41-1,"") | G42: =IFERROR(C42/E42,"") | H42: =E42*I42 | I42: =근거_매출!N29/1000000 | L42: =IF(VALUE(MID(B42,3,4))<=$K$28,"ACT","EST")

Sheet 원본_NSA_연간예측
A2: NSA SAP매출 연간 예측 모델 — 고정비율 기반 (SAP 수량 = IQVIA ÷ k)
A4: ① 고정비율 파라미터 (FY2020~FY2025, 6개년 평균)
A5: 항목 | B5: 값 | C5: 설명
A6: 고정비율 k (IQVIA/SAP) | B6: =AVERAGE(D14:D19) | C6: FY2020~FY2025 평균 IQVIA/SAP 비율 ← 산출 자동
A7: 예측 공식 | B7: SAP 매출 예측 수량 = FY2026 IQVIA 예측수량 ÷ k
A8: 검증 MAPE | B8: =TEXT(AVERAGE(ABS(G17),ABS(G18),ABS(G19)),"0.00%")&" (FY2023~FY2025 평균 절대오차)"
A10: ② 과거 실적 데이터 (FY2020~FY2025)
A11: 회계연도 | B11: IQVIA 수량 (A) | C11: SAP 매출수량 (A) | D11: IQVIA/SAP 비율 | E11: 평균 대비 | F11: 고정비율 예측 SAP | G11: 예측 오차 | H11: 비고
A12: FY2018 | B12: =근거_매출!B7 | C12: =근거_매출!B10 | D12: =IFERROR(B12/C12,"") | E12: =IFERROR(D12-$B$6,"") | F12: =IFERROR(B12/$B$6,"") | G12: =IFERROR(F12/C12-1,"")
A13: FY2019 | B13: =근거_매출!C7 | C13: =근거_매출!C10 | D13: =IFERROR(B13/C13,"") | E13: =IFERROR(D13-$B$6,"") | F13: =IFERROR(B13/$B$6,"") | G13: =IFERROR(F13/C13-1,"")
A14: FY2020 | B14: =근거_매출!D7 | C14: =근거_매출!D10 | D14: =IFERROR(B14/C14,"") | E14: =IFERROR(D14-$B$6,"") | F14: =IFERROR(B14/$B$6,"") | G14: =IFERROR(F14/C14-1,"")
A15: FY2021 | B15: =근거_매출!E7 | C15: =근거_매출!E10 | D15: =IFERROR(B15/C15,"") | E15: =IFERROR(D15-$B$6,"") | F15: =IFERROR(B15/$B$6,"") | G15: =IFERROR(F15/C15-1,"")
A16: FY2022 | B16: =근거_매출!F7 | C16: =근거_매출!F10 | D16: =IFERROR(B16/C16,"") | E16: =IFERROR(D16-$B$6,"") | F16: =IFERROR(B16/$B$6,"") | G16: =IFERROR(F16/C16-1,"") | H16: FY2022 비율 1.14 (SAP 대비 IQVIA 과대) — 재고 조정 영향 추정
A17: FY2023 | B17: =근거_매출!G7 | C17: =근거_매출!G10 | D17: =IFERROR(B17/C17,"") | E17: =IFERROR(D17-$B$6,"") | F17: =IFERROR(B17/$B$6,"") | G17: =IFERROR(F17/C17-1,"")
A18: FY2024 | B18: =근거_매출!H7 | C18: =근거_매출!H10 | D18: =IFERROR(B18/C18,"") | E18: =IFERROR(D18-$B$6,"") | F18: =IFERROR(B18/$B$6,"") | G18: =IFERROR(F18/C18-1,"")
A19: FY2025 | B19: =근거_매출!I7 | C19: =근거_매출!I10 | D19: =IFERROR(B19/C19,"") | E19: =IFERROR(D19-$B$6,"") | F19: =IFERROR(B19/$B$6,"") | G19: =IFERROR(F19/C19-1,"")
A20: 평균 | D20: =AVERAGE(D14:D19) | G20: =AVERAGE(G14:G19)
A22: ③ FY2026 연간 예측 — 유일한 수동 입력: IQVIA 예측 수량
A23: FY2026 IQVIA 예측수량 (A) | B23: ='근거_NSA수량(IQVIA기준)'!J27 | C23: ← 유일한 수동 입력 (현재 바텀업 모델 FY2026 수량 연동; 독립 대조 시 값으로 덮어쓰기)
A24: 고정비율 k | B24: =B6
A25: ★ FY2026 연간 예측 (A) | B25: =B23/B24
A26: 예측 성장률 (YoY) | B26: =B25/C19-1
A28: ④ 민감도 분석 — IQVIA 예측수량 시나리오별
A29: IQVIA 예측 (A) | B29: IQVIA YoY | C29: 예측 SAP 수량 (A) | D29: SAP YoY | E29: FY2025 대비 증감 | F29: 비고
A30: 2000000 | B30: =A30/B19-1 | C30: =A30/$B$6 | D30: =C30/C19-1 | E30: =C30-C19 | F30: ="보수: IQVIA "&TEXT(B30,"+0.0%;-0.0%")
A31: 2100000 | B31: =A31/B19-1 | C31: =A31/$B$6 | D31: =C31/C19-1 | E31: =C31-C19 | F31: ="보수: IQVIA "&TEXT(B31,"+0.0%;-0.0%")
A32: 2200000 | B32: =A32/B19-1 | C32: =A32/$B$6 | D32: =C32/C19-1 | E32: =C32-C19 | F32: 기준−
A33: =B23 | B33: =A33/B19-1 | C33: =A33/$B$6 | D33: =C33/C19-1 | E33: =C33-C19 | F33: ← 연초 입력값
A34: 2450000 | B34: =A34/B19-1 | C34: =A34/$B$6 | D34: =C34/C19-1 | E34: =C34-C19 | F34: 기준+
A35: 2600000 | B35: =A35/B19-1 | C35: =A35/$B$6 | D35: =C35/C19-1 | E35: =C35-C19 | F35: ="낙관: IQVIA "&TEXT(B35,"+0.0%;-0.0%")
A36: 2800000 | B36: =A36/B19-1 | C36: =A36/$B$6 | D36: =C36/C19-1 | E36: =C36-C19 | F36: ="낙관: IQVIA "&TEXT(B36,"+0.0%;-0.0%")
A38: ⑤ 모니터링 기준
A39: 고정비율 k 업데이트 | B39: 매 FY 종료 후 → 실적 추가하여 평균 재산출
A40: 비율 이상치 기준 | B40: IQVIA/SAP 비율이 k ± 0.05 초과 시 → 원인 파악 필요 (재고·입찰 시점)
A41: 검증 MAPE | B41: FY2023~FY2025 기준 평균 절대오차 (B8 참조)
A42: Rolling 갱신 | B42: 분기 실적 확정 시 원자료_분기실측 갱신 → 자동 재계산
A44: [ 범례 ] 파란 글씨/노랑: 수동 입력 │ 검정: 자동 계산 │ 초록: 예측 결과

Sheet 모니터링_분기별
A2: 모니터링_분기별 — 종별 NSA MS 이탈 감시
A3: 예측을 갱신하는 시트가 아닙니다. 분기 실측(원자료_분기실측)이 모델 예측(근거_NSA수량 43~46행)에서 벗어났는지 판정합니다. 경보가 뜰 때만 예측 가정을 손댑니다
A5: ■ 파라미터
A6: 상급종합 임계 (MAPE, %p) | B6: 0.029 | C6: 백테스트 MAPE 2.92%
A7: 종합병원 임계 | B7: 0.038 | C7: 백테스트 MAPE 3.83%
A8: 병원 임계 | B8: 0.089 | C8: 백테스트 MAPE 8.89%
A9: 의원 임계 | B9: 0.103 | C9: 백테스트 MAPE 10.30%
A10: 경보 임계 (배수) | B10: 1.5 | C10: 이탈률이 MAPE × 배수를 넘고
A11: 경보 연속 분기 | B11: 2 | C11: 연속 이 분기 이상이면 경보
A13: ■ 분기 감시표 (실측 열이 채워진 분기만 판정 · 원자료_분기실측 갱신 시 자동)
A14: CY분기 | B14: Ramo 시장 실측 | C14: NSA 실측 | D14: 전체 MS 실측 | E14: 전체 MS 모델 | F14: 이탈 | G14: 상급 MS 실측 | H14: 상급 모델 | I14: 이탈률 | J14: 신호 | K14: 종합 MS 실측 | L14: 종합 모델 | M14: 이탈률 | N14: 신호 | O14: 병원 MS 실측 | P14: 병원 모델 | Q14: 이탈률
