Workbook
Name 표시연도: 'FCST RESULT'!$P$4

Sheet 표지

Sheet FCST RESULT
B3: SVK HCT SALES FORECAST
P4: 2026
B6: 1. 매출수량 (백만 T)
B21: 구분 | C21: FY2026 | D21: FY2027 | E21: FY2028 | F21: FY2029 | G21: FY2030
B22: Model Base | C22: =근거_매출!J10/1000000 | D22: =근거_매출!K10/1000000 | E22: =근거_매출!L10/1000000 | F22: =근거_매출!M10/1000000 | G22: =근거_매출!N10/1000000
B23: MKT Base | C23: =IF(근거_매출!$J$12="",NA(),근거_매출!J12/1000000) | D23: =IF(근거_매출!$J$12="",NA(),근거_매출!K12/1000000) | E23: =IF(근거_매출!$J$12="",NA(),근거_매출!L12/1000000) | F23: =IF(근거_매출!$J$12="",NA(),근거_매출!M12/1000000) | G23: =IF(근거_매출!$J$12="",NA(),근거_매출!N12/1000000)
B24: Best (침투 -10%p) | C24: =근거_매출!J14/1000000 | D24: =근거_매출!K14/1000000 | E24: =근거_매출!L14/1000000 | F24: =근거_매출!M14/1000000 | G24: =근거_매출!N14/1000000
B25: Worst (침투 +10%p) | C25: =근거_매출!J16/1000000 | D25: =근거_매출!K16/1000000 | E25: =근거_매출!L16/1000000 | F25: =근거_매출!M16/1000000 | G25: =근거_매출!N16/1000000
B26: Best (침투 -5%p) | C26: =근거_매출!J18/1000000 | D26: =근거_매출!K18/1000000 | E26: =근거_매출!L18/1000000 | F26: =근거_매출!M18/1000000 | G26: =근거_매출!N18/1000000
B27: Worst (침투 +5%p) | C27: =근거_매출!J20/1000000 | D27: =근거_매출!K20/1000000 | E27: =근거_매출!L20/1000000 | F27: =근거_매출!M20/1000000 | G27: =근거_매출!N20/1000000
B29: 2. 매출액 (백만원)
B44: 구분 | C44: FY2026 | D44: FY2027 | E44: FY2028 | F44: FY2029 | G44: FY2030
B45: Model Base | C45: =근거_매출!J32 | D45: =근거_매출!K32 | E45: =근거_매출!L32 | F45: =근거_매출!M32 | G45: =근거_매출!N32
B46: MKT Base | C46: =IF(근거_매출!$J$12="",NA(),근거_매출!J34) | D46: =IF(근거_매출!$J$12="",NA(),근거_매출!K34) | E46: =IF(근거_매출!$J$12="",NA(),근거_매출!L34) | F46: =IF(근거_매출!$J$12="",NA(),근거_매출!M34) | G46: =IF(근거_매출!$J$12="",NA(),근거_매출!N34)
B47: Best (침투 -10%p) | C47: =근거_매출!J35 | D47: =근거_매출!K35 | E47: =근거_매출!L35 | F47: =근거_매출!M35 | G47: =근거_매출!N35
B48: Worst (침투 +10%p) | C48: =근거_매출!J36 | D48: =근거_매출!K36 | E48: =근거_매출!L36 | F48: =근거_매출!M36 | G48: =근거_매출!N36
B49: Best (침투 -5%p) | C49: =근거_매출!J37 | D49: =근거_매출!K37 | E49: =근거_매출!L37 | F49: =근거_매출!M37 | G49: =근거_매출!N37
B50: Worst (침투 +5%p) | C50: =근거_매출!J38 | D50: =근거_매출!K38 | E50: =근거_매출!L38 | F50: =근거_매출!M38 | G50: =근거_매출!N38

Sheet 변동요인분석
A2: SVK HCT FCST 변동 요인 분석과 시뮬레이션
A4: ① 변동 요인 분석
A5: - 핵심 변동 요인 : 제네릭 침투(성분 내 Original 비율) (매출 변동성 ±21.2%로, 타 요인 대비 압도적인 영향력을 행사함)
A6: - 기타 변동 요인: Olmesartan MS 하한(±8.7%), ARB+CCB+DU 비율 상한 L(±8.5%), 의료이용비율(±5.5%) 등 (구조 파라미터 성격, 실측 갱신 시 자동 재추정)
A7: - 예외 요인: 약가 인하 고시(현재 없음) 및 MKT 제출 수치와의 차이는 본 시뮬레이션 외 별도 리스크로 분류 · 환자 체인(L1~L4)은 VPP 역산 구조로 방향이 직관과 반대일 수 있어 해석 주의
A25: ② 시뮬레이션 : 제네릭 침투 방어의 재무적 가치
A26: - Best (침투 방어): 성분 내 Original 비율 +10%p 방어 시 → FY2030 매출 382억 (상단) · +5%p 시 349억
A27: - Worst (침투 확대): 성분 내 Original 비율 -10%p 잠식 시 → FY2030 매출 249억 (하단) · -5%p 시 282억
A28: (※ 기준선 Base: 315억 · 세일즈 포캐스트 밴드는 FY2027부터 적용)
A47: · 근거: 근거_민감도 참조

Sheet FCST FLOW
A2: SVK HCT Sales FCST FLOW
J3: 각 행의 [▶ 근거] 를 클릭하면 해당 백데이터 시트로 이동 (기준수치·예측수치는 백데이터 참조)
A5: 단계 | B5: 항목 | C5: 기준 수치 | D5: 모델 방법 | E5: FY2026E | F5: FY2027 | G5: FY2028 | H5: FY2029 | I5: FY2030 | J5: 근거
A6: ① 환자 현황 | B6: 고혈압 유병환자수 | C6: =CALC!C19 | D6: · 추계인구(통계청 중위) × 연령별 유병률 복합예측 | E6: =INDEX(CALC!$C$5:$C$25,MATCH(표시연도,CALC!$B$5:$B$25,0)) | F6: =INDEX(CALC!$C$5:$C$25,MATCH(2027,CALC!$B$5:$B$25,0)) | G6: =INDEX(CALC!$C$5:$C$25,MATCH(2028,CALC!$B$5:$B$25,0)) | H6: =INDEX(CALC!$C$5:$C$25,MATCH(2029,CALC!$B$5:$B$25,0)) | I6: =INDEX(CALC!$C$5:$C$25,MATCH(2030,CALC!$B$5:$B$25,0)) | J6: ▶ 근거
B7: 고혈압 의료이용환자수 | C7: =CALC!E19 | D7: · 고혈압 유병환자수 × 의료이용비율 (직전 4개년 평균비율) | E7: =INDEX(CALC!$E$5:$E$25,MATCH(표시연도,CALC!$B$5:$B$25,0)) | F7: =INDEX(CALC!$E$5:$E$25,MATCH(2027,CALC!$B$5:$B$25,0)) | G7: =INDEX(CALC!$E$5:$E$25,MATCH(2028,CALC!$B$5:$B$25,0)) | H7: =INDEX(CALC!$E$5:$E$25,MATCH(2029,CALC!$B$5:$B$25,0)) | I7: =INDEX(CALC!$E$5:$E$25,MATCH(2030,CALC!$B$5:$B$25,0)) | J7: ▶ 근거
B8: 고혈압 치료환자수 | C8: =CALC!G18 | D8: · 고혈압 의료이용환자수 × 치료비율 (2014~23 선형회귀) | E8: =INDEX(CALC!$G$5:$G$25,MATCH(표시연도,CALC!$B$5:$B$25,0)) | F8: =INDEX(CALC!$G$5:$G$25,MATCH(2027,CALC!$B$5:$B$25,0)) | G8: =INDEX(CALC!$G$5:$G$25,MATCH(2028,CALC!$B$5:$B$25,0)) | H8: =INDEX(CALC!$G$5:$G$25,MATCH(2029,CALC!$B$5:$B$25,0)) | I8: =INDEX(CALC!$G$5:$G$25,MATCH(2030,CALC!$B$5:$B$25,0)) | J8: ▶ 근거
B9: ARB 처방 환자수 | C9: =CALC!I18 | D9: · 고혈압 치료환자수 × ARB 처방률 (로지스틱 S-curve) | E9: =INDEX(CALC!$I$5:$I$25,MATCH(표시연도,CALC!$B$5:$B$25,0)) | F9: =INDEX(CALC!$I$5:$I$25,MATCH(2027,CALC!$B$5:$B$25,0)) | G9: =INDEX(CALC!$I$5:$I$25,MATCH(2028,CALC!$B$5:$B$25,0)) | H9: =INDEX(CALC!$I$5:$I$25,MATCH(2029,CALC!$B$5:$B$25,0)) | I9: =INDEX(CALC!$I$5:$I$25,MATCH(2030,CALC!$B$5:$B$25,0)) | J9: ▶ 근거
A10: ② 시장 구조 | B10: 환자당 처방량(VPP) | C10: =INDEX(CALC!$L$5:$L$25,MATCH(표시연도-1,CALC!$B$5:$B$25,0)) | D10: · FY2026 : 월별 롤링(실측 YTD × 가중 성장률) ÷ 환자수 / FY2027~ : 최근 3개년 증가 일수 평균 반영, 28년부터 고정 | E10: =INDEX(CALC!$L$5:$L$25,MATCH(표시연도,CALC!$B$5:$B$25,0)) | F10: =INDEX(CALC!$L$5:$L$25,MATCH(2027,CALC!$B$5:$B$25,0)) | G10: =INDEX(CALC!$L$5:$L$25,MATCH(2028,CALC!$B$5:$B$25,0)) | H10: =INDEX(CALC!$L$5:$L$25,MATCH(2029,CALC!$B$5:$B$25,0)) | I10: =INDEX(CALC!$L$5:$L$25,MATCH(2030,CALC!$B$5:$B$25,0)) | J10: ▶ 근거
B11: ARB 처방량 | C11: =INDEX(CALC!$M$5:$M$25,MATCH(표시연도-1,CALC!$B$5:$B$25,0)) | D11: · ARB 처방환자수 × VPP | E11: =INDEX(CALC!$M$5:$M$25,MATCH(표시연도,CALC!$B$5:$B$25,0)) | F11: =INDEX(CALC!$M$5:$M$25,MATCH(2027,CALC!$B$5:$B$25,0)) | G11: =INDEX(CALC!$M$5:$M$25,MATCH(2028,CALC!$B$5:$B$25,0)) | H11: =INDEX(CALC!$M$5:$M$25,MATCH(2029,CALC!$B$5:$B$25,0)) | I11: =INDEX(CALC!$M$5:$M$25,MATCH(2030,CALC!$B$5:$B$25,0)) | J11: ▶ 근거
B12: ARB+CCB+DU 복합제 처방량(시장 전체) | C12: =INDEX(CALC!$O$5:$O$25,MATCH(표시연도-1,CALC!$B$5:$B$25,0)) | D12: · ARB 처방량 × ARB 복합제 비율(하한형 S-curve) × ARB+CCB+DU 비율(상한형 S-curve) | E12: =INDEX(CALC!$O$5:$O$25,MATCH(표시연도,CALC!$B$5:$B$25,0)) | F12: =INDEX(CALC!$O$5:$O$25,MATCH(2027,CALC!$B$5:$B$25,0)) | G12: =INDEX(CALC!$O$5:$O$25,MATCH(2028,CALC!$B$5:$B$25,0)) | H12: =INDEX(CALC!$O$5:$O$25,MATCH(2029,CALC!$B$5:$B$25,0)) | I12: =INDEX(CALC!$O$5:$O$25,MATCH(2030,CALC!$B$5:$B$25,0)) | J12: ▶ 근거
B13: ARB+CCB+DU 복합제 처방량(HP) | C13: =INDEX(CALC!$Q$5:$Q$25,MATCH(표시연도-1,CALC!$B$5:$B$25,0)) | D13: · ARB+CCB+DU복합제 처방량 x HP:GP 비율 (로지스틱, 하한고정 22.0%, FY2024Q3 이후 분기회귀) | E13: =INDEX(CALC!$Q$5:$Q$25,MATCH(표시연도,CALC!$B$5:$B$25,0)) | F13: =INDEX(CALC!$Q$5:$Q$25,MATCH(2027,CALC!$B$5:$B$25,0)) | G13: =INDEX(CALC!$Q$5:$Q$25,MATCH(2028,CALC!$B$5:$B$25,0)) | H13: =INDEX(CALC!$Q$5:$Q$25,MATCH(2029,CALC!$B$5:$B$25,0)) | I13: =INDEX(CALC!$Q$5:$Q$25,MATCH(2030,CALC!$B$5:$B$25,0)) | J13: ▶ 근거
B14: ARB+CCB+DU 복합제 처방량(GP) | C14: =INDEX(CALC!$S$5:$S$25,MATCH(표시연도-1,CALC!$B$5:$B$25,0)) | D14: · ARB+CCB+DU복합제 처방량 x HP:GP 비율 (로지스틱, 하한고정 22.0%, FY2024Q3 이후 분기회귀) | E14: =INDEX(CALC!$S$5:$S$25,MATCH(표시연도,CALC!$B$5:$B$25,0)) | F14: =INDEX(CALC!$S$5:$S$25,MATCH(2027,CALC!$B$5:$B$25,0)) | G14: =INDEX(CALC!$S$5:$S$25,MATCH(2028,CALC!$B$5:$B$25,0)) | H14: =INDEX(CALC!$S$5:$S$25,MATCH(2029,CALC!$B$5:$B$25,0)) | I14: =INDEX(CALC!$S$5:$S$25,MATCH(2030,CALC!$B$5:$B$25,0)) | J14: ▶ 근거
A15: ③ 경쟁 현황 | B15: (HP 내) SVK HCT MS | C15: =INDEX(CALC!$V$5:$V$25,MATCH(표시연도-1,CALC!$B$5:$B$25,0)) | D15: · Olmesartan 비율=하한고정(로지스틱, 하한 47.0%), 성분 내 Original비율=직접 선형회귀 → 상세: 근거_SVK HCT처방량 시트 하단, 근거_제네릭벤치마크 시트 | E15: =INDEX(CALC!$V$5:$V$25,MATCH(표시연도,CALC!$B$5:$B$25,0)) | F15: =INDEX(CALC!$V$5:$V$25,MATCH(2027,CALC!$B$5:$B$25,0)) | G15: =INDEX(CALC!$V$5:$V$25,MATCH(2028,CALC!$B$5:$B$25,0)) | H15: =INDEX(CALC!$V$5:$V$25,MATCH(2029,CALC!$B$5:$B$25,0)) | I15: =INDEX(CALC!$V$5:$V$25,MATCH(2030,CALC!$B$5:$B$25,0)) | J15: ▶ 근거
B16: (GP 내) SVK HCT MS | C16: =INDEX(CALC!$Y$5:$Y$25,MATCH(표시연도-1,CALC!$B$5:$B$25,0)) | D16: · Olmesartan 비율=하한고정(로지스틱, 하한 37.9%), 최근5분기 자동연동 / 성분 내 Original비율=로짓 변환 회귀 | E16: =INDEX(CALC!$Y$5:$Y$25,MATCH(표시연도,CALC!$B$5:$B$25,0)) | F16: =INDEX(CALC!$Y$5:$Y$25,MATCH(2027,CALC!$B$5:$B$25,0)) | G16: =INDEX(CALC!$Y$5:$Y$25,MATCH(2028,CALC!$B$5:$B$25,0)) | H16: =INDEX(CALC!$Y$5:$Y$25,MATCH(2029,CALC!$B$5:$B$25,0)) | I16: =INDEX(CALC!$Y$5:$Y$25,MATCH(2030,CALC!$B$5:$B$25,0)) | J16: ▶ 근거
A17: ④ 시장매출 | B17: DSKR 매출수량 (T) | C17: =INDEX(근거_매출!$B$10:$N$10,표시연도-1-2017) | D17: · SVK HCT 처방량(UBIST, 정) ÷ 전환비율(FY22~25 평균 0.987) → 판매 수량 환산 | E17: =INDEX(근거_매출!$B$10:$N$10,표시연도-2017) | F17: =INDEX(근거_매출!$B$10:$N$10,2027-2017) | G17: =INDEX(근거_매출!$B$10:$N$10,2028-2017) | H17: =INDEX(근거_매출!$B$10:$N$10,2029-2017) | I17: =INDEX(근거_매출!$B$10:$N$10,2030-2017) | J17: ▶ 근거
B18: 연도별 단가 (원/T) | C18: =근거_매출!B27 | D18: · 기준단가 615.6원(FY26 목표단가 채널·용량 물량가중) × 약가 배율 (인하 고시 없음 → 100% 유지, 근거_매출 24행에서 조정) | E18: =INDEX(근거_매출!$B$29:$N$29,표시연도-2017) | F18: =INDEX(근거_매출!$B$29:$N$29,2027-2017) | G18: =INDEX(근거_매출!$B$29:$N$29,2028-2017) | H18: =INDEX(근거_매출!$B$29:$N$29,2029-2017) | I18: =INDEX(근거_매출!$B$29:$N$29,2030-2017) | J18: ▶ 근거
A20: ▶ 결과 | B20: ARB+CCB+DU 복합제 시장 (처방량) | C20: =INDEX(CALC!$O$5:$O$25,MATCH(표시연도-1,CALC!$B$5:$B$25,0)) | D20: ARB 처방량 × ARB 복합제 비율 × ARB+CCB+DU 비율 | E20: =INDEX(CALC!$O$5:$O$25,MATCH(표시연도,CALC!$B$5:$B$25,0)) | F20: =INDEX(CALC!$O$5:$O$25,MATCH(2027,CALC!$B$5:$B$25,0)) | G20: =INDEX(CALC!$O$5:$O$25,MATCH(2028,CALC!$B$5:$B$25,0)) | H20: =INDEX(CALC!$O$5:$O$25,MATCH(2029,CALC!$B$5:$B$25,0)) | I20: =INDEX(CALC!$O$5:$O$25,MATCH(2030,CALC!$B$5:$B$25,0)) | J20: ▶ 근거
B21: SVK HCT 처방 (UBIST) | C21: =INDEX(CALC!$AA$5:$AA$25,MATCH(표시연도-1,CALC!$B$5:$B$25,0)) | D21: ARB+CCB+DU 복합제 시장 × SVK HCT MS(성분별×성분내) | E21: =INDEX(CALC!$AA$5:$AA$25,MATCH(표시연도,CALC!$B$5:$B$25,0)) | F21: =INDEX(CALC!$AA$5:$AA$25,MATCH(2027,CALC!$B$5:$B$25,0)) | G21: =INDEX(CALC!$AA$5:$AA$25,MATCH(2028,CALC!$B$5:$B$25,0)) | H21: =INDEX(CALC!$AA$5:$AA$25,MATCH(2029,CALC!$B$5:$B$25,0)) | I21: =INDEX(CALC!$AA$5:$AA$25,MATCH(2030,CALC!$B$5:$B$25,0)) | J21: ▶ 근거
B22: SVK HCT 시장매출 (백만원) | C22: =INDEX(근거_매출!$B$32:$N$32,표시연도-1-2017) | D22: DSKR 매출수량 × 연도별 단가 | E22: =INDEX(근거_매출!$B$32:$N$32,표시연도-2017) | F22: =INDEX(근거_매출!$B$32:$N$32,2027-2017) | G22: =INDEX(근거_매출!$B$32:$N$32,2028-2017) | H22: =INDEX(근거_매출!$B$32:$N$32,2029-2017) | I22: =INDEX(근거_매출!$B$32:$N$32,2030-2017) | J22: ▶ 근거
H23: ="※ 시나리오 밴드(FY2030): "&TEXT(근거_매출!N36,"#,##0")&" ~ "&TEXT(근거_매출!N35,"#,##0")&" (침투 ±10%p) · "&TEXT(근거_매출!N38,"#,##0")&" ~ "&TEXT(근거_매출!N37,"#,##0")&" (±5%p) →" | I23: =HYPERLINK("#'FCST RESULT'!A1","상세: FCST RESULT ▶")
B25: ※ 기준 수치 - 출처 및 기준연도
B26: ① 환자 현황
B27: 1)고혈압 유병환자수: 국민건강영양조사 데이터, CY2024
B28: 2)고혈압 의료이용 환자수: HIRA 고혈압(ICD-10: I10) 주부상병, CY2024
B29: 3)고혈압 치료·ARB처방환자수: 건보공단 전수 데이터, CY2023
B30: ② 시장 구조(VPP·ARB 처방량·복합제 처방량): UBIST, FY2025
B31: ③ 경쟁 현황(성분별·성분 내 MS): UBIST, FY2025
B32: ④ 시장매출(수량·단가): 내부 시장매출 실측 FY2025 / 단가: FY2026 목표단가 (채널·용량별 물량가중)
B35: ■ 부록 — 백테스트 (rolling-origin 홀드아웃, 2026-09-14 수행)
B36: 시점(실측 월수) | C36: 그 시점의 FY2026E | D36: 최종(5개월) 대비 | E36: 판정
B37: 4월 마감 (1개월) | C37: 34685 | D37: -0.018697817 | E37: 정상
B38: 5월 마감 (2개월) | C38: 34272 | D38: -0.030373958 | E38: 가중치 전환 구간 — 참고용
B39: 6월 마감 (3개월) | C39: 34889 | D39: -0.012938624 | E39: 정상 — 이 시점부터 리비전 논의 유효
B40: 7월 마감 (4개월) | C40: 35170 | D40: -0.0049724934 | E40: 정상
B41: 8월 마감 (5개월) | C41: 35346 | D41: 기준 | E41: 현재
B42: · 방법: FY2026 실측 월(ARB 시장 Total, 원본_월별 ■A)을 시점별로 제한해 각 시점의 연간 추정을 재현(사본 시뮬레이션). 5개 시점 최대 오차 3.0%, 실측 3개월부터 ±1% 이내 수렴. 복합제·MS 측은 FY26Q1 분기 실측 고정이므로 월별 롤링은 ARB 시장 성장률에만 작용.
B43: · 결론: 월별 롤링 엔진 이상 없음 (검증 범위: FY2026 ARB 시장 실측 5개월 구간, 2026-04~08)

Sheet 근거_유병환자수
A1: 고혈압 유병환자수 산출 : KNHANES 기반 추정
B3: ◀ 실측 (국민건강영양조사, 2010~2024) | Q3: 예측 (회귀, 2025~2030) ▶
A4: 구분 / 연도 ▶ | B4: 2010 | C4: 2011 | D4: 2012 | E4: 2013 | F4: 2014 | G4: 2015 | H4: 2016 | I4: 2017 | J4: 2018 | K4: 2019 | L4: 2020 | M4: 2021 | N4: 2022 | O4: 2023 | P4: 2024 | Q4: 2025 | R4: 2026 | S4: 2027 | T4: 2028 | U4: 2029 | V4: 2030
A5: ■ A. 인구 (명) [통계청 장래인구추계, 중위]
A6: 20-29세 | B6: 6973154 | C6: 6840475 | D6: 6733813 | E6: 6686161 | F6: 6716535 | G6: 6781422 | H6: 6839660 | I6: 6897818 | J6: 6991259 | K6: 7026828 | L6: 7037893 | M6: 6953529 | N6: 6734021 | O6: 6548381 | P6: 6372432 | Q6: 6136764 | R6: 5887622 | S6: 5678166 | T6: 5510243 | U6: 5341561 | V6: 5157518
A7: 30-39세 | B7: 8264820 | C7: 8208754 | D7: 8146381 | E7: 8035971 | F7: 7899840 | G7: 7763702 | H7: 7652940 | I7: 7545842 | J7: 7456227 | K7: 7358231 | L7: 7174782 | M7: 6989477 | N7: 6872945 | O7: 6874383 | P7: 6913023 | Q7: 6975568 | R7: 7037580 | S7: 7096790 | T7: 7152255 | U7: 7158328 | V7: 7156565
A8: 40-49세 | B8: 8578079 | C8: 8600111 | D8: 8657375 | E8: 8653288 | F8: 8774714 | G8: 8752417 | H8: 8671799 | I8: 8585346 | J8: 8504579 | K8: 8335481 | L8: 8257903 | M8: 8158318 | N8: 8097011 | O8: 7993159 | P8: 7852297 | Q8: 7717016 | R8: 7624180 | S8: 7530657 | T8: 7417118 | U8: 7309393 | V8: 7147423
A9: 50-59세 | B9: 6751678 | C9: 7229163 | D9: 7504944 | E9: 7821975 | F9: 8033801 | G9: 8173256 | H9: 8305212 | I9: 8389739 | J9: 8462781 | K9: 8593283 | L9: 8575336 | M9: 8539374 | N9: 8603509 | O9: 8596363 | P9: 8705899 | Q9: 8660370 | R9: 8586606 | S9: 8508537 | T9: 8417195 | U9: 8247351 | V9: 8195954
A10: 60-69세 | B10: 4090354 | C10: 4149296 | D10: 4252495 | E10: 4358060 | F10: 4546950 | G10: 4856462 | H10: 5204346 | I10: 5456887 | J10: 5745656 | K10: 6076571 | L10: 6476602 | M10: 6959660 | N10: 7211963 | O10: 7532388 | P10: 7720341 | Q10: 7844071 | R10: 7980101 | S10: 8068291 | T10: 8139161 | U10: 8263910 | V10: 8262115
A11: 70세 이상 | B11: 3487795 | C11: 3668843 | D11: 3892038 | E11: 4108151 | F11: 4271397 | G11: 4435537 | H11: 4547079 | I11: 4779541 | J11: 5009497 | K11: 5240372 | L11: 5489635 | M11: 5674954 | N11: 5917283 | O11: 6161633 | P11: 6428985 | Q11: 6825302 | R11: 7187553 | S11: 7574606 | T11: 7991794 | U11: 8433421 | V11: 8943049
A12: 전체 (20세+) | B12: =SUM(B6:B11) | C12: =SUM(C6:C11) | D12: =SUM(D6:D11) | E12: =SUM(E6:E11) | F12: =SUM(F6:F11) | G12: =SUM(G6:G11) | H12: =SUM(H6:H11) | I12: =SUM(I6:I11) | ... V12: =SUM(V6:V11)
A14: ■ B. 연령별 유병률 (%) [2010~24 : 고혈압 유병비율 | 2025~30 : 연령대별 다른 방법으로 예측1]
A15: 20-29세 | B15: 2.5 | C15: 7 | D15: 4.8 | E15: 4.2 | F15: 2.2 | G15: 2.7 | H15: 3.5 | I15: 5.1 | J15: 5.4 | K15: 5.2 | L15: 4.4 | M15: 2.8 | N15: 4.3 | O15: 1.5 | P15: 3.1 | Q15: =$I43 | R15: =$I43 | S15: =$I43 | T15: =$I43 | U15: =$I43 | V15: =$I43
A16: 30-39세 | B16: 7.2 | C16: 9.1 | D16: 9.5 | E16: 9.7 | F16: 7.3 | G16: 8.7 | H16: 10.3 | I16: 11.3 | J16: 11.7 | K16: 9.5 | L16: 11.4 | M16: 10 | N16: 8.7 | O16: 6.2 | P16: 9.1 | Q16: =$I44 | R16: =$I44 | S16: =$I44 | T16: =$I44 | U16: =$I44 | V16: =$I44
A17: 40-49세 | B17: 17 | C17: 21.1 | D17: 22.6 | E17: 19.5 | F17: 17.7 | G17: 20.7 | H17: 21.7 | I17: 19.2 | J17: 20.6 | K17: 19 | L17: 20.8 | M17: 19.7 | N17: 20.1 | O17: 17.2 | P17: 20.4 | Q17: =$I45 | R17: =$I45 | S17: =$I45 | T17: =$I45 | U17: =$I45 | V17: =$I45
A18: 50-59세 | B18: 37.3 | C18: 33.8 | D18: 34.5 | E18: 35.9 | F18: 32 | G18: 33.9 | H18: 36.5 | I18: 32.1 | J18: 34.7 | K18: 32.3 | L18: 35.9 | M18: 31.2 | N18: 33.5 | O18: 33.7 | P18: 34.7 | Q18: =$I46 | R18: =$I46 | S18: =$I46 | T18: =$I46 | U18: =$I46 | V18: =$I46
A19: 60-69세 | B19: 55.6 | C19: 55.4 | D19: 54 | E19: 48.7 | F19: 48.5 | G19: 51.8 | H19: 50.9 | I19: 46.9 | J19: 46 | K19: 51.5 | L19: 48.1 | M19: 48 | N19: 48.9 | O19: 47.3 | P19: 51.4 | Q19: =$C$47*Q$4+$D$47 | R19: =$C$47*R$4+$D$47 | S19: =$C$47*S$4+$D$47 | T19: =$C$47*T$4+$D$47 | U19: =$C$47*U$4+$D$47 | V19: =$C$47*V$4+$D$47
A20: 70세 이상 | B20: 61.2 | C20: 66.6 | D20: 66.4 | E20: 62.3 | F20: 63.5 | G20: 67.5 | H20: 69.2 | I20: 64.7 | J20: 70.2 | K20: 67.2 | L20: 65.3 | M20: 66.4 | N20: 68.7 | O20: 68.4 | P20: 65.2 | Q20: =$I48 | R20: =$I48 | S20: =$I48 | T20: =$I48 | U20: =$I48 | V20: =$I48
A22: ■ C. 고혈압 유병환자수 (명) [2013~30 : 유병률(B) × 인구(A)]
A23: 20-29세 | B23: =B6*B15% | C23: =C6*C15% | D23: =D6*D15% | E23: =E6*E15% | F23: =F6*F15% | G23: =G6*G15% | H23: =H6*H15% | I23: =I6*I15% | ... V23: =V6*V15%
A24: 30-39세 | B24: =B7*B16% | C24: =C7*C16% | D24: =D7*D16% | E24: =E7*E16% | F24: =F7*F16% | G24: =G7*G16% | H24: =H7*H16% | I24: =I7*I16% | ... V24: =V7*V16%
A25: 40-49세 | B25: =B8*B17% | C25: =C8*C17% | D25: =D8*D17% | E25: =E8*E17% | F25: =F8*F17% | G25: =G8*G17% | H25: =H8*H17% | I25: =I8*I17% | ... V25: =V8*V17%
A26: 50-59세 | B26: =B9*B18% | C26: =C9*C18% | D26: =D9*D18% | E26: =E9*E18% | F26: =F9*F18% | G26: =G9*G18% | H26: =H9*H18% | I26: =I9*I18% | ... V26: =V9*V18%
A27: 60-69세 | B27: =B10*B19% | C27: =C10*C19% | D27: =D10*D19% | E27: =E10*E19% | F27: =F10*F19% | G27: =G10*G19% | H27: =H10*H19% | I27: =I10*I19% | ... V27: =V10*V19%
A28: 70세 이상 | B28: =B11*B20% | C28: =C11*C20% | D28: =D11*D20% | E28: =E11*E20% | F28: =F11*F20% | G28: =G11*G20% | H28: =H11*H20% | I28: =I11*I20% | ... V28: =V11*V20%
A29: ▶ 전체 유병환자수 | B29: =SUM(B23:B28) | C29: =SUM(C23:C28) | D29: =SUM(D23:D28) | E29: =SUM(E23:E28) | F29: =SUM(F23:F28) | G29: =SUM(G23:G28) | H29: =SUM(H23:H28) | I29: =SUM(I23:I28) | ... V29: =SUM(V23:V28)
B30: =B29/B12 | C30: =C29/C12 | D30: =D29/D12 | E30: =E29/E12 | F30: =F29/F12 | G30: =G29/G12 | H30: =H29/H12 | I30: =I29/I12 | ... V30: =V29/V12
A32: [참고] 유병환자수 산출 공식
A33: ① 고혈압 유병률1 정의 (KNHANES 정의) : 수축기혈압이 140mmHg 이상이거나 이완기혈압이 90mmHg 이상 또는 고혈압 약물을 복용한 분율
A34: ② 유병환자수(명) : 통계청 장래인구추계 x 해당 연도 고혈압 유병률
A37: [참고] 유병률 예측방식 : 선형회귀2 요약
A38: *2010-2024년 15개 연도 OLS 선형회귀로 그룹별 추세 유의성(p-value) 사전 검정
A39: *추세 유의(p<0.05) 그룹은 선형회귀 연장, 추세 비유의 그룹은 표본수 가중 5개년(2020-2024) 평균 적용
A40: *유의 그룹(60-69세, p=0.020): 예측값 = 기울기×연도+절편 (2010-2024 적합) *비유의 그룹(20-29,30-39,40-49,50-59,70+): 예측값 = 표본수(n) 가중 최근5개년(2020-2024) 평균
A41: ★ 주요 파라미터 (분석 구간: 2010~2024년)
B42: 연령대 | C42: 기울기(slope) | D42: 절편(intercept) | E42: R² | F42: p-value | G42: 적합구간 | H42: 적용방법 | I42: 적용값(%, 평균법만 해당)
B43: =A15 | C43: =SLOPE(B15:P15,$B$4:$P$4) | D43: =INTERCEPT(B15:P15,$B$4:$P$4) | E43: =RSQ(B15:P15,$B$4:$P$4) | F43: =_xlfn.T.DIST.2T(ABS(SLOPE($B$15:$P$15,$B$4:$P$4)/(STEYX($B$15:$P$15,$B$4:$P$4)/SQRT(DEVSQ($B$4:$P$4)))),COUNT($B$4:$P$4)-2) | G43: 2010-2024 (참고용, 추세 비유의로 미사용) | H43: 가중평균(2020-2024, 표본수 n 가중) | I43: =SUMPRODUCT(L15:P15,L53:P53)/SUM(L53:P53)
B44: =A16 | C44: =SLOPE(B16:P16,$B$4:$P$4) | D44: =INTERCEPT(B16:P16,$B$4:$P$4) | E44: =RSQ(B16:P16,$B$4:$P$4) | F44: =_xlfn.T.DIST.2T(ABS(SLOPE($B$16:$P$16,$B$4:$P$4)/(STEYX($B$16:$P$16,$B$4:$P$4)/SQRT(DEVSQ($B$4:$P$4)))),COUNT($B$4:$P$4)-2) | G44: 2010-2025 (참고용, 추세 비유의로 미사용) | H44: 가중평균(2020-2025, 표본수 n 가중) | I44: =SUMPRODUCT(L16:P16,L54:P54)/SUM(L54:P54)
B45: =A17 | C45: =SLOPE(B17:P17,$B$4:$P$4) | D45: =INTERCEPT(B17:P17,$B$4:$P$4) | E45: =RSQ(B17:P17,$B$4:$P$4) | F45: =_xlfn.T.DIST.2T(ABS(SLOPE($B$17:$P$17,$B$4:$P$4)/(STEYX($B$17:$P$17,$B$4:$P$4)/SQRT(DEVSQ($B$4:$P$4)))),COUNT($B$4:$P$4)-2) | G45: 2010-2026 (참고용, 추세 비유의로 미사용) | H45: 가중평균(2020-2026, 표본수 n 가중) | I45: =SUMPRODUCT(L17:P17,L55:P55)/SUM(L55:P55)
B46: =A18 | C46: =SLOPE(B18:P18,$B$4:$P$4) | D46: =INTERCEPT(B18:P18,$B$4:$P$4) | E46: =RSQ(B18:P18,$B$4:$P$4) | F46: =_xlfn.T.DIST.2T(ABS(SLOPE($B$18:$P$18,$B$4:$P$4)/(STEYX($B$18:$P$18,$B$4:$P$4)/SQRT(DEVSQ($B$4:$P$4)))),COUNT($B$4:$P$4)-2) | G46: 2010-2027 (참고용, 추세 비유의로 미사용) | H46: 가중평균(2020-2027, 표본수 n 가중) | I46: =SUMPRODUCT(L18:P18,L56:P56)/SUM(L56:P56)
...

Sheet 근거_의료이용환자수
A1: 의료이용 환자수 산출 : HIRA 데이터 기반 추정
B3: ◀ 실측 (HIRA, 2014~2024) | Q3: 예측 (2025~2030) ▶
A4: 구분 / 연도 ▶ | B4: 2010 | C4: 2011 | D4: 2012 | E4: 2013 | F4: 2014 | G4: 2015 | H4: 2016 | I4: 2017 | J4: 2018 | K4: 2019 | L4: 2020 | M4: 2021 | N4: 2022 | O4: 2023 | P4: 2024 | Q4: 2025 | R4: 2026 | S4: 2027 | T4: 2028 | U4: 2029 | V4: 2030
A5: ■ A. 고혈압 유병환자수 (명) [근거_유병환자수 참조]
A6: 유병환자수 (전체) | B6: =근거_유병환자수!B29 | C6: =근거_유병환자수!C29 | D6: =근거_유병환자수!D29 | E6: =근거_유병환자수!E29 | F6: =근거_유병환자수!F29 | G6: =근거_유병환자수!G29 | H6: =근거_유병환자수!H29 | I6: =근거_유병환자수!I29 | ... V6: =근거_유병환자수!V29
A8: ■ B. 고혈압 의료이용 환자수 [2014~24 : HIRA I10 | 2025~30 : 고혈압 유병환자수(A) × 의료이용비율 고정값1]
A9: ▶ 의료이용 환자수 | F9: =8840086 | G9: =9131239 | H9: =9477565 | I9: 9967602 | J9: 10357002 | K9: 10870422 | L9: 11250720 | M9: 11820083 | N9: 12384955 | O9: 12693552 | P9: 13085573 | Q9: =Q6*Q12 | R9: =R6*R12 | S9: =S6*S12 | T9: =T6*T12 | U9: =U6*U12 | V9: =V6*V12
G10: =G9/F9-1 | H10: =H9/G9-1 | I10: =I9/H9-1 | J10: =J9/I9-1 | K10: =K9/J9-1 | L10: =L9/K9-1 | M10: =M9/L9-1 | N10: =N9/M9-1 | ... V10: =V9/U9-1
A11: ■ C. 의료이용비율 (%) [고혈압 의료이용 환자수(B) ÷ 고혈압 유병환자수(A)]
A12: 의료이용비율 | B12: =B9/B6 | C12: =C9/C6 | D12: =D9/D6 | E12: =E9/E6 | F12: =F9/F6 | G12: =G9/G6 | H12: =H9/H6 | I12: =I9/I6 | ... P12: =P9/P6 | Q12: =C16 | R12: =D16 | S12: =$E$16 | T12: =$E$16 | U12: =$E$16 | V12: =$E$16
A14: ★ 주요 파라미터 (분석 구간: 2014~2024년)
B15: 구분 | C15: 2025 | D15: 2026 | E15: 2027~
B16: 의료이용비율1 | C16: =AVERAGE(M12:P12) | D16: =AVERAGE(N12:Q12) | E16: =AVERAGE(O12:R12)
B17: (2023년 추정값이 101%로 100%를 초과함. 이에 따라 직전 4개년 평균 비율을 반영하여 의료이용비율을 추정)
A19: ※ 출처 : HIRA(2014~2024), BI 자체 추정
A20: ※ 고혈압 의료이용환자수: 고혈압(ICD-10: I10) 주부상병
A21: ※ 범례
A22: · 외부 입력 데이터: 청색(Blue) 표기
A23: · 예측 변수(또는 예측치): 녹색(Green) 표기
A24: · 최종 산출 결과: 황색(Yellow) 음영 행

Sheet 근거_고혈압치료환자수
A1: 의료이용 환자수 산출 : Hypertension Fact Sheet 2025 기반 산출
B3: ◀ 실측 (건보공단 전수, 2010~2023) | P3: 예측 (2024~2030) ▶
A4: 구분 / 연도 ▶ | B4: 2010 | C4: 2011 | D4: 2012 | E4: 2013 | F4: 2014 | G4: 2015 | H4: 2016 | I4: 2017 | J4: 2018 | K4: 2019 | L4: 2020 | M4: 2021 | N4: 2022 | O4: 2023 | P4: 2024 | Q4: 2025 | R4: 2026 | S4: 2027 | T4: 2028 | U4: 2029 | V4: 2030
A5: ■ A. 고혈압 의료이용환자수 (명) [근거_의료이용환자수 참조]
A6: 의료이용환자수 (전체) | F6: =근거_의료이용환자수!F9 | G6: =근거_의료이용환자수!G9 | H6: =근거_의료이용환자수!H9 | I6: =근거_의료이용환자수!I9 | J6: =근거_의료이용환자수!J9 | K6: =근거_의료이용환자수!K9 | L6: =근거_의료이용환자수!L9 | M6: =근거_의료이용환자수!M9 | ... V6: =근거_의료이용환자수!V9
A8: ■ B. 고혈압 치료(처방)환자수 [2010~23 : NHIS | 2024~30 : 고혈압 의료이용환자수(A) × 치료비율 (선형회귀 예측값)]
A9: ▶ 치료(처방) 환자수 | B9: 6538000 | C9: 6772000 | D9: 7220000 | E9: 7499000 | F9: 7696000 | G9: 7944000 | H9: 8297000 | I9: 8633000 | J9: 9027000 | K9: 9512000 | L9: 9916000 | M9: 10460000 | N9: 10891000 | O9: 11255000 | P9: =P6*P12 | Q9: =Q6*Q12 | R9: =R6*R12 | S9: =S6*S12 | T9: =T6*T12 | U9: =U6*U12 | V9: =V6*V12
A11: ■ C. 치료비율 (%) [고혈압 치료(처방) 환자수(B) ÷ 고혈압 의료이용환자수(A)]
A12: 의료치료비율 | F12: =F9/F6 | G12: =G9/G6 | H12: =H9/H6 | I12: =I9/I6 | J12: =J9/J6 | K12: =K9/K6 | L12: =L9/L6 | M12: =M9/M6 | ... O12: =O9/O6 | P12: =$B$16*P4+$C$16 | Q12: =$B$16*Q4+$C$16 | R12: =$B$16*R4+$C$16 | S12: =$B$16*S4+$C$16 | T12: =$B$16*T4+$C$16 | U12: =$B$16*U4+$C$16 | V12: =$B$16*V4+$C$16
A14: ★ 주요 파라미터 (분석 구간: 2014-2023, 선형회귀 전체기간 OLS)
B15: 기울기 | C15: 절편 | D15: R² | E15: 2024 환자수 (기준치)
B16: =SLOPE(F12:O12,F4:O4) | C16: =INTERCEPT(F12:O12,F4:O4) | D16: =RSQ(F12:O12,F4:O4) | E16: =$K$9
B17: [산출 공식] 예측 치료비율(연도) = 기울기×연도+절편
A19: ※ 출처 : NHIS(2014~2023), BI 자체 추정
A20: ※ 고혈압 치료 환자수: 고혈압을 진단명으로 연 1회 이상 고혈압 치료제 처방
A21: ※ 범례
A22: · 외부 입력 데이터: 청색(Blue) 표기
A23: · 예측 변수(또는 예측치): 녹색(Green) 표기
A24: · 최종 산출 결과: 황색(Yellow) 음영 행

Sheet 근거_ARB처방환자수
A1: ARB 처방환자수 산출 : Hypertension Fact Sheet 2025 기반 산출
J3: ◀ 실측 (건보공단 전수, 2018~2023) | P3: 예측 (로지스틱, 2024~2030) ▶
A4: 구분 / 연도 ▶ | B4: 2010 | C4: 2011 | D4: 2012 | E4: 2013 | F4: 2014 | G4: 2015 | H4: 2016 | I4: 2017 | J4: 2018 | K4: 2019 | L4: 2020 | M4: 2021 | N4: 2022 | O4: 2023 | P4: 2024 | Q4: 2025 | R4: 2026 | S4: 2027 | T4: 2028 | U4: 2029 | V4: 2030
A5: ■ A. 고혈압 치료환자수 (명) [근거_치료환자수 참조]
A6: 치료환자수 (전체) | B6: =근거_고혈압치료환자수!B9 | C6: =근거_고혈압치료환자수!C9 | D6: =근거_고혈압치료환자수!D9 | E6: =근거_고혈압치료환자수!E9 | F6: =근거_고혈압치료환자수!F9 | G6: =근거_고혈압치료환자수!G9 | H6: =근거_고혈압치료환자수!H9 | I6: =근거_고혈압치료환자수!I9 | ... V6: =근거_고혈압치료환자수!V9
A8: ■ B. ARB 처방률 (%) [2018~23 : 처방환자수(C)÷고혈압치료(A) | 2023~30 : 과거 처방률 추세를 로지스틱 S-curve1로 연장(상한88%)]
A9: ARB 처방률 | J9: =J12/J6 | K9: =K12/K6 | L9: =L12/L6 | M9: =M12/M6 | N9: =N12/N6 | O9: =O12/O6 | P9: =$E$20 + $B$20/(1+EXP(-$C$20*(P$4-$D$20))) | Q9: =$E$20 + $B$20/(1+EXP(-$C$20*(Q$4-$D$20))) | R9: =$E$20 + $B$20/(1+EXP(-$C$20*(R$4-$D$20))) | S9: =$E$20 + $B$20/(1+EXP(-$C$20*(S$4-$D$20))) | T9: =$E$20 + $B$20/(1+EXP(-$C$20*(T$4-$D$20))) | U9: =$E$20 + $B$20/(1+EXP(-$C$20*(U$4-$D$20))) | V9: =$E$20 + $B$20/(1+EXP(-$C$20*(V$4-$D$20)))
A11: ■ C. ARB 처방환자수 (명) [2018~23 : 건보공단 전수 | 2024~30 : 고혈압 치료환자수(A) × ARB 처방률(B)]
A12: ▶ ARB 처방환자수 | J12: 6439000 | K12: 6892000 | L12: 7317000 | M12: 7855000 | N12: 8290000 | O12: 8669000 | P12: =P6*P9 | Q12: =Q6*Q9 | R12: =R6*R9 | S12: =S6*S9 | T12: =T6*T9 | U12: =U6*U9 | V12: =V6*V9
P13: =P12/O12-1 | Q13: =Q12/P12-1 | R13: =R12/Q12-1 | S13: =S12/R12-1 | T13: =T12/S12-1 | U13: =U12/T12-1 | V13: =V12/U12-1
A16: [참고] ARB 처방률 예측방식 : 로지스틱 S-curve1
B17: 곡선식: p(t) = L / (1 + exp(−k·(t − x0))) + anchor
A18: ★ 주요 파라미터 | B18: (적합구간: 2018~2023; R2=0.9984, 전체 실측 6개년 사용)
B19: L (포화상한) | C19: k (성장속도) | D19: x0 (중심연도) | E19: anchor (2023 보정)
B20: 0.88 | C20: =-SLOPE($D$37:$D$42,$B$37:$B$42) | D20: =INTERCEPT($D$37:$D$42,$B$37:$B$42)/C20 | E20: =O9-($B$20/(1+EXP(-C20*(2023-D20))))
B22: 파라미터 | C22: 산출 근거
B23: L (포화상한) | C23: 2018-2023 실측 6개년에 대한 로지스틱 자유적합(curve_fit)으로 추정(표준오차 ±5%p, 95% CI 약 78~98%).
B24: k (성장속도) | C24: 곡선이 가팔라지는 빠르기 = -SLOPE(z,연도) [B38:D43 보조계산, L=0.88 고정]
B25: x0 (중심연도) | C25: 확산이 가장 빨랐던 해 = INTERCEPT(z,연도)/k [B38:D43 보조계산, L=0.88 고정]
B26: anchor (2023 보정) | C26: 곡선을 2023(최신 실측)에 정확히 맞추는 보정 = O9 - 로지스틱순수식(k,x0,L)
A29: ※ 출처 : NHIS(2018~2023), BI 자체 추정
A30: ※ 범례
A31: · 외부 입력 데이터: 청색(Blue) 표기
A32: · 예측 변수(또는 예측치): 녹색(Green) 표기
A33: · 최종 산출 결과: 황색(Yellow) 음영 행
A35: [참고] k, x0, anchor 선형화 보조계산 (L=0.88 고정, z = LN(L/p - 1))
B36: 연도 | C36: 실측 처방률(p) | D36: z = LN(L/p-1)
B37: =J4 | C37: =J9 | D37: =LN($B$20/J9-1)
B38: =K4 | C38: =K9 | D38: =LN($B$20/K9-1)
B39: =L4 | C39: =L9 | D39: =LN($B$20/L9-1)
B40: =M4 | C40: =M9 | D40: =LN($B$20/M9-1)
B41: =N4 | C41: =N9 | D41: =LN($B$20/N9-1)
B42: =O4 | C42: =O9 | D42: =LN($B$20/O9-1)

Sheet 근거_ARB처방량
A1: ARB 처방량(시장) 산출 : UBIST 기반 추정
G3: ◀ 처방량 실측 (UBIST, 2018~2025) | R3: 예측 (2026~2030) ▶ | Z3: 참고비율
A4: 구분 / 연도 ▶ | B4: 2010 | C4: 2011 | D4: 2012 | E4: 2013 | F4: 2014 | G4: 2015 | H4: 2016 | I4: 2017 | J4: 2018 | K4: 2019 | L4: 2020 | M4: 2021 | N4: 2022 | O4: 2023 | P4: 2024 | Q4: 2025 | R4: 2026 | S4: 2027 | T4: 2028 | U4: 2029 | V4: 2030 | X4: FY26 1분기 | Z4: 1Q | AA4: 2Q | AB4: 3Q | AC4: 4Q | AD4: Total
A5: ■ A. ARB 처방환자수 (명) [근거_ARB처방환자수 참조] | Y5: FY23 | Z5: =SUM(원본_월별!B22:D22) | AA5: =SUM(원본_월별!E22:G22) | AB5: =SUM(원본_월별!H22:J22) | AC5: =SUM(원본_월별!K22:M22) | AD5: =SUM(Z5:AC5)
A6: ARB 처방환자수 | B6: =근거_ARB처방환자수!B12 | C6: =근거_ARB처방환자수!C12 | D6: =근거_ARB처방환자수!D12 | E6: =근거_ARB처방환자수!E12 | F6: =근거_ARB처방환자수!F12 | G6: =근거_ARB처방환자수!G12 | H6: =근거_ARB처방환자수!H12 | I6: =근거_ARB처방환자수!I12 | ... V6: =근거_ARB처방환자수!V12 | Y6: FY24 | Z6: =SUM(원본_월별!B23:D23) | AA6: =SUM(원본_월별!E23:G23) | AB6: =SUM(원본_월별!H23:J23) | AC6: =SUM(원본_월별!K23:M23) | AD6: =SUM(Z6:AC6)
Y7: FY25 | Z7: =SUM(원본_월별!B24:D24) | AA7: =SUM(원본_월별!E24:G24) | AB7: =SUM(원본_월별!H24:J24) | AC7: =SUM(원본_월별!K24:M24) | AD7: =SUM(Z7:AC7)
A8: ■ B. ARB 처방량 [2018~25 : UBIST 실측 | 2026~30 : ARB 처방환자수(A) × VPP(C)] | Y8: FY26 | Z8: =SUM(원본_월별!B25:D25)
A9: ▶ ARB 처방량 | J9: 2.0609748e+09 | K9: 2.1970222e+09 | L9: 2.3315652e+09 | M9: =원본_월별!N20 | N9: =원본_월별!N21 | O9: =원본_월별!N22 | P9: =원본_월별!N23 | Q9: =원본_월별!N24 | R9: =R6*R12 | S9: =S6*S12 | T9: =T6*T12 | U9: =U6*U12 | V9: =V6*V12 | X9: =SUM(원본_월별!B25:D25)
K10: =K9/J9-1 | L10: =L9/K9-1 | M10: =M9/L9-1 | N10: =N9/M9-1 | O10: =O9/N9-1 | P10: =P9/O9-1 | Q10: =Q9/P9-1 | R10: =R9/Q9-1 | ... V10: =V9/U9-1 | X10: =X9/AVERAGE(Z10:Z12)*1 | Z10: =Z5/$AD5 | AA10: =AA5/$AD5 | AB10: =AB5/$AD5 | AC10: =AC5/$AD5
A11: ■ C. VPP 환자당 연간 처방일수 (일) [2018~25 : 처방량(B)÷환자수(A) | 2026~30 : 과거 VPP 평균 기반 고정1] | X11: =X10/Q9-1 | Z11: =Z6/$AD6 | AA11: =AA6/$AD6 | AB11: =AB6/$AD6 | AC11: =AC6/$AD6
A12: VPP (처방일/DOT) | J12: =J9/J6 | K12: =K9/K6 | L12: =L9/L6 | M12: =M9/M6 | N12: =N9/N6 | O12: =O9/O6 | P12: =P9/P6 | Q12: =Q9/Q6 | R12: =IF(N32>0,V32,Q12+C16) | S12: =IF(N33>0,V33,R12+D16) | T12: =IF(N34>0,V34,S12+E16) | U12: =IF(N35>0,V35,T12) | V12: =IF(N35>0,V35,U12) | Z12: =Z7/$AD7 | AA12: =AA7/$AD7 | AB12: =AB7/$AD7 | AC12: =AC7/$AD7
K13: =K12-J12 | L13: =L12-K12 | M13: =M12-L12 | N13: =N12-M12 | O13: =O12-N12 | P13: =P12-O12 | Q13: =Q12-P12
A14: ★ 주요 파라미터 (분석 구간: 2018~2025년)
B15: 구분 | C15: 2026 | D15: 2027 | E15: 2028
B16: VPP 증가 일수 | C16: =ROUND(AVERAGE(O13:Q13),0) | D16: =ROUND(C16*80%,0) | E16: =ROUND(D16*50%,0)
B17: (최근 3개년 증가 일수 평균 반영, 증가 점차 둔화 후유지 추정)
A19: ※ 출처 : UBIST(2018~2025), BI 자체 추정
A20: ※ 단위: 처방일(DOT).
A21: ※ 범례
A22: · 외부 입력 데이터: 청색(Blue) 표기
A23: · 예측 변수(또는 예측치): 녹색(Green) 표기
A24: · 최종 산출 결과: 황색(Yellow) 음영 행
A26: ■ D. 월별 ARB 처방량(FY기준) 실측 입력 & 롤링 VPP
A27: ※ 4월~3월=회계연도(FY) 월. 월별 실측은 「원본_월별」■A(ARB 시장 Total)에서 자동 연결 — 매달 UBIST 파일을 「원본_RAW」에 붙여넣으면 자동 갱신 (여기에 직접 입력하지 마십시오)
A28: 회계연도 | B28: 4월 | C28: 5월 | D28: 6월 | E28: 7월 | F28: 8월 | G28: 9월 | H28: 10월 | I28: 11월 | J28: 12월 | K28: 1월 | L28: 2월 | M28: 3월 | N28: 실측월수 | O28: YTD처방량 | P28: 전년동기YTD | Q28: YoY | R28: 장기평균prior(3개년) | S28: 가중치w | T28: 최종성장률 | U28: 연환산처방량 | V28: VPP예측
A29: FY2023 | B29: =IF(원본_월별!B22="","",원본_월별!B22) | C29: =IF(원본_월별!C22="","",원본_월별!C22) | D29: =IF(원본_월별!D22="","",원본_월별!D22) | E29: =IF(원본_월별!E22="","",원본_월별!E22) | F29: =IF(원본_월별!F22="","",원본_월별!F22) | G29: =IF(원본_월별!G22="","",원본_월별!G22) | H29: =IF(원본_월별!H22="","",원본_월별!H22) | I29: =IF(원본_월별!I22="","",원본_월별!I22) | ... M29: =IF(원본_월별!M22="","",원본_월별!M22) | N29: =COUNT(B29:M29) | O29: =SUM(B29:M29)
A30: FY2024 | B30: =IF(원본_월별!B23="","",원본_월별!B23) | C30: =IF(원본_월별!C23="","",원본_월별!C23) | D30: =IF(원본_월별!D23="","",원본_월별!D23) | E30: =IF(원본_월별!E23="","",원본_월별!E23) | F30: =IF(원본_월별!F23="","",원본_월별!F23) | G30: =IF(원본_월별!G23="","",원본_월별!G23) | H30: =IF(원본_월별!H23="","",원본_월별!H23) | I30: =IF(원본_월별!I23="","",원본_월별!I23) | ... M30: =IF(원본_월별!M23="","",원본_월별!M23) | N30: =COUNT(B30:M30) | O30: =SUM(B30:M30)
A31: FY2025 | B31: =IF(원본_월별!B24="","",원본_월별!B24) | C31: =IF(원본_월별!C24="","",원본_월별!C24) | D31: =IF(원본_월별!D24="","",원본_월별!D24) | E31: =IF(원본_월별!E24="","",원본_월별!E24) | F31: =IF(원본_월별!F24="","",원본_월별!F24) | G31: =IF(원본_월별!G24="","",원본_월별!G24) | H31: =IF(원본_월별!H24="","",원본_월별!H24) | I31: =IF(원본_월별!I24="","",원본_월별!I24) | ... M31: =IF(원본_월별!M24="","",원본_월별!M24) | N31: =COUNT(B31:M31) | O31: =SUM(B31:M31)
A32: FY2026 | B32: =IF(원본_월별!B25="","",원본_월별!B25) | C32: =IF(원본_월별!C25="","",원본_월별!C25) | D32: =IF(원본_월별!D25="","",원본_월별!D25) | E32: =IF(원본_월별!E25="","",원본_월별!E25) | F32: =IF(원본_월별!F25="","",원본_월별!F25) | G32: =IF(원본_월별!G25="","",원본_월별!G25) | H32: =IF(원본_월별!H25="","",원본_월별!H25) | I32: =IF(원본_월별!I25="","",원본_월별!I25) | ... M32: =IF(원본_월별!M25="","",원본_월별!M25) | N32: =COUNT(B32:M32) | O32: =SUM(B32:M32) | P32: =IF(N32=0,0,SUM($B31:INDEX($B31:$M31,N32))) | Q32: =IF(OR(N32=0,P32=0),"",O32/P32-1) | R32: =AVERAGE(O9/N9-1,P9/O9-1,Q9/P9-1) | S32: =IF(N32=0,"",IF(N32=1,0.3,IF(N32=2,0.7,0.9))) | T32: =IF(N32=0,"",S32*Q32+(1-S32)*R32) | U32: =IF(N32=0,"",Q9*(1+T32)) | V32: =IF(N32=0,"",U32/R6)
A33: FY2027 | B33: =IF(원본_월별!B26="","",원본_월별!B26) | C33: =IF(원본_월별!C26="","",원본_월별!C26) | D33: =IF(원본_월별!D26="","",원본_월별!D26) | E33: =IF(원본_월별!E26="","",원본_월별!E26) | F33: =IF(원본_월별!F26="","",원본_월별!F26) | G33: =IF(원본_월별!G26="","",원본_월별!G26) | H33: =IF(원본_월별!H26="","",원본_월별!H26) | I33: =IF(원본_월별!I26="","",원본_월별!I26) | ... M33: =IF(원본_월별!M26="","",원본_월별!M26) | N33: =COUNT(B33:M33) | O33: =SUM(B33:M33) | P33: =IF(N33=0,0,SUM($B32:INDEX($B32:$M32,N33))) | Q33: =IF(OR(N33=0,P33=0),"",O33/P33-1) | R33: =AVERAGE(P9/O9-1,Q9/P9-1,R9/Q9-1) | S33: =IF(N33=0,"",IF(N33=1,0.3,IF(N33=2,0.7,0.9))) | T33: =IF(N33=0,"",S33*Q33+(1-S33)*R33) | U33: =IF(N33=0,"",R9*(1+T33)) | V33: =IF(N33=0,"",U33/S6)
A34: FY2028 | B34: =IF(원본_월별!B27="","",원본_월별!B27) | C34: =IF(원본_월별!C27="","",원본_월별!C27) | D34: =IF(원본_월별!D27="","",원본_월별!D27) | E34: =IF(원본_월별!E27="","",원본_월별!E27) | F34: =IF(원본_월별!F27="","",원본_월별!F27) | G34: =IF(원본_월별!G27="","",원본_월별!G27) | H34: =IF(원본_월별!H27="","",원본_월별!H27) | I34: =IF(원본_월별!I27="","",원본_월별!I27) | ... M34: =IF(원본_월별!M27="","",원본_월별!M27) | N34: =COUNT(B34:M34) | O34: =SUM(B34:M34) | P34: =IF(N34=0,0,SUM($B33:INDEX($B33:$M33,N34))) | Q34: =IF(OR(N34=0,P34=0),"",O34/P34-1) | R34: =AVERAGE(Q9/P9-1,R9/Q9-1,S9/R9-1) | S34: =IF(N34=0,"",IF(N34=1,0.3,IF(N34=2,0.7,0.9))) | T34: =IF(N34=0,"",S34*Q34+(1-S34)*R34) | U34: =IF(N34=0,"",S9*(1+T34)) | V34: =IF(N34=0,"",U34/T6)
A35: FY2029 | B35: =IF(원본_월별!B28="","",원본_월별!B28) | C35: =IF(원본_월별!C28="","",원본_월별!C28) | D35: =IF(원본_월별!D28="","",원본_월별!D28) | E35: =IF(원본_월별!E28="","",원본_월별!E28) | F35: =IF(원본_월별!F28="","",원본_월별!F28) | G35: =IF(원본_월별!G28="","",원본_월별!G28) | H35: =IF(원본_월별!H28="","",원본_월별!H28) | I35: =IF(원본_월별!I28="","",원본_월별!I28) | ... M35: =IF(원본_월별!M28="","",원본_월별!M28) | N35: =COUNT(B35:M35) | O35: =SUM(B35:M35) | P35: =IF(N35=0,0,SUM($B34:INDEX($B34:$M34,N35))) | Q35: =IF(OR(N35=0,P35=0),"",O35/P35-1) | R35: =AVERAGE(R9/Q9-1,S9/R9-1,T9/S9-1) | S35: =IF(N35=0,"",IF(N35=1,0.3,IF(N35=2,0.7,0.9))) | T35: =IF(N35=0,"",S35*Q35+(1-S35)*R35) | U35: =IF(N35=0,"",T9*(1+T35)) | V35: =IF(N35=0,"",U35/U6)
A36: FY2030 | B36: =IF(원본_월별!B29="","",원본_월별!B29) | C36: =IF(원본_월별!C29="","",원본_월별!C29) | D36: =IF(원본_월별!D29="","",원본_월별!D29) | E36: =IF(원본_월별!E29="","",원본_월별!E29) | F36: =IF(원본_월별!F29="","",원본_월별!F29) | G36: =IF(원본_월별!G29="","",원본_월별!G29) | H36: =IF(원본_월별!H29="","",원본_월별!H29) | I36: =IF(원본_월별!I29="","",원본_월별!I29) | ... M36: =IF(원본_월별!M29="","",원본_월별!M29) | N36: =COUNT(B36:M36) | O36: =SUM(B36:M36) | P36: =IF(N36=0,0,SUM($B35:INDEX($B35:$M35,N36))) | Q36: =IF(OR(N36=0,P36=0),"",O36/P36-1) | R36: =AVERAGE(S9/R9-1,T9/S9-1,U9/T9-1) | S36: =IF(N36=0,"",IF(N36=1,0.3,IF(N36=2,0.7,0.9))) | T36: =IF(N36=0,"",S36*Q36+(1-S36)*R36) | U36: =IF(N36=0,"",U9*(1+T36)) | V36: =IF(N36=0,"",U36/V6)

Sheet 근거_ARB+CCB+DU복합제처방량
A1: ARB+CCB+DU 복합제 처방량 산출 : UBIST 기반 추정
B3: ◀ 실측 (UBIST MS, FY18~25) | J3: 예측 ▶
A4: 구분 / 회계연도 ▶ | B4: FY2018 | C4: FY2019 | D4: FY2020 | E4: FY2021 | F4: FY2022 | G4: FY2023 | H4: FY2024 | I4: FY2025 | J4: FY2026 | K4: FY2027 | L4: FY2028 | M4: FY2029 | N4: FY2030 | P4: FY26 1분기
A5: ■ A. ARB 처방량 [근거_ARB 처방량 참조]
A6: ARB 처방량 | B6: =근거_ARB처방량!J9 | C6: =근거_ARB처방량!K9 | D6: =근거_ARB처방량!L9 | E6: =근거_ARB처방량!M9 | F6: =근거_ARB처방량!N9 | G6: =근거_ARB처방량!O9 | H6: =근거_ARB처방량!P9 | I6: =근거_ARB처방량!Q9 | ... N6: =근거_ARB처방량!V9 | P6: =근거_ARB처방량!X9 | Q6: =P6*4/J6
A8: ■ B. ARB복합제 비율 [2018~25 : UBIST 실측 | 2026~30 : 하한고정(로지스틱, 하한 59.35%), 이미 정체 국면]
A9: ARB 복합제 비율 | B9: 0.60625872 | C9: 0.60219115 | D9: 0.60010228 | E9: 0.5985175 | F9: 0.5985093 | G9: 0.59688084 | H9: 0.59468021 | I9: 0.59517313 | J9: =$D$22+(1-$D$22)/(1+EXP(-$E$22*(VALUE(MID(J4,3,4))-$F$22)))+$G$22 | K9: =$D$22+(1-$D$22)/(1+EXP(-$E$22*(VALUE(MID(K4,3,4))-$F$22)))+$G$22 | L9: =$D$22+(1-$D$22)/(1+EXP(-$E$22*(VALUE(MID(L4,3,4))-$F$22)))+$G$22 | M9: =$D$22+(1-$D$22)/(1+EXP(-$E$22*(VALUE(MID(M4,3,4))-$F$22)))+$G$22 | N9: =$D$22+(1-$D$22)/(1+EXP(-$E$22*(VALUE(MID(N4,3,4))-$F$22)))+$G$22 | P9: 0.59826775 | Q9: =P9-J9
A11: ■ C. ARB 복합제 중 ARB+CCB+DU 비율 [2018~25 : UBIST 실측 | 2026~30 : 상한고정(로지스틱, 상한 11.5%)]
A12: ARB+CCB+DU 복합제 비율 | B12: 0.044854934 | C12: 0.057894343 | D12: 0.07271715 | E12: 0.081059308 | F12: 0.091581319 | G12: 0.098549952 | H12: 0.10175936 | I12: 0.10537134 | J12: =$D$23/(1+EXP(-$E$23*(VALUE(MID(J4,3,4))-$F$23)))+$G$23 | K12: =$D$23/(1+EXP(-$E$23*(VALUE(MID(K4,3,4))-$F$23)))+$G$23 | L12: =$D$23/(1+EXP(-$E$23*(VALUE(MID(L4,3,4))-$F$23)))+$G$23 | M12: =$D$23/(1+EXP(-$E$23*(VALUE(MID(M4,3,4))-$F$23)))+$G$23 | N12: =$D$23/(1+EXP(-$E$23*(VALUE(MID(N4,3,4))-$F$23)))+$G$23 | P12: 0.11408274 | Q12: =P12-J12
A14: ■ D. ARB+CCB+DU 복합제 처방량 : [ARB 처방량 (A) × ARB복합제비율 (B) x ARB+CCB+DU비율(C)]
A15: ▶ ARB+CCB+DU 복합제 처방량 | B15: 56045520 | C15: 76595800 | D15: 1.0174421e+08 | E15: =원본_월별!N36+원본_월별!N51 | F15: =원본_월별!N37+원본_월별!N52 | G15: =원본_월별!N38+원본_월별!N53 | H15: =원본_월별!N39+원본_월별!N54 | I15: =원본_월별!N40+원본_월별!N55 | J15: =J6*J9*J12 | K15: =K6*K9*K12 | L15: =L6*L9*L12 | M15: =M6*M9*M12 | N15: =N6*N9*N12 | P15: 52859760 | Q15: 1.1081194
I16: =I15/H15-1 | J16: =J15/I15-1 | K16: =K15/J15-1 | L16: =L15/K15-1 | M16: =M15/L15-1 | N16: =N15/M15-1
A17: [참고] 전체 ARB 시장 중 ARB+CCB+DU 복합제 비율: [ARB+CCB+DU 복합제 처방량 (D) ÷ ARB 처방량 (A)]
B18: =B15/B6 | C18: =C15/C6 | D18: =D15/D6 | E18: =E15/E6 | F18: =F15/F6 | G18: =G15/G6 | H18: =H15/H6 | I18: =I15/I6 | ... N18: =N15/N6 | P18: 320409135 | Q18: 1.028
B20: ★ 주요 파라미터 (분석 구간: 2018~2025년 실측 기준)
B21: 구분 | C21: 유형 | D21: floor / L | E21: k | F21: x0 | G21: anchor | H21: 설명 및 비고
B22: ARB 복합제 비율 | C22: 하한형 | D22: 0.5935 | E22: -0.2979 | F22: 2006.4 | G22: 7e-05 | H22: 2018-2025 실측치에 하한 있는 S자 곡선(로지스틱)을 맞춰 산출, 자동 산출값 그대로 사용(고정값). ※ floor 조정 시 anchor 재검토 필요
B23: ARB+CCB+DU 복합제 비율 | C23: 상한형 | D23: 0.115 | E23: 0.489 | F23: 2018.8 | G23: 0.0024035 | H23: 2018-2025 실측치에 상한 있는 S자 곡선(로지스틱)을 맞춰 산출, anchor는 FY26 1분기 실측(11.41%)에 맞춰 수동 재보정(고정값). ※ L 조정 시 anchor 재검토 필요
B25: ★ 추정 산출 흐름 (① curve_fit 모수 추정 → ② S-curve 곡선식 적용 → ③ anchor 보정)
B26: 단계 | C26: 연산 과정 | E26: 개념 및 설명
B27: S1. 모수 추정 (curve_fit) | C27: floor(또는 L), k, x0 동시 추정 (비선형 최소자승) | E27: 실측 데이터에 가장 잘 맞는 곡선의 하한(또는 상한)·기울기·중심연도를 컴퓨터가 한 번에 자동 산출
B28: S2. 곡선식 적용 (상한형) | C28: p(t) = L ÷ (1+EXP(−k×(t−x0))) | E28: t(연도)가 커질수록 상한(L)에 아래에서 위로 수렴
B29: S2. 곡선식 적용 (하한형) | C29: p(t) = floor + (1−floor)÷(1+EXP(−k×(t−x0))) | E29: t(연도)가 커질수록 하한(floor)에 위에서 아래로 수렴
B30: S3. anchor 보정 | C30: 최종 p(t) = ②값 + anchor | E30: ②에서 산출한 곡선값을 최신 실측 시점에 정확히 맞도록 미세 보정
B31: [예시] FY2026 ARB+CCB+DU 비율(상한형): 0.115÷(1+EXP(−0.489×(2026−2018.8)))+0.00240 = 11.41% | FY2026 ARB 복합제 비율(하한형): 0.5935+(1−0.5935)÷(1+EXP(−(−0.2979)×(2026−2006.4)))+0.00007 = 59.48%
A33: ※ 출처 : UBIST(2018~2025), BI 자체 추정
A34: ※ 범례
A35: · 외부 입력 데이터: 청색(Blue) 표기
A36: · 예측 변수(또는 예측치): 녹색(Green) 표기
A37: · 최종 산출 결과: 황색(Yellow) 음영 행

Sheet 근거_SVK HCT처방량
A1: SVK HCT 처방량 산출 : UBIST 데이터 기반 추정
B3: ◀ 실측 (UBIST MS, FY18~25) | J3: 예측 ▶
A4: 구분 / 회계연도 ▶ | B4: FY2018 | C4: FY2019 | D4: FY2020 | E4: FY2021 | F4: FY2022 | G4: FY2023 | H4: FY2024 | I4: FY2025 | J4: FY2026 | K4: FY2027 | L4: FY2028 | M4: FY2029 | N4: FY2030 | P4: FY26 1분기
A5: ■ A. ARB+CCB+DU복합제 처방량 [근거_ARB+CCB+DU복합제 처방량 참조]
A6: ARB+CCB+DU복합제 처방량 (시장) | B6: ='근거_ARB+CCB+DU복합제처방량'!B15 | C6: ='근거_ARB+CCB+DU복합제처방량'!C15 | D6: ='근거_ARB+CCB+DU복합제처방량'!D15 | E6: ='근거_ARB+CCB+DU복합제처방량'!E15 | F6: ='근거_ARB+CCB+DU복합제처방량'!F15 | G6: ='근거_ARB+CCB+DU복합제처방량'!G15 | H6: ='근거_ARB+CCB+DU복합제처방량'!H15 | I6: ='근거_ARB+CCB+DU복합제처방량'!I15 | ... N6: ='근거_ARB+CCB+DU복합제처방량'!N15
A8: ■ B. ARB+CCB+DU복합제 HP:GP 비율 : [2018~25 : UBIST 실측 | 2026~30 : FY2024Q3(peak) 이후 분기 기반 로지스틱 회귀, 하한 고정(22.0%)]
A9: HP비율 | B9: 0.35033633 | C9: 0.30655767 | D9: 0.25695488 | E9: =원본_월별!N36/(원본_월별!N36+원본_월별!N51) | F9: =원본_월별!N37/(원본_월별!N37+원본_월별!N52) | G9: =원본_월별!N38/(원본_월별!N38+원본_월별!N53) | H9: =원본_월별!N39/(원본_월별!N39+원본_월별!N54) | I9: =원본_월별!N40/(원본_월별!N40+원본_월별!N55) | J9: =AVERAGE(B66:E66) | K9: =AVERAGE(F66:I66) | L9: =AVERAGE(J66:M66) | M9: =AVERAGE(N66:Q66) | N9: =AVERAGE(R66:U66) | P9: =원본_월별!V289 | Q9: =P9-J9
A10: GP비율 | B10: 0.64966367 | C10: 0.69344233 | D10: 0.74304512 | E10: =1-E9 | F10: =1-F9 | G10: =1-G9 | H10: =1-H9 | I10: =1-I9 | J10: =1-J9 | K10: =1-K9 | L10: =1-L9 | ... N10: =1-N9 | P10: =1-P9 | Q10: =P10-J10
A11: HP성장률 | C11: =(C$6*C9)/(B$6*B9)-1 | D11: =(D$6*D9)/(C$6*C9)-1 | E11: =(E$6*E9)/(D$6*D9)-1 | F11: =(F$6*F9)/(E$6*E9)-1 | G11: =(G$6*G9)/(F$6*F9)-1 | H11: =(H$6*H9)/(G$6*G9)-1 | I11: =(I$6*I9)/(H$6*H9)-1 | J11: =(J$6*J9)/(I$6*I9)-1 | ... N11: =(N$6*N9)/(M$6*M9)-1
A12: GP성장률 | C12: =(C$6*C10)/(B$6*B10)-1 | D12: =(D$6*D10)/(C$6*C10)-1 | E12: =(E$6*E10)/(D$6*D10)-1 | F12: =(F$6*F10)/(E$6*E10)-1 | G12: =(G$6*G10)/(F$6*F10)-1 | H12: =(H$6*H10)/(G$6*G10)-1 | I12: =(I$6*I10)/(H$6*H10)-1 | J12: =(J$6*J10)/(I$6*I10)-1 | ... N12: =(N$6*N10)/(M$6*M10)-1
A14: ■ C. HP내 SVK HCT MS : [2018~25 : UBIST 실측 | 2026~30 : Olmesartan 비율=하한고정(로지스틱, 하한 47.0%), Original 비율=분기실측 기반 FY2020Q1~ 자동확장 직접선형회귀]
A15: Olmesartan MS | B15: 0.88632325 | C15: 0.79044332 | D15: 0.69758354 | E15: =원본_월별!N67/원본_월별!N36 | F15: =원본_월별!N68/원본_월별!N37 | G15: =원본_월별!N69/원본_월별!N38 | H15: =원본_월별!N70/원본_월별!N39 | I15: =원본_월별!N71/원본_월별!N40 | J15: =AVERAGE(B67:E67) | K15: =AVERAGE(F67:I67) | L15: =AVERAGE(J67:M67) | M15: =AVERAGE(N67:Q67) | N15: =AVERAGE(R67:U67) | P15: =원본_월별!V290 | Q15: =P15-J15
A16: Original 비율 | B16: 1 | C16: 0.99651363 | D16: 0.98969879 | E16: =원본_월별!N98/원본_월별!N67 | F16: =원본_월별!N99/원본_월별!N68 | G16: =원본_월별!N100/원본_월별!N69 | H16: =원본_월별!N101/원본_월별!N70 | I16: =원본_월별!N102/원본_월별!N71 | J16: =AVERAGE(B68:E68) | K16: =AVERAGE(F68:I68) | L16: =AVERAGE(J68:M68) | M16: =AVERAGE(N68:Q68) | N16: =AVERAGE(R68:U68) | P16: =원본_월별!V291 | Q16: =P16-J16
A17: HP내 SVK HCT MS | B17: =B15*B16 | C17: =C15*C16 | D17: =D15*D16 | E17: =E15*E16 | F17: =F15*F16 | G17: =G15*G16 | H17: =H15*H16 | I17: =I15*I16 | ... N17: =N15*N16 | P17: =P15*P16 | Q17: =P17-J17
A19: ■ D. GP내 SVK HCT MS : [2018~25 : UBIST 실측 | 2026~30 : Olmesartan=분기실측 기반 floor고정(37.9%, 판단치) 로지스틱회귀(자동연동), Original=분기실측 기반 FY2019Q1~ 자동확장 로짓 변환 회귀]
A20: Olmesartan MS | B20: 0.57609307 | C20: 0.50089694 | D20: 0.45280893 | E20: =원본_월별!N82/원본_월별!N51 | F20: =원본_월별!N83/원본_월별!N52 | G20: =원본_월별!N84/원본_월별!N53 | H20: =원본_월별!N85/원본_월별!N54 | I20: =원본_월별!N86/원본_월별!N55 | J20: =AVERAGE(B69:E69) | K20: =AVERAGE(F69:I69) | L20: =AVERAGE(J69:M69) | M20: =AVERAGE(N69:Q69) | N20: =AVERAGE(R69:U69) | P20: =원본_월별!V292
A21: Original 비율 | B21: 0.99975943 | C21: 0.86151369 | D21: 0.74299527 | E21: =원본_월별!N113/원본_월별!N82 | F21: =원본_월별!N114/원본_월별!N83 | G21: =원본_월별!N115/원본_월별!N84 | H21: =원본_월별!N116/원본_월별!N85 | I21: =원본_월별!N117/원본_월별!N86 | J21: =AVERAGE(B70:E70) | K21: =AVERAGE(F70:I70) | L21: =AVERAGE(J70:M70) | M21: =AVERAGE(N70:Q70) | N21: =AVERAGE(R70:U70) | P21: =원본_월별!V293
A22: GP내 SVK HCT MS | B22: =B20*B21 | C22: =C20*C21 | D22: =D20*D21 | E22: =E20*E21 | F22: =F20*F21 | G22: =G20*G21 | H22: =H20*H21 | I22: =I20*I21 | ... N22: =N20*N21 | P22: =P20*P21 | Q22: =P22-J22
A24: (전체 시장 내) Olmesartan MS | B24: =((B$6*B$9*B15)+(B$6*B$10*B20))/B$6 | C24: =((C$6*C$9*C15)+(C$6*C$10*C20))/C$6 | D24: =((D$6*D$9*D15)+(D$6*D$10*D20))/D$6 | E24: =((E$6*E$9*E15)+(E$6*E$10*E20))/E$6 | F24: =((F$6*F$9*F15)+(F$6*F$10*F20))/F$6 | G24: =((G$6*G$9*G15)+(G$6*G$10*G20))/G$6 | H24: =((H$6*H$9*H15)+(H$6*H$10*H20))/H$6 | I24: =((I$6*I$9*I15)+(I$6*I$10*I20))/I$6 | ... N24: =((N$6*N$9*N15)+(N$6*N$10*N20))/N$6
A25: (전체 시장 내) Olmesartan 中 Original MS | B25: =((B$6*B$9*B15*B16)+(B$6*B$10*B20*B21))/((B$6*B$9*B15)+(B$6*B$10*B20)) | C25: =((C$6*C$9*C15*C16)+(C$6*C$10*C20*C21))/((C$6*C$9*C15)+(C$6*C$10*C20)) | D25: =((D$6*D$9*D15*D16)+(D$6*D$10*D20*D21))/((D$6*D$9*D15)+(D$6*D$10*D20)) | E25: =((E$6*E$9*E15*E16)+(E$6*E$10*E20*E21))/((E$6*E$9*E15)+(E$6*E$10*E20)) | F25: =((F$6*F$9*F15*F16)+(F$6*F$10*F20*F21))/((F$6*F$9*F15)+(F$6*F$10*F20)) | G25: =((G$6*G$9*G15*G16)+(G$6*G$10*G20*G21))/((G$6*G$9*G15)+(G$6*G$10*G20)) | H25: =((H$6*H$9*H15*H16)+(H$6*H$10*H20*H21))/((H$6*H$9*H15)+(H$6*H$10*H20)) | I25: =((I$6*I$9*I15*I16)+(I$6*I$10*I20*I21))/((I$6*I$9*I15)+(I$6*I$10*I20)) | ... N25: =((N$6*N$9*N15*N16)+(N$6*N$10*N20*N21))/((N$6*N$9*N15)+(N$6*N$10*N20))
A26: (전체 시장 내) SVK HCT MS | B26: =B31/B6 | C26: =C31/C6 | D26: =D31/D6 | E26: =E31/E6 | F26: =F31/F6 | G26: =G31/G6 | H26: =H31/H6 | I26: =I31/I6 | ... N26: =N31/N6
A28: ■ E. SVK HCT 처방량 : [ARB+CCB+DU 복합제 처방량 (A) × HPorGP비율(B) x SVK HCT MS(C or D)]
A29: SVK HCT HP 처방량 | B29: 17402764 | C29: 18495715 | D29: 18049527 | E29: =원본_월별!N98 | F29: =원본_월별!N99 | G29: =원본_월별!N100 | H29: =원본_월별!N101 | I29: =원본_월별!N102 | J29: =J6*J9*J17 | K29: =K6*K9*K17 | L29: =L6*L9*L17 | M29: =M6*M9*M17 | N29: =N6*N9*N17 | P29: =원본_월별!V287
A30: SVK HCT GP 처방량 | B30: 20970928 | C30: 22920594 | D30: 25434659 | E30: =원본_월별!N113 | F30: =원본_월별!N114 | G30: =원본_월별!N115 | H30: =원본_월별!N116 | I30: =원본_월별!N117 | J30: =J6*J10*J22 | K30: =K6*K10*K22 | L30: =L6*L10*L22 | M30: =M6*M10*M22 | N30: =N6*N10*N22 | P30: =원본_월별!V288
A31: ▶ SVK HCT 처방량 | B31: =B29+B30 | C31: =C29+C30 | D31: =D29+D30 | E31: =E29+E30 | F31: =F29+F30 | G31: =G29+G30 | H31: =H29+H30 | I31: =I29+I30 | ... N31: =N29+N30 | P31: =P29+P30 | Q31: 1.0156681
B33: ★ 주요 파라미터 (분석 구간: 2018~2025년 실측 기준, 계열별 방식 상이) — 분기 원자료·FY26 1분기는 원본_월별 ■I 분기 집계에 자동 연동
B34: 구분 | C34: 산출 방식 | D34: floor | E34: slope(k) | F34: intercept(x0) | G34: anchor | H34: 예측 로직 | J34: 비고
B35: HP:GP 비율 | C35: 로지스틱(하한 판단고정 22.0%) + 분기회귀 | D35: 0.22 | E35: =SLOPE($R$59:INDEX($R$59:$CZ$59,COUNTA($R$59:$CZ$59)),$R$57:INDEX($R$57:$CZ$57,COUNTA($R$57:$CZ$57))) | F35: =INTERCEPT($R$59:INDEX($R$59:$CZ$59,COUNTA($R$59:$CZ$59)),$R$57:INDEX($R$57:$CZ$57,COUNTA($R$57:$CZ$57))) | G35: =INDEX($C$59:$CZ$59,COUNTA($C$59:$CZ$59))-(E35*INDEX($C$57:$CZ$57,COUNTA($C$57:$CZ$57))+F35) | H35: FY26=실측 1분기+예측 3분기 평균, FY27-30=예측 4분기 평균 | J35: FY2024Q3(peak) 이후 7분기, p=0.00017·R²=0.953
B36: Olmesartan MS (HP) | C36: 로지스틱(하한 47.03%) curve_fit | D36: 0.4703 | E36: -0.5269 | F36: 2019.9 | G36: -0.0030596296 | H36: FY26=실측 1분기+예측 3분기 평균, FY27-30=예측 4분기 평균 | J36: 2018-2025 실측 자유적합, SE(floor)=±4.00%p
B37: Original 비율 (HP) | C37: 직접선형회귀 (로짓변환 미사용) | E37: =SLOPE($J$60:INDEX($J$60:$CZ$60,COUNTA($J$60:$CZ$60)),$J$54:INDEX($J$54:$CZ$54,COUNTA($J$54:$CZ$54))) | F37: =INTERCEPT($J$60:INDEX($J$60:$CZ$60,COUNTA($J$60:$CZ$60)),$J$54:INDEX($J$54:$CZ$54,COUNTA($J$54:$CZ$54))) | G37: =INDEX($B$60:$CZ$60,COUNTA($B$60:$CZ$60))-(E37*INDEX($B$54:$CZ$54,COUNTA($B$54:$CZ$54))+F37) | H37: FY26=실측 1분기+예측 3분기 평균, FY27-30=예측 4분기 평균 | J37: 로짓변환 시 인위적 가속 확인되어 직접선형 유지, 장기외삽 주의
B38: Olmesartan MS (GP) | C38: 로지스틱(하한 판단고정 37.9%) + 최근5분기 회귀 | D38: 0.379 | E38: =SLOPE(INDEX($B$61:$CZ$61,COUNTA($B$61:$CZ$61)-4):INDEX($B$61:$CZ$61,COUNTA($B$61:$CZ$61)),INDEX($B$54:$CZ$54,COUNTA($B$54:$CZ$54)-4):INDEX($B$54:$CZ$54,COUNTA($B$54:$CZ$54))) | F38: =INTERCEPT(INDEX($B$61:$CZ$61,COUNTA($B$61:$CZ$61)-4):INDEX($B$61:$CZ$61,COUNTA($B$61:$CZ$61)),INDEX($B$54:$CZ$54,COUNTA($B$54:$CZ$54)-4):INDEX($B$54:$CZ$54,COUNTA($B$54:$CZ$54))) | H38: FY26=실측 1분기+예측 3분기 평균, FY27-30=FY26 4분기 예측값 고정(flat) | J38: 무기한 하락 비현실적이라 FY26 Q4 수준에서 고정
B39: Original 비율 (GP) | C39: 로짓 변환 회귀 (최근구간만 사용) | E39: =SLOPE($V$62:INDEX($V$62:$CZ$62,COUNTA($V$62:$CZ$62)),$V$54:INDEX($V$54:$CZ$54,COUNTA($V$54:$CZ$54))) | F39: =INTERCEPT($V$62:INDEX($V$62:$CZ$62,COUNTA($V$62:$CZ$62)),$V$54:INDEX($V$54:$CZ$54,COUNTA($V$54:$CZ$54))) | G39: =INDEX($B$62:$CZ$62,COUNTA($B$62:$CZ$62))-(E39*INDEX($B$54:$CZ$54,COUNTA($B$54:$CZ$54))+F39) | H39: FY26=실측 1분기+예측 3분기 평균, FY27-30=예측 4분기 평균 | J39: FY2023Q1~ 자동확장, 전체기간 사용시 초기급락 왜곡 확인되어 최근구간만 사용
A41: ★ 추정 산출 흐름 — 계열마다 곡선식이 달라 아래 3가지 유형으로 구분
B42: 유형 | C42: 적용 계열 | D42: 곡선식 | E42: 설명
B43: ① 로지스틱(하한) | C43: HP:GP비율, Olmesartan MS(HP,GP) | D43: p(t) = floor + (1−floor)÷(1+EXP(−(slope×t+intercept[+anchor]))) | E43: floor는 판단 고정값 또는 curve_fit 산출값, slope·intercept는 분기 회귀로 산출
B44: ② 직접선형회귀 | C44: Original 비율(HP) | D44: p(t) = (slope×t + intercept + anchor) ÷ 100 | E44: 로짓변환 없이 %p 단위로 바로 선형회귀 (로짓변환 시 왜곡 발생 확인되어 미사용)
B45: ③ 로짓 변환 회귀 | C45: Original 비율(GP) | D45: p(t) = EXP(slope×t+intercept+anchor) ÷ (1+EXP(slope×t+intercept+anchor)) | E45: 표준 로짓변환 회귀 + anchor는 로짓(z) 공간에서 최신 실측에 보정
B46: [분기평균] 모든 계열이 회귀식 하나로 연도값을 바로 내지 않고, 4개 분기(FY+0/0.25/0.5/0.75)를 각각 계산해 평균 — FY26은 1분기 실측을 그대로 쓰고 2~4분기만 예측해서 평균, FY27~30은 4개 분기 모두 예측해서 평균 (Olmesartan MS(GP)만 FY27 이후 4분기째 예측값에서 고정)
A48: ★ [부록] 분기 원자료 (5개 계열 자동확장 회귀용, FY2018Q1~FY2026Q1)
A49: 항목 / FY분기 ▶ | B49: FY2018Q1 | C49: FY2018Q2 | D49: FY2018Q3 | E49: FY2018Q4 | F49: FY2019Q1 | G49: FY2019Q2 | H49: FY2019Q3 | I49: FY2019Q4 | J49: FY2020Q1 | K49: FY2020Q2 | L49: FY2020Q3 | M49: FY2020Q4 | N49: FY2021Q1 | O49: FY2021Q2 | P49: FY2021Q3 | Q49: FY2021Q4 | R49: FY2022Q1 | S49: FY2022Q2 | T49: FY2022Q3 | U49: FY2022Q4 | V49: FY2023Q1 | W49: FY2023Q2 | X49: FY2023Q3 | Y49: FY2023Q4 | Z49: FY2024Q1 | AA49: FY2024Q2 | AB49: FY2024Q3 | AC49: FY2024Q4 | AD49: FY2025Q1 | AE49: FY2025Q2 | AF49: FY2025Q3 | AG49: FY2025Q4 | AH49: FY2026Q1
...

Sheet SVK HCT_MS_예측
A1: ARB 시장 구조 예측 모델 | 파라미터·예측 통합 | C1: FY기준
A2: 항목 | B2: 단위 | C2: 2018 | D2: 2019 | E2: 2020 | F2: 2021 | G2: 2022 | H2: 2023 | I2: 2024 | J2: 2025 | K2: 2026 | L2: 2027 | M2: 2028 | N2: 2029 | O2: 2030
A3: A. 전체 ARB 시장
A4: 전체 시장 | B4: 처방량 | C4: 2.0609748e+09 | D4: 2.1970222e+09 | E4: 2.3315652e+09 | F4: 2.4932969e+09 | G4: 2.6410482e+09 | H4: 2.7780287e+09 | I4: 2.9182679e+09 | J4: 3.0036776e+09 | K4: =근거_ARB처방량!R9 | L4: =근거_ARB처방량!S9 | M4: =근거_ARB처방량!T9 | N4: =근거_ARB처방량!U9 | O4: =근거_ARB처방량!V9
A6: B. ARB 처방중 단일제/복합제 비율 | 예측(2026-30): 복합제(비다중, MAIN)는 로지스틱(하한) 개별 자유적합, 단일제는 추세 비유의(p=0.337)로 8년 평균 고정, 복합제(다중)는 100%-나머지2개 잔여값. 근거: 하단 [참고] 표
A7: 단일제 | B7: % | C7: 0.35107131 | D7: 0.35163699 | E7: 0.34666846 | F7: 0.3439211 | G7: 0.34500165 | H7: 0.34828624 | I7: 0.35318282 | J7: 0.35821684 | K7: =$C$60 | L7: =$C$60 | M7: =$C$60 | N7: =$C$60 | O7: =$C$60
A8: 복합제 (심혈관 질환 다중요법 목적의 복합제제 제외) | B8: % | C8: 0.60625872 | D8: 0.60219115 | E8: 0.60010228 | F8: 0.5985175 | G8: 0.5985093 | H8: 0.59688084 | I8: 0.59468021 | J8: 0.59517313 | K8: =$C$59+(1-$C$59)/(1+EXP(-$D$59*(K$2-$E$59)))+$F$59 | L8: =$C$59+(1-$C$59)/(1+EXP(-$D$59*(L$2-$E$59)))+$F$59 | M8: =$C$59+(1-$C$59)/(1+EXP(-$D$59*(M$2-$E$59)))+$F$59 | N8: =$C$59+(1-$C$59)/(1+EXP(-$D$59*(N$2-$E$59)))+$F$59 | O8: =$C$59+(1-$C$59)/(1+EXP(-$D$59*(O$2-$E$59)))+$F$59
A9: 복합제 (심혈관 질환 다중요법 목적의 복합제제) | B9: % | C9: 0.042669966 | D9: 0.046171855 | E9: 0.053229265 | F9: 0.057561401 | G9: 0.056489055 | H9: 0.054832926 | I9: 0.052136974 | J9: 0.046610027 | K9: =1-(K7+K8) | L9: =1-(L7+L8) | M9: =1-(M7+M8) | N9: =1-(N7+N8) | O9: =1-(O7+O8)
A11: C. ARB 복합제 중 특정 조합 비율 | 예측(2026-30): ARB+CCB·ARB+CCB+DU·ARB+DU는 로지스틱(S-curve) 개별 자유적합, 기타는 100%-나머지3개 잔여값으로 산출(잔여값이 실측 기타와 최대오차 0.2%p로 근접해 타당성 확인). 근거: 하단 [참고] 표
A12: ARB+DU 복합제 | B12: % | C12: 0.32525431 | D12: 0.29403023 | E12: 0.26881837 | F12: 0.24294782 | G12: 0.21980297 | H12: 0.20416795 | I12: 0.1887998 | J12: 0.17352958 | K12: =$C$66+(1-$C$66)/(1+EXP(-$D$66*(K$2-$E$66)))+$F$66 | L12: =$C$66+(1-$C$66)/(1+EXP(-$D$66*(L$2-$E$66)))+$F$66 | M12: =$C$66+(1-$C$66)/(1+EXP(-$D$66*(M$2-$E$66)))+$F$66 | N12: =$C$66+(1-$C$66)/(1+EXP(-$D$66*(N$2-$E$66)))+$F$66 | O12: =$C$66+(1-$C$66)/(1+EXP(-$D$66*(O$2-$E$66)))+$F$66
A13: ARB+CCB 복합제 | B13: % | C13: 0.62712655 | D13: 0.64246772 | E13: 0.65001638 | F13: 0.66447148 | G13: 0.67299871 | H13: 0.67661484 | I13: 0.68380199 | J13: 0.69246354 | K13: =$C$64/(1+EXP(-$D$64*(K$2-$E$64)))+$F$64 | L13: =$C$64/(1+EXP(-$D$64*(L$2-$E$64)))+$F$64 | M13: =$C$64/(1+EXP(-$D$64*(M$2-$E$64)))+$F$64 | N13: =$C$64/(1+EXP(-$D$64*(N$2-$E$64)))+$F$64 | O13: =$C$64/(1+EXP(-$D$64*(O$2-$E$64)))+$F$64
A14: ARB+CCB+DU 복합제 | B14: % | C14: 0.044854934 | D14: 0.057894343 | E14: 0.07271715 | F14: 0.081059308 | G14: 0.091581319 | H14: 0.098549952 | I14: 0.10175936 | J14: 0.10537134 | K14: =$C$65/(1+EXP(-$D$65*(K$2-$E$65)))+$F$65 | L14: =$C$65/(1+EXP(-$D$65*(L$2-$E$65)))+$F$65 | M14: =$C$65/(1+EXP(-$D$65*(M$2-$E$65)))+$F$65 | N14: =$C$65/(1+EXP(-$D$65*(N$2-$E$65)))+$F$65 | O14: =$C$65/(1+EXP(-$D$65*(O$2-$E$65)))+$F$65
A15: 기타 복합제 | B15: % | C15: 0.0027642119 | D15: 0.0056077067 | E15: 0.0084480964 | F15: 0.011521388 | G15: 0.015617 | H15: 0.020667259 | I15: 0.025638846 | J15: 0.028635539 | K15: =1-(K12+K13+K14) | L15: =1-(L12+L13+L14) | M15: =1-(M12+M13+M14) | N15: =1-(N12+N13+N14) | O15: =1-(O12+O13+O14)
A16: 합계 확인 | B16: % | C16: =SUM(C12:C15) | D16: =SUM(D12:D15) | E16: =SUM(E12:E15) | F16: =SUM(F12:F15) | G16: =SUM(G12:G15) | H16: =SUM(H12:H15) | I16: =SUM(I12:I15) | J16: =SUM(J12:J15) | ... O16: =SUM(O12:O15)
A18: D. ARB+CCB+DU 복합제: HP/GP 비율 | 예측(2026-30): 최근5년(2021-25) 평균고정(사실상 정체). 근거: 하단 [참고] 표
A19: HP | B19: % | C19: 0.35033633 | D19: 0.30655767 | E19: 0.25695488 | F19: 0.24505992 | G19: 0.2354529 | H19: 0.24609997 | I19: 0.2474314 | J19: 0.23597099 | K19: =(INDEX($C$118:$CZ$118,COUNTA($C$118:$CZ$118))+($G$70+(1-$G$70)/(1+EXP(-($C$70*2026.25+$D$70+$F$70))))+($G$70+(1-$G$70)/(1+EXP(-($C$70*2026.5+$D$70+$F$70))))+($G$70+(1-$G$70)/(1+EXP(-($C$70*2026.75+$D$70+$F$70)))))/4 | L19: =(($G$70+(1-$G$70)/(1+EXP(-($C$70*2027+$D$70+$F$70))))+($G$70+(1-$G$70)/(1+EXP(-($C$70*2027.25+$D$70+$F$70))))+($G$70+(1-$G$70)/(1+EXP(-($C$70*2027.5+$D$70+$F$70))))+($G$70+(1-$G$70)/(1+EXP(-($C$70*2027.75+$D$70+$F$70)))))/4 | M19: =(($G$70+(1-$G$70)/(1+EXP(-($C$70*2028+$D$70+$F$70))))+($G$70+(1-$G$70)/(1+EXP(-($C$70*2028.25+$D$70+$F$70))))+($G$70+(1-$G$70)/(1+EXP(-($C$70*2028.5+$D$70+$F$70))))+($G$70+(1-$G$70)/(1+EXP(-($C$70*2028.75+$D$70+$F$70)))))/4 | N19: =(($G$70+(1-$G$70)/(1+EXP(-($C$70*2029+$D$70+$F$70))))+($G$70+(1-$G$70)/(1+EXP(-($C$70*2029.25+$D$70+$F$70))))+($G$70+(1-$G$70)/(1+EXP(-($C$70*2029.5+$D$70+$F$70))))+($G$70+(1-$G$70)/(1+EXP(-($C$70*2029.75+$D$70+$F$70)))))/4 | O19: =(($G$70+(1-$G$70)/(1+EXP(-($C$70*2030+$D$70+$F$70))))+($G$70+(1-$G$70)/(1+EXP(-($C$70*2030.25+$D$70+$F$70))))+($G$70+(1-$G$70)/(1+EXP(-($C$70*2030.5+$D$70+$F$70))))+($G$70+(1-$G$70)/(1+EXP(-($C$70*2030.75+$D$70+$F$70)))))/4
A20: GP | B20: % | C20: 0.64966367 | D20: 0.69344233 | E20: 0.74304512 | F20: 0.75494008 | G20: 0.7645471 | H20: 0.75390003 | I20: 0.7525686 | J20: 0.76402901 | K20: =1-K19 | L20: =1-L19 | M20: =1-M19 | N20: =1-N19 | O20: =1-O19
A22: E. ARB+CCB+DU 복합제 / HP/ 성분별 비율 | 예측(2026-30): olmesartan[MAIN]=로지스틱(하한), FY2026은 1분기 실측+분기 추세 블렌드로 계산방식 통일(기존 단일점 대입 방식 폐기), fimasartan=로지스틱(상한), telmisartan=선형회귀, valsartan=가정치, losartan=잔여값. 근거: 하단 [참고] 표
A23: olmesartan | B23: % | C23: 0.88632325 | D23: 0.79044332 | E23: 0.69758354 | F23: 0.6674126 | G23: 0.63582451 | H23: 0.55685985 | I23: 0.51850922 | J23: 0.50099706 | K23: =(INDEX($B$98:$CZ$98,COUNTA($B$98:$CZ$98))+($C$73+(1-$C$73)/(1+EXP(-$D$73*(K$2+0.25-$E$73)))+$F$73)+($C$73+(1-$C$73)/(1+EXP(-$D$73*(K$2+0.5-$E$73)))+$F$73)+($C$73+(1-$C$73)/(1+EXP(-$D$73*(K$2+0.75-$E$73)))+$F$73))/4 | L23: =(($C$73+(1-$C$73)/(1+EXP(-$D$73*(L$2-$E$73)))+$F$73)+($C$73+(1-$C$73)/(1+EXP(-$D$73*(L$2+0.25-$E$73)))+$F$73)+($C$73+(1-$C$73)/(1+EXP(-$D$73*(L$2+0.5-$E$73)))+$F$73)+($C$73+(1-$C$73)/(1+EXP(-$D$73*(L$2+0.75-$E$73)))+$F$73))/4 | M23: =(($C$73+(1-$C$73)/(1+EXP(-$D$73*(M$2-$E$73)))+$F$73)+($C$73+(1-$C$73)/(1+EXP(-$D$73*(M$2+0.25-$E$73)))+$F$73)+($C$73+(1-$C$73)/(1+EXP(-$D$73*(M$2+0.5-$E$73)))+$F$73)+($C$73+(1-$C$73)/(1+EXP(-$D$73*(M$2+0.75-$E$73)))+$F$73))/4 | N23: =(($C$73+(1-$C$73)/(1+EXP(-$D$73*(N$2-$E$73)))+$F$73)+($C$73+(1-$C$73)/(1+EXP(-$D$73*(N$2+0.25-$E$73)))+$F$73)+($C$73+(1-$C$73)/(1+EXP(-$D$73*(N$2+0.5-$E$73)))+$F$73)+($C$73+(1-$C$73)/(1+EXP(-$D$73*(N$2+0.75-$E$73)))+$F$73))/4 | O23: =(($C$73+(1-$C$73)/(1+EXP(-$D$73*(O$2-$E$73)))+$F$73)+($C$73+(1-$C$73)/(1+EXP(-$D$73*(O$2+0.25-$E$73)))+$F$73)+($C$73+(1-$C$73)/(1+EXP(-$D$73*(O$2+0.5-$E$73)))+$F$73)+($C$73+(1-$C$73)/(1+EXP(-$D$73*(O$2+0.75-$E$73)))+$F$73))/4 | P23: [MAIN][26~30: 로지스틱(하한 47.0%)]
A24: fimasartan | B24: % | C24: 0 | D24: 0 | E24: 0 | F24: 0 | G24: 0.045000642 | H24: 0.1501385 | I24: 0.20136216 | J24: 0.21602565 | K24: =$C$74/(1+EXP(-$D$74*(K$2-$E$74)))+$F$74 | L24: =$C$74/(1+EXP(-$D$74*(L$2-$E$74)))+$F$74 | M24: =$C$74/(1+EXP(-$D$74*(M$2-$E$74)))+$F$74 | N24: =$C$74/(1+EXP(-$D$74*(N$2-$E$74)))+$F$74 | O24: =$C$74/(1+EXP(-$D$74*(O$2-$E$74)))+$F$74 | P24: [26~30: 로지스틱(상한 21.6%)]
A25: losartan | B25: % | C25: 0.086876825 | D25: 0.16529931 | E25: 0.20288256 | F25: 0.19742301 | G25: 0.18126101 | H25: 0.16076669 | I25: 0.14956588 | J25: 0.15713461 | K25: =1-(K23+K24+K26+K27) | L25: =1-(L23+L24+L26+L27) | M25: =1-(M23+M24+M26+M27) | N25: =1-(N23+N24+N26+N27) | O25: =1-(O23+O24+O26+O27) | P25: [26~30: 잔여값]
A26: telmisartan | B26: % | C26: 0.026799926 | D26: 0.044257373 | E26: 0.099533907 | F26: 0.13516439 | G26: 0.13791384 | H26: 0.13223497 | I26: 0.13056273 | J26: 0.1258065 | K26: =$C$75*K$2+$D$75 | L26: =$C$75*L$2+$D$75 | M26: =$C$75*M$2+$D$75 | N26: =$C$75*N$2+$D$75 | O26: =$C$75*O$2+$D$75 | P26: [26~30: 선형회귀]
A27: valsartan | B27: % | C27: 0 | D27: 0 | E27: 0 | F27: 0 | G27: 0 | H27: 0 | I27: 0 | J27: 3.6178805e-05 | K27: =$C$76 | L27: =$C$76 | M27: =$C$76 | N27: =$C$76 | O27: =$C$76 | P27: [26~30: 가정치·고정]
A29: F. ARB+CCB+DU 복합제 / HP/ Olmesartan / Original:generic 비율 | 예측(2026-30): Original[MAIN]=분기실측 기반 FY2020Q1~ 자동확장 직접선형회귀 (연간(2020-25) 방식 폐기, 로짓변환 시 인위적 가속 재확인되어 직접선형 유지). 근거: 하단 [참고] 표
A30: Original | B30: % | C30: 1 | D30: 0.99651363 | E30: 0.98969879 | F30: 0.97943735 | G30: 0.97481446 | H30: 0.96902683 | I30: 0.95857066 | J30: 0.95268942 | K30: =(INDEX($B$99:$CZ$99,COUNTA($B$99:$CZ$99))+(($C$81*2026.25+$D$81+$F$81)/100)+(($C$81*2026.5+$D$81+$F$81)/100)+(($C$81*2026.75+$D$81+$F$81)/100))/4 | L30: =((($C$81*2027+$D$81+$F$81)/100)+(($C$81*2027.25+$D$81+$F$81)/100)+(($C$81*2027.5+$D$81+$F$81)/100)+(($C$81*2027.75+$D$81+$F$81)/100))/4 | M30: =((($C$81*2028+$D$81+$F$81)/100)+(($C$81*2028.25+$D$81+$F$81)/100)+(($C$81*2028.5+$D$81+$F$81)/100)+(($C$81*2028.75+$D$81+$F$81)/100))/4 | N30: =((($C$81*2029+$D$81+$F$81)/100)+(($C$81*2029.25+$D$81+$F$81)/100)+(($C$81*2029.5+$D$81+$F$81)/100)+(($C$81*2029.75+$D$81+$F$81)/100))/4 | O30: =((($C$81*2030+$D$81+$F$81)/100)+(($C$81*2030.25+$D$81+$F$81)/100)+(($C$81*2030.5+$D$81+$F$81)/100)+(($C$81*2030.75+$D$81+$F$81)/100))/4 | P30: [MAIN][26~30: 직접 선형회귀]
A31: Generic | B31: % | C31: 0 | D31: 0.0034863731 | E31: 0.010301212 | F31: 0.020562647 | G31: 0.025185544 | H31: 0.03097317 | I31: 0.041429341 | J31: 0.047310584 | K31: =1-K30 | L31: =1-L30 | M31: =1-M30 | N31: =1-N30 | O31: =1-O30 | P31: [26~30: Original과 대칭]
A33: G. ARB+CCB+DU 복합제 / GP/ 성분별 비율 | 예측(2026-30): olmesartan[MAIN]=FY26 1분기까지 분기 실측 기준 로짓 추세 3분기 연장 후 flat(잠정), losartan=선형회귀(최근5년) 폐기 — 분기 실측상 FY25Q1(20.4%, 역대 최저) 저점 찍고 4분기 연속 반등 확인되어 최근 저점권 평균 flat 고정, fimasartan=로지스틱(상한), valsartan=가정치, telmisartan=잔여값(olmesartan·losartan 재조정으로 30% 상한 이내 안착 확인). 근거: 하단 [참고] 표
A34: olmesartan | B34: % | C34: 0.57609307 | D34: 0.50089694 | E34: 0.45280893 | F34: 0.46322065 | G34: 0.4490182 | H34: 0.4455954 | I34: 0.45725159 | J34: 0.44699716 | K34: =(INDEX($B$104:$CZ$104,COUNTA($B$104:$CZ$104))+($C$84+(1-$C$84)/(1+EXP(-($D$84*2026.25+$E$84))))+($C$84+(1-$C$84)/(1+EXP(-($D$84*2026.5+$E$84))))+($C$84+(1-$C$84)/(1+EXP(-($D$84*2026.75+$E$84)))))/4 | L34: =($C$84+(1-$C$84)/(1+EXP(-($D$84*2026.75+$E$84)))) | M34: =($C$84+(1-$C$84)/(1+EXP(-($D$84*2026.75+$E$84)))) | N34: =($C$84+(1-$C$84)/(1+EXP(-($D$84*2026.75+$E$84)))) | O34: =($C$84+(1-$C$84)/(1+EXP(-($D$84*2026.75+$E$84)))) | P34: [MAIN][26~30: 20-25년 평균고정]
A35: losartan | B35: % | C35: 0.33914297 | D35: 0.35648864 | E35: 0.30440269 | F35: 0.28488359 | G35: 0.24532403 | H35: 0.22973399 | I35: 0.21396793 | J35: 0.21216939 | K35: =$C$86 | L35: =$C$86 | M35: =$C$86 | N35: =$C$86 | O35: =$C$86 | P35: [26~30: 선형회귀(최근5년)]
A36: telmisartan | B36: % | C36: 0.084763953 | D36: 0.14261442 | E36: 0.24278838 | F36: 0.25189576 | G36: 0.22923486 | H36: 0.2137816 | I36: 0.20485878 | J36: 0.20816594 | K36: =1-(K34+K35+K37+K38) | L36: =1-(L34+L35+L37+L38) | M36: =1-(M34+M35+M37+M38) | N36: =1-(N34+N35+N37+N38) | O36: =1-(O34+O35+O37+O38) | P36: [26~30: 잔여값]
A37: fimasartan | B37: % | C37: 0 | D37: 0 | E37: 0 | F37: 0 | G37: 0.07642292 | H37: 0.110889 | I37: 0.12392171 | J37: 0.13082815 | K37: =$C$85/(1+EXP(-$D$85*(K$2-$E$85)))+$F$85 | L37: =$C$85/(1+EXP(-$D$85*(L$2-$E$85)))+$F$85 | M37: =$C$85/(1+EXP(-$D$85*(M$2-$E$85)))+$F$85 | N37: =$C$85/(1+EXP(-$D$85*(N$2-$E$85)))+$F$85 | O37: =$C$85/(1+EXP(-$D$85*(O$2-$E$85)))+$F$85 | P37: [26~30: 로지스틱(상한 13.2%)]
A38: valsartan | B38: % | C38: 0 | D38: 0 | E38: 0 | F38: 0 | G38: 0 | H38: 0 | I38: 0 | J38: 0.0018393659 | K38: =$C$87 | L38: =$C$87 | M38: =$C$87 | N38: =$C$87 | O38: =$C$87 | P38: [26~30: 가정치·고정]
K39: =SUM(K34:K38) | L39: =SUM(L34:L38) | M39: =SUM(M34:M38) | N39: =SUM(N34:N38) | O39: =SUM(O34:O38)
A40: H. ARB+CCB+DU 복합제 / GP/ Olmesartan / Original:generic 비율 | 예측(2026-30): Original[MAIN]=분기실측 기반 FY2019Q1~ 자동확장 로짓 변환 회귀 (연간(최근5년) 방식 폐기). 근거: 하단 [참고] 표
